Workbook

Sheet Things To Address
A1: Type | B1: Description
A2: PPC Cost | B2: You have paid clicks (CampaignAdjusted=Capterra,SplitAdjusted=capterra,KeyWord=GetApp) that have not been allocated a cost. Use the Tools menu to update costs.
A3: PPC Cost | B3: You have paid clicks (CampaignAdjusted=Capterra,SplitAdjusted=capterra,KeyWord=FreeTrial) that have not been allocated a cost. However, this looks invalid, as it came from a blank Referrer.
A4: PPC Cost | B4: You have paid clicks (CampaignAdjusted=Capterra,SplitAdjusted=Capterra_destinationURL,KeyWord=trial) that have not been allocated a cost. However, this looks invalid, as it came from a blank Referrer.
A5: PPC Cost | B5: You have paid clicks (CampaignAdjusted=Capterra,SplitAdjusted=Capterra_freetrial,KeyWord=CS) that have not been allocated a cost. However, this looks invalid, as it came from a blank Referrer.
A6: PPC Cost | B6: You have paid clicks (CampaignAdjusted=Capterra,SplitAdjusted=,KeyWord=crm-software) that have not been allocated a cost. However, this looks invalid, as it came from a blank Referrer.
A7: PPC Cost | B7: You have paid clicks (CampaignAdjusted=Capterra,SplitAdjusted=Proposals,KeyWord=LP) that have not been allocated a cost. Use the Tools menu to update costs.
A8: PPC Cost | B8: You have paid clicks (CampaignAdjusted=Capterra,SplitAdjusted=Capterra_destinationURL,KeyWord=capterra) that have not been allocated a cost. Use the Tools menu to update costs.
A9: PPC Cost | B9: You have paid clicks (CampaignAdjusted=Capterra,SplitAdjusted=ME,KeyWord=LP) that have not been allocated a cost. Use the Tools menu to update costs.
A10: PPC Cost | B10: You have paid clicks (CampaignAdjusted=Capterra,SplitAdjusted=Capterra_destinationURL,KeyWord=capterra) that have not been allocated a cost. However, this looks invalid, as it came from a blank Referrer.
A11: PPC Cost | B11: You have paid clicks (CampaignAdjusted=Capterra,SplitAdjusted=ME,KeyWord=LP) that have not been allocated a cost. However, this looks invalid, as it came from a blank Referrer.
A12: PPC Cost | B12: You have paid clicks (CampaignAdjusted=Capterra,SplitAdjusted=Proposals,KeyWord=LP) that have not been allocated a cost. However, this looks invalid, as it came from a blank Referrer.
... A469: PPC Cost | B469: You have paid clicks (CampaignAdjusted=Twitter X Ad,SplitAdjusted=Video-views,KeyWord=Desktop) that have not been allocated a cost. However, this looks invalid, as it came from a blank Referrer.

Sheet Accounts
A1: RecordID | B1: AccountName | C1: SignUpDate | D1: CancellationDate | E1: ConvertPayDate | F1: IsActive | G1: IsConversionException | H1: IsCountedAsChurn | I1: IsTrialConverted | J1: PayType | K1: AppName | L1: AccountingPlatform | M1: PlatformToggle | N1: CustDatSaaSAmountToDate | O1: CustDatLastSaaSAmount | P1: CustDatPSAmountToDate | Q1: CustDatPSLastMonth | R1: ExpectedLifetime | S1: MethodDiscount | T1: Channel | U1: PartnerName | V1: CookieID | W1: Att_Direct_SEO_Referrer | X1: Att_Direct | Y1: Att_SEO | Z1: Att_OPN_Other_Peoples_Networks | AA1: Att_Pay_Per_Click | AB1: Att_Partners | AC1: Att_Email | AD1: Att_Remarketing | AE1: Att_Social | AF1: Att_Help_Center | AG1: Att_Online_Chat_Tool | AH1: Att_Content | AI1: Att_Banner_Ads | AJ1: Att_Seminar_Conference | AK1: Att_Referral_Program | AL1: Att_Referral_Link | AM1: Att_Backlinks | AN1: Att_Other | AO1: Att_Webinar | AP1: Att_None | AQ1: SyncTypeRegion | AR1: Vertical | AS1: Sector | AT1: CustDatIndustry | AU1: CustDatFirstSyncCompleted | AV1: CustDatLastRefreshed | AW1: CustDatCountOfEmployees | AX1: CustDatAnnualSales | AY1: CustDatCountOfCustomers | AZ1: LicenseCount | BA1: CountOfCustomScreens | BB1: CountOfCustomScreensMN | BC1: Day | BD1: Week | BE1: Month | BF1: Year | BG1: SignUpCountry | BH1: URL | BI1: Category | BJ1: Media Type
A2: 153108 | B2: multdoor | C2: 45991.991 | F2: TRUE | G2: FALSE | H2: FALSE | I2: FALSE | J2: Monthly | K2: Method:CRM For QBO | L2: QBO | M2: New | N2: 0 | O2: 63.75 | P2: 0 | Q2: 0 | R2: 0 | S2: US-3 Month Promo(25% off) | T2: Direct | V2: 7217712 | W2: https://www.google.com/ | X2: 0 | Y2: 1 | Z2: 0 | AA2: 0 | AB2: 0 | AC2: 0 | AD2: 0 | AE2: 0 | AF2: 0 | AG2: 0 | AH2: 0 | AI2: 0 | AJ2: 0 | AK2: 0 | AL2: 0 | AM2: 0 | AN2: 0 | AO2: 0 | AP2: =1-SUM(X2:AN2) -> 0 | AQ2: CA | AR2: Other | AS2: other | AT2: Industrial building construction | AU2: 45991 | AV2: 46024.034 | AW2: 0 | AX2: 318369.12 | AY2: 13 | AZ2: 1 | BA2: 0 | BB2: 0 | BC2: 45991 | BD2: 47 | BE2: Nov | BF2: 2025 | BG2: Canada | BH2: =VLOOKUP(B2,CookieClicks!D:O,12,FALSE) -> https://www.method.me/ | BI2: =IFERROR(__xludf.DUMMYFUNCTION("VLOOKUP(REGEXREPLACE(BH2,""[?].*"",""""),ContentBuckets!A:C,2,FALSE)"),"Homepage") -> Homepage | BJ2: =IFERROR(__xludf.DUMMYFUNCTION("VLOOKUP(REGEXREPLACE(BH2,""[?].*"",""""),ContentBuckets!A:C,3,FALSE)"),"Other page") -> Other page
A3: 153109 | B3: alromanimechanicalworkshop6 | C3: 45992.129 | F3: TRUE | G3: FALSE | H3: FALSE | I3: FALSE | J3: Monthly | K3: Method:CRM For QBO | L3: QBO | M3: New | N3: 0 | O3: 53.25 | P3: 0 | Q3: 0 | R3: 28 | S3: US-3 Month Promo(25% off) | T3: Direct | V3: 7218180 | W3: https://www.google.com/ | X3: 0 | Y3: 1 | Z3: 0 | AA3: 0 | AB3: 0 | AC3: 0 | AD3: 0 | AE3: 0 | AF3: 0 | AG3: 0 | AH3: 0 | AI3: 0 | AJ3: 0 | AK3: 0 | AL3: 0 | AM3: 0 | AN3: 0 | AO3: 0 | AP3: =1-SUM(X3:AN3) -> 0 | AQ3: KW | AR3: Repair and maintenance | AV3: 46023.982 | AW3: 9 | AX3: 0 | AY3: 214 | AZ3: 1 | BA3: 0 | BB3: 0 | BC3: 45992 | BD3: 48 | BE3: Dec | BF3: 2025 | BG3: Kuwait | BH3: =VLOOKUP(B3,CookieClicks!D:O,12,FALSE) -> https://www.method.me/ | BI3: =IFERROR(__xludf.DUMMYFUNCTION("VLOOKUP(REGEXREPLACE(BH3,""[?].*"",""""),ContentBuckets!A:C,2,FALSE)"),"Homepage") -> Homepage | BJ3: =IFERROR(__xludf.DUMMYFUNCTION("VLOOKUP(REGEXREPLACE(BH3,""[?].*"",""""),ContentBuckets!A:C,3,FALSE)"),"Other page") -> Other page
A4: 153110 | B4: student26 | C4: 45992.176 | F4: TRUE | G4: FALSE | H4: FALSE | I4: FALSE | J4: Monthly | K4: Method:CRM | L4: QuickBooks | M4: New | N4: 0 | O4: 44.25 | P4: 0 | Q4: 0 | R4: 0 | S4: US-3 Month Promo(25% off) | T4: Direct | V4: 7218307 | X4: 0 | Y4: 0 | Z4: 0 | AA4: 0 | AB4: 0 | AC4: 0 | AD4: 0 | AE4: 0 | AF4: 0 | AG4: 0 | AH4: 0 | AI4: 0 | AJ4: 0 | AK4: 0 | AL4: 0 | AM4: 0 | AN4: 1 | AO4: 0 | AP4: =1-SUM(X4:AN4) -> 0 | AV4: 46024.028 | AW4: 0 | AX4: 0 | AY4: 0 | AZ4: 1 | BA4: 0 | BB4: 0 | BC4: 45992 | BD4: 48 | BE4: Dec | BF4: 2025 | BG4: Indonesia | BH4: =VLOOKUP(B4,CookieClicks!D:O,12,FALSE) -> https://www.method.me/blog/construction-project-success-crm-solution/ | BI4: =IFERROR(__xludf.DUMMYFUNCTION("VLOOKUP(REGEXREPLACE(BH4,""[?].*"",""""),ContentBuckets!A:C,2,FALSE)"),"CRM") -> CRM | BJ4: =IFERROR(__xludf.DUMMYFUNCTION("VLOOKUP(REGEXREPLACE(BH4,""[?].*"",""""),ContentBuckets!A:C,3,FALSE)"),"Blog") -> Blog
A5: 153111 | B5: healthcaremaintenanceservices | C5: 45992.326 | E5: 46006.688 | F5: TRUE | G5: FALSE | H5: FALSE | I5: FALSE | J5: Monthly | K5: Method:CRM For QBO | L5: QBO | M5: New | N5: 88.5 | O5: 70.5 | P5: 0 | Q5: 0 | R5: 28 | S5: US-3 Month Promo(25% off) | T5: Direct | V5: 7204189 | W5: https://www.google.com/ | X5: 0 | Y5: 1 | Z5: 0 | AA5: 0 | AB5: 0 | AC5: 0 | AD5: 0 | AE5: 0 | AF5: 0 | AG5: 0 | AH5: 0 | AI5: 0 | AJ5: 0 | AK5: 0 | AL5: 0 | AM5: 0 | AN5: 0 | AO5: 0 | AP5: =1-SUM(X5:AN5) -> 0 | AQ5: US | AR5: Repair and maintenance | AU5: 45992 | AV5: 46024.001 | AW5: 6 | AX5: 4570973.8 | AY5: 441 | AZ5: 2 | BA5: 0 | BB5: 0 | BC5: 45992 | BD5: 48 | BE5: Dec | BF5: 2025 | BG5: United States | BH5: =VLOOKUP(B5,CookieClicks!D:O,12,FALSE) -> https://www.method.me/blog/quickbooks-customer-portal/ | BI5: =IFERROR(__xludf.DUMMYFUNCTION("VLOOKUP(REGEXREPLACE(BH5,""[?].*"",""""),ContentBuckets!A:C,2,FALSE)"),"Listicle - General") -> Listicle - General | BJ5: =IFERROR(__xludf.DUMMYFUNCTION("VLOOKUP(REGEXREPLACE(BH5,""[?].*"",""""),ContentBuckets!A:C,3,FALSE)"),"Blog") -> Blog
A6: 153112 | B6: customoutdoorkitchens | C6: 45992.336 | F6: TRUE | G6: FALSE | H6: FALSE | I6: FALSE | J6: Monthly | K6: Method:CRM For QBO | L6: QBO | M6: New | N6: 0 | O6: 44.25 | P6: 0 | Q6: 0 | R6: 28 | S6: US-3 Month Promo(25% off) | T6: Direct | V6: 7171808 | W6: https://www.google.com/ | X6: 0 | Y6: 1 | Z6: 0 | AA6: 0 | AB6: 0 | AC6: 0 | AD6: 0 | AE6: 0 | AF6: 0 | AG6: 0 | AH6: 0 | AI6: 0 | AJ6: 0 | AK6: 0 | AL6: 0 | AM6: 0 | AN6: 0 | AO6: 0 | AP6: =1-SUM(X6:AN6) -> 0 | AQ6: US | AR6: Construction | AT6: Outdoor Kitchen Design / Build | AU6: 45992 | AV6: 46023.99 | AW6: 0 | AX6: 0 | AY6: 403 | AZ6: 1 | BA6: 0 | BB6: 0 | BC6: 45992 | BD6: 48 | BE6: Dec | BF6: 2025 | BG6: United States | BH6: =VLOOKUP(B6,CookieClicks!D:O,12,FALSE) -> https://www.method.me/ | BI6: =IFERROR(__xludf.DUMMYFUNCTION("VLOOKUP(REGEXREPLACE(BH6,""[?].*"",""""),ContentBuckets!A:C,2,FALSE)"),"Homepage") -> Homepage | BJ6: =IFERROR(__xludf.DUMMYFUNCTION("VLOOKUP(REGEXREPLACE(BH6,""[?].*"",""""),ContentBuckets!A:C,3,FALSE)"),"Other page") -> Other page
A7: 153113 | B7: manexusa | C7: 45992.342 | D7: 45992.365 | F7: FALSE | G7: TRUE | H7: FALSE | I7: FALSE | J7: Monthly | K7: Method:CRM | L7: QuickBooks | M7: New | N7: 0 | O7: 0 | P7: 0 | Q7: 0 | R7: 0 | S7: US-3 Month Promo(25% off) | T7: Direct | V7: 7168930 | X7: 1 | Y7: 0 | Z7: 0 | AA7: 0 | AB7: 0 | AC7: 0 | AD7: 0 | AE7: 0 | AF7: 0 | AG7: 0 | AH7: 0 | AI7: 0 | AJ7: 0 | AK7: 0 | AL7: 0 | AM7: 0 | AN7: 0 | AO7: 0 | AP7: =1-SUM(X7:AN7) -> 0 | AW7: 0 | AX7: 0 | AY7: 0 | AZ7: 1 | BA7: 0 | BB7: 0 | BC7: 45992 | BD7: 48 | BE7: Dec | BF7: 2025 | BG7: United States | BH7: =VLOOKUP(B7,CookieClicks!D:O,12,FALSE) -> http://signup.method.me/methodcrm | BI7: =IFERROR(__xludf.DUMMYFUNCTION("VLOOKUP(REGEXREPLACE(BH7,""[?].*"",""""),ContentBuckets!A:C,2,FALSE)"),"#N/A") -> #N/A | BJ7: =IFERROR(__xludf.DUMMYFUNCTION("VLOOKUP(REGEXREPLACE(BH7,""[?].*"",""""),ContentBuckets!A:C,3,FALSE)"),"#N/A") -> #N/A
A8: 153114 | B8: reddoorpestcontrol2 | C8: 45992.347 | F8: TRUE | G8: FALSE | H8: FALSE | I8: FALSE | J8: Monthly | K8: Method:CRM For QBO | L8: QBO | M8: New | N8: 0 | O8: 44.25 | P8: 0 | Q8: 0 | R8: 28 | S8: US-3 Month Promo(25% off) | T8: Direct | V8: 7218855 | X8: 1 | Y8: 0 | Z8: 0 | AA8: 0 | AB8: 0 | AC8: 0 | AD8: 0 | AE8: 0 | AF8: 0 | AG8: 0 | AH8: 0 | AI8: 0 | AJ8: 0 | AK8: 0 | AL8: 0 | AM8: 0 | AN8: 0 | AO8: 0 | AP8: =1-SUM(X8:AN8) -> 0 | AQ8: US | AR8: Field Services | AU8: 45992 | AV8: 46024.028 | AW8: 0 | AX8: 44332.44 | AY8: 564 | AZ8: 1 | BA8: 0 | BB8: 0 | BC8: 45992 | BD8: 48 | BE8: Dec | BF8: 2025 | BG8: United States | BH8: =VLOOKUP(B8,CookieClicks!D:O,12,FALSE) -> https://signin.method.me/Password/Reset?rpcode=-nZQ0G03B%2bIuTre9Gdsw3ggkv!rw%3du%3dJPbRgJ7a-UmqVNiskXhWYwfMQB8a5 | BI8: =IFERROR(__xludf.DUMMYFUNCTION("VLOOKUP(REGEXREPLACE(BH8,""[?].*"",""""),ContentBuckets!A:C,2,FALSE)"),"#N/A") -> #N/A | BJ8: =IFERROR(__xludf.DUMMYFUNCTION("VLOOKUP(REGEXREPLACE(BH8,""[?].*"",""""),ContentBuckets!A:C,3,FALSE)"),"#N/A") -> #N/A
A9: 153115 | B9: manexusa2 | C9: 45992.362 | D9: 46000.378 | F9: FALSE | G9: TRUE | H9: FALSE | I9: FALSE | J9: Monthly | K9: Method:CRM for QBD | L9: QBDT | M9: New | N9: 0 | O9: 63.75 | P9: 0 | Q9: 0 | R9: 28 | S9: US-3 Month Promo(25% off) | T9: Direct | V9: 7168930 | X9: 1 | Y9: 0 | Z9: 0 | AA9: 0 | AB9: 0 | AC9: 0 | AD9: 0 | AE9: 0 | AF9: 0 | AG9: 0 | AH9: 0 | AI9: 0 | AJ9: 0 | AK9: 0 | AL9: 0 | AM9: 0 | AN9: 0 | AO9: 0 | AP9: =1-SUM(X9:AN9) -> 0 | AQ9: US | AR9: Manufacturing (MWD) | AU9: 45992 | AV9: 46000.018 | AW9: 15 | AX9: 933479.16 | AY9: 3208 | AZ9: 1 | BA9: 0 | BB9: 0 | BC9: 45992 | BD9: 48 | BE9: Dec | BF9: 2025 | BG9: United States | BH9: =VLOOKUP(B9,CookieClicks!D:O,12,FALSE) -> http://signup.method.me/methodcrm | BI9: =IFERROR(__xludf.DUMMYFUNCTION("VLOOKUP(REGEXREPLACE(BH9,""[?].*"",""""),ContentBuckets!A:C,2,FALSE)"),"#N/A") -> #N/A | BJ9: =IFERROR(__xludf.DUMMYFUNCTION("VLOOKUP(REGEXREPLACE(BH9,""[?].*"",""""),ContentBuckets!A:C,3,FALSE)"),"#N/A") -> #N/A
A10: 153116 | B10: jlbcompanies | C10: 45992.416 | E10: 46009.496 | F10: TRUE | G10: FALSE | H10: FALSE | I10: FALSE | J10: Monthly | K10: Method:CRM For QBO | L10: QBO | M10: New | N10: 72.75 | O10: 72.75 | P10: 0 | Q10: 0 | R10: 28 | S10: US-3 Month Promo(25% off) | T10: Direct | V10: 7210242 | W10: https://www.google.com/ | X10: 0 | Y10: 1 | Z10: 0 | AA10: 0 | AB10: 0 | AC10: 0 | AD10: 0 | AE10: 0 | AF10: 0 | AG10: 0 | AH10: 0 | AI10: 0 | AJ10: 0 | AK10: 0 | AL10: 0 | AM10: 0 | AN10: 0 | AO10: 0 | AP10: =1-SUM(X10:AN10) -> 0 | AQ10: US | AR10: Other | AU10: 45992 | AV10: 46024.003 | AW10: 56 | AX10: 2704501.3 | AY10: 1178 | AZ10: 1 | BA10: 0 | BB10: 1 | BC10: 45992 | BD10: 48 | BE10: Dec | BF10: 2025 | BG10: United States | BH10: =VLOOKUP(B10,CookieClicks!D:O,12,FALSE) -> https://www.method.me/ | BI10: =IFERROR(__xludf.DUMMYFUNCTION("VLOOKUP(REGEXREPLACE(BH10,""[?].*"",""""),ContentBuckets!A:C,2,FALSE)"),"Homepage") -> Homepage | BJ10: =IFERROR(__xludf.DUMMYFUNCTION("VLOOKUP(REGEXREPLACE(BH10,""[?].*"",""""),ContentBuckets!A:C,3,FALSE)"),"Other page") -> Other page
A11: 153119 | B11: ssisanitary | C11: 45992.461 | E11: 46006.461 | F11: TRUE | G11: FALSE | H11: FALSE | I11: FALSE | J11: Monthly | K11: Method:CRM For QBO | L11: QBO | M11: New | N11: 452.5 | O11: 127.5 | P11: 558 | Q11: 558 | R11: 28 | S11: US-3 Month Promo(25% off) | T11: Direct | V11: 7191321 | W11: https://www.google.com/ | X11: 0 | Y11: 1 | Z11: 0 | AA11: 0 | AB11: 0 | AC11: 0 | AD11: 0 | AE11: 0 | AF11: 0 | AG11: 0 | AH11: 0 | AI11: 0 | AJ11: 0 | AK11: 0 | AL11: 0 | AM11: 0 | AN11: 0 | AO11: 0 | AP11: =1-SUM(X11:AN11) -> 0 | AQ11: US | AR11: Wholesale and distribution services (MWD) | AU11: 45992 | AV11: 46024.027 | AW11: 0 | AX11: 2002376.5 | AY11: 1130 | AZ11: 2 | BA11: 0 | BB11: 12 | BC11: 45992 | BD11: 48 | BE11: Dec | BF11: 2025 | BG11: United States | BH11: =VLOOKUP(B11,CookieClicks!D:O,12,FALSE) -> https://www.method.me/ | BI11: =IFERROR(__xludf.DUMMYFUNCTION("VLOOKUP(REGEXREPLACE(BH11,""[?].*"",""""),ContentBuckets!A:C,2,FALSE)"),"Homepage") -> Homepage | BJ11: =IFERROR(__xludf.DUMMYFUNCTION("VLOOKUP(REGEXREPLACE(BH11,""[?].*"",""""),ContentBuckets!A:C,3,FALSE)"),"Other page") -> Other page
A12: 153120 | B12: highendcompaniesllc | C12: 45992.476 | E12: 46006.486 | F12: TRUE | G12: FALSE | H12: FALSE | I12: FALSE | J12: Monthly | K12: Method:CRM For QBO | L12: QBO | M12: New | N12: 88.5 | O12: 116 | P12: 0 | Q12: 0 | R12: 28 | S12: US-3 Month Promo(25% off) | T12: Direct | V12: 7219935 | W12: https://www.google.com/ | X12: 0 | Y12: 1 | Z12: 0 | AA12: 0 | AB12: 0 | AC12: 0 | AD12: 0 | AE12: 0 | AF12: 0 | AG12: 0 | AH12: 0 | AI12: 0 | AJ12: 0 | AK12: 0 | AL12: 0 | AM12: 0 | AN12: 0 | AO12: 0 | AP12: =1-SUM(X12:AN12) -> 0 | AQ12: US | AR12: Other | AU12: 45992 | AV12: 46024.012 | AW12: 0 | AX12: 877018.8 | AY12: 117 | AZ12: 2 | BA12: 0 | BB12: 1 | BC12: 45992 | BD12: 48 | BE12: Dec | BF12: 2025 | BG12: United States | BH12: =VLOOKUP(B12,CookieClicks!D:O,12,FALSE) -> https://www.method.me/ | BI12: =IFERROR(__xludf.DUMMYFUNCTION("VLOOKUP(REGEXREPLACE(BH12,""[?].*"",""""),ContentBuckets!A:C,2,FALSE)"),"Homepage") -> Homepage | BJ12: =IFERROR(__xludf.DUMMYFUNCTION("VLOOKUP(REGEXREPLACE(BH12,""[?].*"",""""),ContentBuckets!A:C,3,FALSE)"),"Other page") -> Other page
A13: 153121 | B13: jirehtransmissionsllc | C13: 45992.497 | D13: 45992.503 | F13: FALSE | G13: FALSE | H13: FALSE | I13: FALSE | J13: Monthly | K13: Method:CRM For QBO | L13: QBO | M13: New | N13: 0 | O13: 0 | P13: 0 | Q13: 0 | R13: 0 | S13: US-3 Month Promo(25% off) | T13: Direct | V13: 7220141 | X13: 0 | Y13: 0 | Z13: 0 | AA13: 1 | AB13: 0 | AC13: 0 | AD13: 0 | AE13: 0 | AF13: 0 | AG13: 0 | AH13: 0 | AI13: 0 | AJ13: 0 | AK13: 0 | AL13: 0 | AM13: 0 | AN13: 0 | AO13: 0 | AP13: =1-SUM(X13:AN13) -> 0 | AQ13: US | AW13: 0 | AX13: 0 | AY13: 0 | AZ13: 1 | BA13: 0 | BB13: 0 | BC13: 45992 | BD13: 48 | BE13: Dec | BF13: 2025 | BG13: United States | BH13: =VLOOKUP(B13,CookieClicks!D:O,12,FALSE) -> https://grow.method.me/crm-quickbooks/?trc=86&trk=how to add signature in quickbooks online&trs=USA-G-QB-Bing&msclkid=557a0cff02eb14d3c64065d2caeb7896&utm_source=bing&utm_medium=cpc&utm_campaign=US - Generic 2020&utm_term=how to add signature in quickbooks online&utm_content=Generic | BI13: =IFERROR(__xludf.DUMMYFUNCTION("VLOOKUP(REGEXREPLACE(BH13,""[?].*"",""""),ContentBuckets!A:C,2,FALSE)"),"#N/A") -> #N/A | BJ13: =IFERROR(__xludf.DUMMYFUNCTION("VLOOKUP(REGEXREPLACE(BH13,""[?].*"",""""),ContentBuckets!A:C,3,FALSE)"),"#N/A") -> #N/A
A14: 153122 | B14: waycosalesinc | C14: 45992.517 | E14: 46007.597 | F14: TRUE | G14: FALSE | H14: FALSE | I14: FALSE | J14: Monthly | K14: Method:CRM For QBO | L14: QBO | M14: New | N14: 165 | O14: 186 | P14: 0 | Q14: 0 | R14: 0 | S14: US-3 Month Promo(25% off) | T14: Direct | V14: 6659644 | X14: 0 | Y14: 0 | Z14: 0 | AA14: 1 | AB14: 0 | AC14: 0 | AD14: 0 | AE14: 0 | AF14: 0 | AG14: 0 | AH14: 0 | AI14: 0 | AJ14: 0 | AK14: 0 | AL14: 0 | AM14: 0 | AN14: 0 | AO14: 0 | AP14: =1-SUM(X14:AN14) -> 0 | AQ14: US | AT14: Other | AU14: 45992 | AV14: 46024.035 | AW14: 13 | AX14: 8098044.1 | AY14: 1917 | AZ14: 4 | BA14: 0 | BB14: 10 | BC14: 45992 | BD14: 48 | BE14: Dec | BF14: 2025 | BG14: United States | BH14: =VLOOKUP(B14,CookieClicks!D:O,12,FALSE) -> https://grow.method.me/crm-quickbooks/?trc=81&trk=crm integrates with quickbooks&trs=US-QBInt&campaignid=1543381580&adgroupid=100383660218&adid=424373886646&gad_source=1&gad_campaignid=1543381580&gclid=Cj0KCQjw64jDBhDXARIsABkk8J7ukkus1kvinzQTfDBa9T3cwLPvsAUFxay55glRRXyqwvQ1Qif88XkaAgwwEALw_wcB | BI14: =IFERROR(__xludf.DUMMYFUNCTION("VLOOKUP(REGEXREPLACE(BH14,""[?].*"",""""),ContentBuckets!A:C,2,FALSE)"),"#N/A") -> #N/A | BJ14: =IFERROR(__xludf.DUMMYFUNCTION("VLOOKUP(REGEXREPLACE(BH14,""[?].*"",""""),ContentBuckets!A:C,3,FALSE)"),"#N/A") -> #N/A
A15: 153124 | B15: aeromarinebiotechllc | C15: 45992.532 | F15: TRUE | G15: FALSE | H15: FALSE | I15: FALSE | J15: Monthly | K15: Method:CRM For QBO | L15: QBO | M15: New | N15: 0 | O15: 63.75 | P15: 0 | Q15: 0 | R15: 28 | S15: US-3 Month Promo(25% off) | T15: Direct | V15: 7220412 | X15: 0 | Y15: 0 | Z15: 1 | AA15: 0 | AB15: 0 | AC15: 0 | AD15: 0 | AE15: 0 | AF15: 0 | AG15: 0 | AH15: 0 | AI15: 0 | AJ15: 0 | AK15: 0 | AL15: 0 | AM15: 0 | AN15: 0 | AO15: 0 | AP15: =1-SUM(X15:AN15) -> 0 | AQ15: US | AR15: Manufacturing (MWD) | AU15: 45992 | AV15: 46023.982 | AW15: 0 | AX15: 610920 | AY15: 47 | AZ15: 1 | BA15: 0 | BB15: 0 | BC15: 45992 | BD15: 48 | BE15: Dec | BF15: 2025 | BG15: United States | BH15: =VLOOKUP(B15,CookieClicks!D:O,12,FALSE) -> https://signup.method.me/QBOAppstoreSignup?offering=methodcrm | BI15: =IFERROR(__xludf.DUMMYFUNCTION("VLOOKUP(REGEXREPLACE(BH15,""[?].*"",""""),ContentBuckets!A:C,2,FALSE)"),"#N/A") -> #N/A | BJ15: =IFERROR(__xludf.DUMMYFUNCTION("VLOOKUP(REGEXREPLACE(BH15,""[?].*"",""""),ContentBuckets!A:C,3,FALSE)"),"#N/A") -> #N/A
A16: 153126 | B16: whitingdesignandelectric | C16: 45992.56 | F16: TRUE | G16: FALSE | H16: FALSE | I16: FALSE | J16: Monthly | K16: Method:CRM For QBO | L16: QBO | M16: New | N16: 0 | O16: 44.25 | P16: 0 | Q16: 0 | R16: 0 | S16: US-3 Month Promo(25% off) | T16: Direct | V16: 7220589 | X16: 0 | Y16: 0 | Z16: 0 | AA16: 1 | AB16: 0 | AC16: 0 | AD16: 0 | AE16: 0 | AF16: 0 | AG16: 0 | AH16: 0 | AI16: 0 | AJ16: 0 | AK16: 0 | AL16: 0 | AM16: 0 | AN16: 0 | AO16: 0 | AP16: =1-SUM(X16:AN16) -> 0 | AU16: 45992 | AV16: 46024.037 | AW16: 1 | AX16: 117120 | AY16: 331 | AZ16: 1 | BA16: 0 | BB16: 0 | BC16: 45992 | BD16: 48 | BE16: Dec | BF16: 2025 | BG16: United States | BH16: =VLOOKUP(B16,CookieClicks!D:O,12,FALSE) -> https://grow.method.me/crm-quickbooks/?trc=81&trk=quickbooks crm&trs=USA-QB-G_Ex&campaignid=22265826203&adgroupid=176758613473&adid=734012603510&gad_source=1&gad_campaignid=22265826203&gbraid=0AAAAAD3ItnbQ-scslMn1OtVxbVSWxN2mJ&gclid=CjwKCAiAlrXJBhBAEiwA-5pgwvitKEc_ApMEwccMJJ-0vo8UrY40YDAv2UXM6GNodmORrMYKZy6gOhoC3A0QAvD_BwE | BI16: =IFERROR(__xludf.DUMMYFUNCTION("VLOOKUP(REGEXREPLACE(BH16,""[?].*"",""""),ContentBuckets!A:C,2,FALSE)"),"#N/A") -> #N/A | BJ16: =IFERROR(__xludf.DUMMYFUNCTION("VLOOKUP(REGEXREPLACE(BH16,""[?].*"",""""),ContentBuckets!A:C,3,FALSE)"),"#N/A") -> #N/A
A17: 153127 | B17: mastercraneandhoist | C17: 45992.584 | E17: 46006.663 | F17: TRUE | G17: FALSE | H17: FALSE | I17: FALSE | J17: Monthly | K17: Method:CRM For QBO | L17: QBO | M17: New | N17: 59 | O17: 59 | P17: 0 | Q17: 0 | R17: 28 | T17: Direct | V17: 7158239 | X17: 0 | Y17: 0 | Z17: 0 | AA17: 0 | AB17: 0 | AC17: 0 | AD17: 0 | AE17: 0 | AF17: 0 | AG17: 0 | AH17: 0 | AI17: 0 | AJ17: 0 | AK17: 0 | AL17: 0 | AM17: 0 | AN17: 0 | AO17: 0 | AP17: =1-SUM(X17:AN17) -> 1 | AQ17: US | AR17: Consulting and Professional Services | AT17: All other professional, scientific, and technical services | AU17: 45992 | AV17: 46024.01 | AW17: 1 | AX17: 0 | AY17: 24 | AZ17: 1 | BA17: 0 | BB17: 6 | BC17: 45992 | BD17: 48 | BE17: Dec | BF17: 2025 | BG17: United States | BH17: =VLOOKUP(B17,CookieClicks!D:O,12,FALSE) -> https://signin.method.me/error?errorCode=165&returnUrl=https%3A%2F%2Fcandhcraneservices.method.me%2Fapps%2FDefault.aspx%23%2Ff71e8a16-2653-4e1e-89d3-37753dce28a2 | BI17: =IFERROR(__xludf.DUMMYFUNCTION("VLOOKUP(REGEXREPLACE(BH17,""[?].*"",""""),ContentBuckets!A:C,2,FALSE)"),"#N/A") -> #N/A | BJ17: =IFERROR(__xludf.DUMMYFUNCTION("VLOOKUP(REGEXREPLACE(BH17,""[?].*"",""""),ContentBuckets!A:C,3,FALSE)"),"#N/A") -> #N/A
A18: 153128 | B18: grety | C18: 45992.584 | D18: 45999.674 | F18: FALSE | G18: TRUE | H18: FALSE | I18: FALSE | J18: Monthly | K18: Method:CRM for QBD | L18: QBDT | M18: New | N18: 0 | O18: 44.25 | P18: 0 | Q18: 0 | R18: 0 | S18: US-3 Month Promo(25% off) | T18: Direct | V18: 7220805 | X18: 1 | Y18: 0 | Z18: 0 | AA18: 0 | AB18: 0 | AC18: 0 | AD18: 0 | AE18: 0 | AF18: 0 | AG18: 0 | AH18: 0 | AI18: 0 | AJ18: 0 | AK18: 0 | AL18: 0 | AM18: 0 | AN18: 0 | AO18: 0 | AP18: =1-SUM(X18:AN18) -> 0 | AV18: 45999.006 | AW18: 0 | AX18: 0 | AY18: 0 | AZ18: 1 | BA18: 0 | BB18: 0 | BC18: 45992 | BD18: 48 | BE18: Dec | BF18: 2025 | BG18: Canada | BH18: =VLOOKUP(B18,CookieClicks!D:O,12,FALSE) -> http://signup.method.me/methodcrm?_gl=1*16dqon3*_gcl_au*NjAzNTg3NTQzLjE3NjQ2MDk3Mjc.*_ga*MjEyOTUxMjU4MC4xNzY0NjA5NzM0*_ga_L2HEZNW53E*czE3NjQ2MDk3MzQkbzEkZzAkdDE3NjQ2MDk3MzUkajU5JGwwJGgxNjczNjM2NjYx&_ga=2.54480033.848033626.1764609734-2129512580.1764609734 | BI18: =IFERROR(__xludf.DUMMYFUNCTION("VLOOKUP(REGEXREPLACE(BH18,""[?].*"",""""),ContentBuckets!A:C,2,FALSE)"),"#N/A") -> #N/A | BJ18: =IFERROR(__xludf.DUMMYFUNCTION("VLOOKUP(REGEXREPLACE(BH18,""[?].*"",""""),ContentBuckets!A:C,3,FALSE)"),"#N/A") -> #N/A
A19: 153129 | B19: danielaziz | C19: 45992.613 | F19: TRUE | G19: FALSE | H19: FALSE | I19: FALSE | J19: Monthly | K19: Method:CRM | L19: QuickBooks | M19: New | N19: 0 | O19: 44.25 | P19: 0 | Q19: 0 | R19: 0 | S19: US-3 Month Promo(25% off) | T19: Direct | V19: 7221061 | X19: 1 | Y19: 0 | Z19: 0 | AA19: 0 | AB19: 0 | AC19: 0 | AD19: 0 | AE19: 0 | AF19: 0 | AG19: 0 | AH19: 0 | AI19: 0 | AJ19: 0 | AK19: 0 | AL19: 0 | AM19: 0 | AN19: 0 | AO19: 0 | AP19: =1-SUM(X19:AN19) -> 0 | AV19: 46023.993 | AW19: 0 | AX19: 0 | AY19: 0 | AZ19: 1 | BA19: 0 | BB19: 0 | BC19: 45992 | BD19: 48 | BE19: Dec | BF19: 2025 | BG19: United States | BH19: =VLOOKUP(B19,CookieClicks!D:O,12,FALSE) -> https://signin.method.me/?returnUrl=https%3A%2F%2Fumjca.methodportal.com%2Fapps%2F | BI19: =IFERROR(__xludf.DUMMYFUNCTION("VLOOKUP(REGEXREPLACE(BH19,""[?].*"",""""),ContentBuckets!A:C,2,FALSE)"),"#N/A") -> #N/A | BJ19: =IFERROR(__xludf.DUMMYFUNCTION("VLOOKUP(REGEXREPLACE(BH19,""[?].*"",""""),ContentBuckets!A:C,3,FALSE)"),"#N/A") -> #N/A
A20: 153130 | B20: knightinsurancesolutions | C20: 45992.629 | D20: 46000.424 | F20: FALSE | G20: TRUE | H20: FALSE | I20: FALSE | J20: Monthly | K20: Method:CRM | L20: QuickBooks | M20: New | N20: 0 | O20: 44.25 | P20: 0 | Q20: 0 | R20: 0 | S20: US-3 Month Promo(25% off) | T20: Direct | V20: 7155332 | W20: https://www.google.com/ | X20: 0 | Y20: 0.6 | Z20: 0 | AA20: 0.4 | AB20: 0 | AC20: 0 | AD20: 0 | AE20: 0 | AF20: 0 | AG20: 0 | AH20: 0 | AI20: 0 | AJ20: 0 | AK20: 0 | AL20: 0 | AM20: 0 | AN20: 0 | AO20: 0 | AP20: =1-SUM(X20:AN20) -> 0 | AV20: 46000.015 | AW20: 0 | AX20: 0 | AY20: 0 | AZ20: 1 | BA20: 0 | BB20: 0 | BC20: 45992 | BD20: 48 | BE20: Dec | BF20: 2025 | BG20: United States | BH20: =VLOOKUP(B20,CookieClicks!D:O,12,FALSE) -> https://grow.method.me/multi-entity/?trc=81&trk=multi-account crm&trs=US-Multi-entity&campaignid=22836319657&adgroupid=183992915458&adid=765768443211&gad_source=1&gad_campaignid=22836319657&gbraid=0AAAAAD3ItnZcCORda2sETHQ4nib78uZ3B&gclid=Cj0KCQiArOvIBhDLARIsAPwJXOaKqhQhO0cz3xMBJwlL3cEyFuApzdc6oy79yWcGj6HiTsVqGqWRzxkaAhctEALw_wcB | BI20: =IFERROR(__xludf.DUMMYFUNCTION("VLOOKUP(REGEXREPLACE(BH20,""[?].*"",""""),ContentBuckets!A:C,2,FALSE)"),"#N/A") -> #N/A | BJ20: =IFERROR(__xludf.DUMMYFUNCTION("VLOOKUP(REGEXREPLACE(BH20,""[?].*"",""""),ContentBuckets!A:C,3,FALSE)"),"#N/A") -> #N/A
A21: 153131 | B21: joeythecoffeeguy | C21: 45992.64 | F21: TRUE | G21: FALSE | H21: FALSE | I21: FALSE | J21: Monthly | K21: Method:CRM For QBO | L21: QBO | M21: New | N21: 0 | O21: 63.75 | P21: 0 | Q21: 0 | R21: 0 | S21: US-3 Month Promo(25% off) | T21: Direct | V21: 7221267 | X21: 0 | Y21: 0 | Z21: 0 | AA21: 1 | AB21: 0 | AC21: 0 | AD21: 0 | AE21: 0 | AF21: 0 | AG21: 0 | AH21: 0 | AI21: 0 | AJ21: 0 | AK21: 0 | AL21: 0 | AM21: 0 | AN21: 0 | AO21: 0 | AP21: =1-SUM(X21:AN21) -> 0 | AQ21: US | AT21: Coffee and tea manufacturing | AU21: 45992 | AV21: 46024.017 | AW21: 1 | AX21: 4891.68 | AY21: 89 | AZ21: 1 | BA21: 0 | BB21: 0 | BC21: 45992 | BD21: 48 | BE21: Dec | BF21: 2025 | BG21: United States | BH21: =VLOOKUP(B21,CookieClicks!D:O,12,FALSE) -> https://grow.method.me/qb-payment/?trc=81&trk=quickbooks online payment processing&trs=US-payment&campaignid=19733246298&adgroupid=146278163933&adid=649435146420&gad_source=1&gad_campaignid=19733246298&gbraid=0AAAAAD3ItnZi9CFAjVhQFCFOFcYmyOWup&gclid=CjwKCAiAlrXJBhBAEiwA-5pgwvgqW2qm5b78Drd4wf59_QQVxH1WepiBjaJvI-eC_MsZ_LDbnGVEVxoC8okQAvD_BwE | BI21: =IFERROR(__xludf.DUMMYFUNCTION("VLOOKUP(REGEXREPLACE(BH21,""[?].*"",""""),ContentBuckets!A:C,2,FALSE)"),"#N/A") -> #N/A | BJ21: =IFERROR(__xludf.DUMMYFUNCTION("VLOOKUP(REGEXREPLACE(BH21,""[?].*"",""""),ContentBuckets!A:C,3,FALSE)"),"#N/A") -> #N/A
A22: 153132 | B22: octopusgdn | C22: 45992.687 | E22: 46007.792 | F22: TRUE | G22: FALSE | H22: FALSE | I22: FALSE | J22: Monthly | K22: Method:CRM For QBO | L22: QBO | M22: New | N22: 44.25 | O22: 44.25 | P22: 0 | Q22: 0 | R22: 28 | S22: US-3 Month Promo(25% off) | T22: Direct | V22: 7034286 | W22: https://www.google.com/ | X22: 0 | Y22: 1 | Z22: 0 | AA22: 0 | AB22: 0 | AC22: 0 | AD22: 0 | AE22: 0 | AF22: 0 | AG22: 0 | AH22: 0 | AI22: 0 | AJ22: 0 | AK22: 0 | AL22: 0 | AM22: 0 | AN22: 0 | AO22: 0 | AP22: =1-SUM(X22:AN22) -> 0 | AQ22: US | AR22: Wholesale and distribution services (MWD) | AT22: Fish and seafood merchant wholesalers | AU22: 45992 | AV22: 46024.037 | AW22: 3 | AX22: 996361.8 | AY22: 89 | AZ22: 1 | BA22: 0 | BB22: 0 | BC22: 45992 | BD22: 48 | BE22: Dec | BF22: 2025 | BG22: United States | BH22: =VLOOKUP(B22,CookieClicks!D:O,12,FALSE) -> https://www.method.me/crm-quickbooks/pricing/ | BI22: =IFERROR(__xludf.DUMMYFUNCTION("VLOOKUP(REGEXREPLACE(BH22,""[?].*"",""""),ContentBuckets!A:C,2,FALSE)"),"/crm-quickbooks/") -> /crm-quickbooks/ | BJ22: =IFERROR(__xludf.DUMMYFUNCTION("VLOOKUP(REGEXREPLACE(BH22,""[?].*"",""""),ContentBuckets!A:C,3,FALSE)"),"Other page") -> Other page
A23: 153134 | B23: cravenscoffee | C23: 45992.769 | F23: TRUE | G23: FALSE | H23: FALSE | I23: FALSE | J23: Monthly | K23: Method:CRM for QBD | L23: QBDT | M23: New | N23: 0 | O23: 109.5 | P23: 0 | Q23: 0 | R23: 28 | S23: US-3 Month Promo(25% off) | T23: Direct | V23: 7012113 | W23: https://chatgpt.com/ | X23: 0 | Y23: 0.4 | Z23: 0 | AA23: 0 | AB23: 0 | AC23: 0.6002 | AD23: 0 | AE23: 0 | AF23: 0 | AG23: 0 | AH23: 0 | AI23: 0 | AJ23: 0 | AK23: 0 | AL23: 0 | AM23: 0 | AN23: 0 | AO23: 0 | AP23: =1-SUM(X23:AN23) -> -0.0002 | AQ23: US | AR23: Wholesale and distribution services (MWD) | AT23: OtherNone | AU23: 45993 | AV23: 46023.995 | AW23: 25 | AX23: 404158.8 | AY23: 732 | AZ23: 2 | BA23: 0 | BB23: 0 | BC23: 45992 | BD23: 48 | BE23: Dec | BF23: 2025 | BG23: United States | BH23: =VLOOKUP(B23,CookieClicks!D:O,12,FALSE) -> https://www.method.me/ | BI23: =IFERROR(__xludf.DUMMYFUNCTION("VLOOKUP(REGEXREPLACE(BH23,""[?].*"",""""),ContentBuckets!A:C,2,FALSE)"),"Homepage") -> Homepage | BJ23: =IFERROR(__xludf.DUMMYFUNCTION("VLOOKUP(REGEXREPLACE(BH23,""[?].*"",""""),ContentBuckets!A:C,3,FALSE)"),"Other page") -> Other page
A24: 153135 | B24: cosmicvisionairesllc | C24: 45992.803 | F24: TRUE | G24: FALSE | H24: FALSE | I24: FALSE | J24: Monthly | K24: Method:CRM For QBO | L24: QBO | M24: New | N24: 0 | O24: 62.25 | P24: 0 | Q24: 0 | R24: 28 | S24: US-3 Month Promo(25% off) | T24: Direct | V24: 7203163 | W24: https://www.google.com/ | X24: 0 | Y24: 0.5 | Z24: 0 | AA24: 0.5 | AB24: 0 | AC24: 0 | AD24: 0 | AE24: 0 | AF24: 0 | AG24: 0 | AH24: 0 | AI24: 0 | AJ24: 0 | AK24: 0 | AL24: 0 | AM24: 0 | AN24: 0 | AO24: 0 | AP24: =1-SUM(X24:AN24) -> 0 | AQ24: US | AR24: IT and computer related | AT24: Software publishers | AU24: 45992 | AV24: 46023.994 | AW24: 0 | AX24: 0 | AY24: 0 | AZ24: 1 | BA24: 0 | BB24: 0 | BC24: 45992 | BD24: 48 | BE24: Dec | BF24: 2025 | BG24: United States | BH24: =VLOOKUP(B24,CookieClicks!D:O,12,FALSE) -> https://www.method.me/ | BI24: =IFERROR(__xludf.DUMMYFUNCTION("VLOOKUP(REGEXREPLACE(BH24,""[?].*"",""""),ContentBuckets!A:C,2,FALSE)"),"Homepage") -> Homepage | BJ24: =IFERROR(__xludf.DUMMYFUNCTION("VLOOKUP(REGEXREPLACE(BH24,""[?].*"",""""),ContentBuckets!A:C,3,FALSE)"),"Other page") -> Other page
A25: 153136 | B25: khshopapp | C25: 45992.827 | F25: TRUE | G25: FALSE | H25: FALSE | I25: FALSE | J25: Monthly | K25: Method:CRM | L25: QuickBooks | M25: New | N25: 0 | O25: 26.25 | P25: 0 | Q25: 0 | R25: 0 | S25: US-3 Month Promo(25% off) | T25: Direct | V25: 7222319 | W25: https://www.google.com/ | X25: 0 | Y25: 1 | Z25: 0 | AA25: 0 | AB25: 0 | AC25: 0 | AD25: 0 | AE25: 0 | AF25: 0 | AG25: 0 | AH25: 0 | AI25: 0 | AJ25: 0 | AK25: 0 | AL25: 0 | AM25: 0 | AN25: 0 | AO25: 0 | AP25: =1-SUM(X25:AN25) -> 0 | AV25: 46024.007 | AW25: 0 | AX25: 0 | AY25: 0 | AZ25: 1 | BA25: 0 | BB25: 0 | BC25: 45992 | BD25: 48 | BE25: Dec | BF25: 2025 | BG25: Egypt | BH25: =VLOOKUP(B25,CookieClicks!D:O,12,FALSE) -> http://signup.method.me/donor/ | BI25: =IFERROR(__xludf.DUMMYFUNCTION("VLOOKUP(REGEXREPLACE(BH25,""[?].*"",""""),ContentBuckets!A:C,2,FALSE)"),"#N/A") -> #N/A | BJ25: =IFERROR(__xludf.DUMMYFUNCTION("VLOOKUP(REGEXREPLACE(BH25,""[?].*"",""""),ContentBuckets!A:C,3,FALSE)"),"#N/A") -> #N/A
A26: 153138 | B26: servicerankprocommateiucwebcompaniesllc | C26: 45992.931 | F26: TRUE | G26: FALSE | H26: FALSE | I26: FALSE | J26: Monthly | K26: Method:CRM For QBO | L26: QBO | M26: New | N26: 0 | O26: 81 | P26: 0 | Q26: 0 | R26: 28 | S26: US-3 Month Promo(25% off) | T26: Direct | V26: 7222778 | X26: 0 | Y26: 0 | Z26: 0 | AA26: 0 | AB26: 0 | AC26: 0 | AD26: 0 | AE26: 0 | AF26: 0 | AG26: 0 | AH26: 0 | AI26: 0 | AJ26: 0 | AK26: 0 | AL26: 0 | AM26: 0 | AN26: 0 | AO26: 0 | AP26: =1-SUM(X26:AN26) -> 1 | AQ26: US | AR26: Consulting and Professional Services | AU26: 45992 | AV26: 46024.026 | AW26: 0 | AX26: 6600 | AY26: 26 | AZ26: 2 | BA26: 0 | BB26: 0 | BC26: 45992 | BD26: 48 | BE26: Dec | BF26: 2025 | BG26: United States | BH26: =VLOOKUP(B26,CookieClicks!D:O,12,FALSE) -> http://signup.method.me/methodcrm?_gl=1*35xga*_gcl_au*OTA4NzE2NzI5LjE3NjQ2NDU2NTg.*_ga*MTI1ODgwNDgzOS4xNzY0NjQ1NjU4*_ga_L2HEZNW53E*czE3NjQ2NDU2NTgkbzEkZzAkdDE3NjQ2NDU2NTgkajYwJGwwJGgzNDc2MjkzNDg.&_ga=2.76960469.1538964529.1764645658-1258804839.1764645658 | BI26: =IFERROR(__xludf.DUMMYFUNCTION("VLOOKUP(REGEXREPLACE(BH26,""[?].*"",""""),ContentBuckets!A:C,2,FALSE)"),"#N/A") -> #N/A | BJ26: =IFERROR(__xludf.DUMMYFUNCTION("VLOOKUP(REGEXREPLACE(BH26,""[?].*"",""""),ContentBuckets!A:C,3,FALSE)"),"#N/A") -> #N/A
A27: 153139 | B27: test212 | C27: 45992.956 | F27: TRUE | G27: FALSE | H27: FALSE | I27: FALSE | J27: Monthly | K27: Method:CRM for QBD | L27: QBDT | M27: New | N27: 0 | O27: 44.25 | P27: 0 | Q27: 0 | R27: 28 | S27: US-3 Month Promo(25% off) | T27: Direct | V27: 7222681 | X27: 0 | Y27: 0 | Z27: 0 | AA27: 0 | AB27: 0 | AC27: 1 | AD27: 0 | AE27: 0 | AF27: 0 | AG27: 0 | AH27: 0 | AI27: 0 | AJ27: 0 | AK27: 0 | AL27: 0 | AM27: 0 | AN27: 0 | AO27: 0 | AP27: =1-SUM(X27:AN27) -> 0 | AQ27: US | AR27: Wholesale and distribution services (MWD) | AT27: WholesaleDistributionandSales | AU27: 45992 | AV27: 46024.03 | AW27: 0 | AX27: 1943.4 | AY27: 3 | AZ27: 1 | BA27: 0 | BB27: 0 | BC27: 45992 | BD27: 48 | BE27: Dec | BF27: 2025 | BG27: United States | BH27: =VLOOKUP(B27,CookieClicks!D:O,12,FALSE) -> https://www.method.me/ | BI27: =IFERROR(__xludf.DUMMYFUNCTION("VLOOKUP(REGEXREPLACE(BH27,""[?].*"",""""),ContentBuckets!A:C,2,FALSE)"),"Homepage") -> Homepage | BJ27: =IFERROR(__xludf.DUMMYFUNCTION("VLOOKUP(REGEXREPLACE(BH27,""[?].*"",""""),ContentBuckets!A:C,3,FALSE)"),"Other page") -> Other page
A28: 153140 | B28: butleragway | C28: 45992.958 | F28: TRUE | G28: FALSE | H28: FALSE | I28: FALSE | J28: Monthly | K28: Method:CRM | L28: None | M28: New | N28: 0 | O28: 44.25 | P28: 0 | Q28: 0 | R28: 0 | S28: US-3 Month Promo(25% off) | T28: Direct | V28: 7222912 | X28: 0 | Y28: 0 | Z28: 0 | AA28: 1 | AB28: 0 | AC28: 0 | AD28: 0 | AE28: 0 | AF28: 0 | AG28: 0 | AH28: 0 | AI28: 0 | AJ28: 0 | AK28: 0 | AL28: 0 | AM28: 0 | AN28: 0 | AO28: 0 | AP28: =1-SUM(X28:AN28) -> 0 | AV28: 46023.981 | AW28: 0 | AX28: 0 | AY28: 0 | AZ28: 1 | BA28: 0 | BB28: 0 | BC28: 45992 | BD28: 48 | BE28: Dec | BF28: 2025 | BG28: United States | BH28: =VLOOKUP(B28,CookieClicks!D:O,12,FALSE) -> https://www.method.me/?trc=81&trk=PMax&trs=PMax-FS&campaignid=21074820200&adgroupid&adid&gad_source=5&gad_campaignid=21077580125 | BI28: =IFERROR(__xludf.DUMMYFUNCTION("VLOOKUP(REGEXREPLACE(BH28,""[?].*"",""""),ContentBuckets!A:C,2,FALSE)"),"Homepage") -> Homepage | BJ28: =IFERROR(__xludf.DUMMYFUNCTION("VLOOKUP(REGEXREPLACE(BH28,""[?].*"",""""),ContentBuckets!A:C,3,FALSE)"),"Other page") -> Other page
A29: 153141 | B29: westernheatingandairllc | C29: 45992.972 | E29: 46006.532 | F29: TRUE | G29: FALSE | H29: FALSE | I29: FALSE | J29: Prepay | K29: Method:CRM For QBO | L29: QBO | M29: New | N29: 53.1 | O29: 59 | P29: 0 | Q29: 0 | R29: 28 | T29: Direct | V29: 7222975 | X29: 1 | Y29: 0 | Z29: 0 | AA29: 0 | AB29: 0 | AC29: 0 | AD29: 0 | AE29: 0 | AF29: 0 | AG29: 0 | AH29: 0 | AI29: 0 | AJ29: 0 | AK29: 0 | AL29: 0 | AM29: 0 | AN29: 0 | AO29: 0 | AP29: =1-SUM(X29:AN29) -> 0 | AQ29: US | AR29: Field Services | AU29: 45993 | AV29: 46024.042 | AW29: 2 | AX29: 1592809.9 | AY29: 843 | AZ29: 1 | BA29: 0 | BB29: 5 | BC29: 45992 | BD29: 48 | BE29: Dec | BF29: 2025 | BG29: United States | BH29: =VLOOKUP(B29,CookieClicks!D:O,12,FALSE) -> http://signup.method.me/methodcrm/ | BI29: =IFERROR(__xludf.DUMMYFUNCTION("VLOOKUP(REGEXREPLACE(BH29,""[?].*"",""""),ContentBuckets!A:C,2,FALSE)"),"#N/A") -> #N/A | BJ29: =IFERROR(__xludf.DUMMYFUNCTION("VLOOKUP(REGEXREPLACE(BH29,""[?].*"",""""),ContentBuckets!A:C,3,FALSE)"),"#N/A") -> #N/A
A30: 153142 | B30: makeready | C30: 45993.035 | F30: TRUE | G30: FALSE | H30: FALSE | I30: FALSE | J30: Monthly | K30: Method:CRM For QBO | L30: QBO | M30: New | N30: 0 | O30: 53.25 | P30: 0 | Q30: 0 | R30: 0 | S30: US-3 Month Promo(25% off) | T30: Direct | V30: 7223248 | X30: 0 | Y30: 0 | Z30: 0 | AA30: 1 | AB30: 0 | AC30: 0 | AD30: 0 | AE30: 0 | AF30: 0 | AG30: 0 | AH30: 0 | AI30: 0 | AJ30: 0 | AK30: 0 | AL30: 0 | AM30: 0 | AN30: 0 | AO30: 0 | AP30: =1-SUM(X30:AN30) -> 0 | AV30: 46024.01 | AW30: 0 | AX30: 0 | AY30: 0 | AZ30: 1 | BA30: 0 | BB30: 0 | BC30: 45993 | BD30: 48 | BE30: Dec | BF30: 2025 | BG30: United States | BH30: =VLOOKUP(B30,CookieClicks!D:O,12,FALSE) -> https://grow.method.me/crm-quickbooks/?trc=86&trk=quickbook estimate&trs=USA-G-QB-Bing&msclkid=9d5a77cb2b2b167e1c921ee5569f174b&utm_source=bing&utm_medium=cpc&utm_campaign=US - Generic 2020&utm_term=quickbook estimate&utm_content=Generic | BI30: =IFERROR(__xludf.DUMMYFUNCTION("VLOOKUP(REGEXREPLACE(BH30,""[?].*"",""""),ContentBuckets!A:C,2,FALSE)"),"#N/A") -> #N/A | BJ30: =IFERROR(__xludf.DUMMYFUNCTION("VLOOKUP(REGEXREPLACE(BH30,""[?].*"",""""),ContentBuckets!A:C,3,FALSE)"),"#N/A") -> #N/A
A31: 153143 | B31: cloudheroes2 | C31: 45993.297 | F31: TRUE | G31: FALSE | H31: FALSE | I31: FALSE | J31: Monthly | K31: Method:CRM For QBO | L31: QBO | M31: New | N31: 0 | O31: 236.25 | P31: 0 | Q31: 0 | R31: 28 | S31: US-3 Month Promo(25% off) | T31: Direct | V31: 7224530 | W31: https://www.google.com/ | X31: 0 | Y31: 1 | Z31: 0 | AA31: 0 | AB31: 0 | AC31: 0 | AD31: 0 | AE31: 0 | AF31: 0 | AG31: 0 | AH31: 0 | AI31: 0 | AJ31: 0 | AK31: 0 | AL31: 0 | AM31: 0 | AN31: 0 | AO31: 0 | AP31: =1-SUM(X31:AN31) -> 0 | AQ31: GB | AR31: IT and computer related | AU31: 45993 | AV31: 46023.993 | AW31: 4 | AX31: 154369.32 | AY31: 1305 | AZ31: 2 | BA31: 0 | BB31: 1 | BC31: 45993 | BD31: 48 | BE31: Dec | BF31: 2025 | BG31: United Kingdom | BH31: =VLOOKUP(B31,CookieClicks!D:O,12,FALSE) -> https://www.method.me/ | BI31: =IFERROR(__xludf.DUMMYFUNCTION("VLOOKUP(REGEXREPLACE(BH31,""[?].*"",""""),ContentBuckets!A:C,2,FALSE)"),"Homepage") -> Homepage | BJ31: =IFERROR(__xludf.DUMMYFUNCTION("VLOOKUP(REGEXREPLACE(BH31,""[?].*"",""""),ContentBuckets!A:C,3,FALSE)"),"Other page") -> Other page
A32: 153144 | B32: umjca2 | C32: 45993.306 | D32: 46000.642 | F32: FALSE | G32: FALSE | H32: FALSE | I32: FALSE | J32: Monthly | K32: Method:CRM For QBO | L32: QBO | M32: New | N32: 0 | O32: 44.25 | P32: 0 | Q32: 0 | R32: 0 | S32: US-3 Month Promo(25% off) | T32: Direct | V32: 7224570 | X32: 1 | Y32: 0 | Z32: 0 | AA32: 0 | AB32: 0 | AC32: 0 | AD32: 0 | AE32: 0 | AF32: 0 | AG32: 0 | AH32: 0 | AI32: 0 | AJ32: 0 | AK32: 0 | AL32: 0 | AM32: 0 | AN32: 0 | AO32: 0 | AP32: =1-SUM(X32:AN32) -> 0 | AV32: 46000.042 | AW32: 0 | AX32: 0 | AY32: 0 | AZ32: 1 | BA32: 0 | BB32: 0 | BC32: 45993 | BD32: 48 | BE32: Dec | BF32: 2025 | BG32: United States | BH32: =VLOOKUP(B32,CookieClicks!D:O,12,FALSE) -> https://signin.method.me/?returnUrl=https%3A%2F%2Fumjca.methodportal.com%2Fapps%2F | BI32: =IFERROR(__xludf.DUMMYFUNCTION("VLOOKUP(REGEXREPLACE(BH32,""[?].*"",""""),ContentBuckets!A:C,2,FALSE)"),"#N/A") -> #N/A | BJ32: =IFERROR(__xludf.DUMMYFUNCTION("VLOOKUP(REGEXREPLACE(BH32,""[?].*"",""""),ContentBuckets!A:C,3,FALSE)"),"#N/A") -> #N/A
A33: 153145 | B33: fetzerfinancial8 | C33: 45993.333 | F33: TRUE | G33: FALSE | H33: FALSE | I33: FALSE | J33: Monthly | K33: Method:CRM For QBO | L33: QBO | M33: New | N33: 0 | O33: 54.75 | P33: 0 | Q33: 0 | R33: 28 | S33: US-3 Month Promo(25% off) | T33: Direct | V33: 7224692 | X33: 0 | Y33: 0 | Z33: 1 | AA33: 0 | AB33: 0 | AC33: 0 | AD33: 0 | AE33: 0 | AF33: 0 | AG33: 0 | AH33: 0 | AI33: 0 | AJ33: 0 | AK33: 0 | AL33: 0 | AM33: 0 | AN33: 0 | AO33: 0 | AP33: =1-SUM(X33:AN33) -> 0 | AQ33: US | AR33: Accounting and Bookkeeping | AU33: 45993 | AV33: 46023.999 | AW33: 2 | AX33: 0 | AY33: 1550 | AZ33: 1 | BA33: 0 | BB33: 0 | BC33: 45993 | BD33: 48 | BE33: Dec | BF33: 2025 | BG33: United States | BH33: =VLOOKUP(B33,CookieClicks!D:O,12,FALSE) -> https://signup.method.me/QBOAppstoreSignup?offering=methodcrm | BI33: =IFERROR(__xludf.DUMMYFUNCTION("VLOOKUP(REGEXREPLACE(BH33,""[?].*"",""""),ContentBuckets!A:C,2,FALSE)"),"#N/A") -> #N/A | BJ33: =IFERROR(__xludf.DUMMYFUNCTION("VLOOKUP(REGEXREPLACE(BH33,""[?].*"",""""),ContentBuckets!A:C,3,FALSE)"),"#N/A") -> #N/A
A34: 153146 | B34: platinumplaygrounds | C34: 45993.335 | F34: TRUE | G34: FALSE | H34: FALSE | I34: FALSE | J34: Monthly | K34: Method:CRM For QBO | L34: QBO | M34: New | N34: 0 | O34: 150.75 | P34: 0 | Q34: 0 | R34: 28 | S34: US-3 Month Promo(25% off) | T34: Direct | V34: 7148020 | X34: 1 | Y34: 0 | Z34: 0 | AA34: 0 | AB34: 0 | AC34: 0 | AD34: 0 | AE34: 0 | AF34: 0 | AG34: 0 | AH34: 0 | AI34: 0 | AJ34: 0 | AK34: 0 | AL34: 0 | AM34: 0 | AN34: 0 | AO34: 0 | AP34: =1-SUM(X34:AN34) -> 0 | AQ34: US | AR34: Other | AT34: 21 | AU34: 45993 | AV34: 46024.038 | AW34: 30 | AX34: 183336 | AY34: 1068 | AZ34: 3 | BA34: 0 | BB34: 0 | BC34: 45993 | BD34: 48 | BE34: Dec | BF34: 2025 | BG34: United States | BH34: =VLOOKUP(B34,CookieClicks!D:O,12,FALSE) -> https://www.method.me/industries/field-service-management-software/?utm_source=chatgpt.com | BI34: =IFERROR(__xludf.DUMMYFUNCTION("VLOOKUP(REGEXREPLACE(BH34,""[?].*"",""""),ContentBuckets!A:C,2,FALSE)"),"Industries page") -> Industries page | BJ34: =IFERROR(__xludf.DUMMYFUNCTION("VLOOKUP(REGEXREPLACE(BH34,""[?].*"",""""),ContentBuckets!A:C,3,FALSE)"),"Other page") -> Other page
A35: 153147 | B35: rvrepairnearmellc | C35: 45993.36 | F35: TRUE | G35: FALSE | H35: FALSE | I35: FALSE | J35: Monthly | K35: Method:FieldServices for QBD | L35: QBDT | M35: New | N35: 0 | O35: 44.25 | P35: 0 | Q35: 0 | R35: 28 | S35: US-3 Month Promo(25% off) | T35: Direct | V35: 7224805 | X35: 0 | Y35: 0 | Z35: 0 | AA35: 1 | AB35: 0 | AC35: 0 | AD35: 0 | AE35: 0 | AF35: 0 | AG35: 0 | AH35: 0 | AI35: 0 | AJ35: 0 | AK35: 0 | AL35: 0 | AM35: 0 | AN35: 0 | AO35: 0 | AP35: =1-SUM(X35:AN35) -> 0 | AR35: Field Services | AV35: 46024.023 | AW35: 0 | AX35: 0 | AY35: 0 | AZ35: 1 | BA35: 0 | BB35: 0 | BC35: 45993 | BD35: 48 | BE35: Dec | BF35: 2025 | BG35: United States | BH35: =VLOOKUP(B35,CookieClicks!D:O,12,FALSE) -> https://grow.method.me/quickbooks-fsm/?trc=81&trk=quickbooks work order management&trs=US-WorkOrder&campaignid=12406628869&adgroupid=118144098877&adid=500417359916&gad_source=1&gad_campaignid=12406628869&gbraid=0AAAAAD3Itnbb-v0p7Dw7Bhdk7OpsQaId8&gclid=Cj0KCQiAubrJBhCbARIsAHIdxD9PhuzgzFx4d3Oeatq_oulj9ZdbZgTzuwu80IJCqEK0UFsHKWmAAL4aAnntEALw_wcB | BI35: =IFERROR(__xludf.DUMMYFUNCTION("VLOOKUP(REGEXREPLACE(BH35,""[?].*"",""""),ContentBuckets!A:C,2,FALSE)"),"#N/A") -> #N/A | BJ35: =IFERROR(__xludf.DUMMYFUNCTION("VLOOKUP(REGEXREPLACE(BH35,""[?].*"",""""),ContentBuckets!A:C,3,FALSE)"),"#N/A") -> #N/A
A36: 153157 | B36: individual6 | C36: 45993.44 | F36: TRUE | G36: FALSE | H36: FALSE | I36: FALSE | J36: Monthly | K36: Method:CRM For QBO | L36: QBO | M36: New | N36: 0 | O36: 62.25 | P36: 0 | Q36: 0 | R36: 28 | S36: US-3 Month Promo(25% off) | T36: Direct | V36: 7225423 | X36: 0 | Y36: 0 | Z36: 0 | AA36: 1 | AB36: 0 | AC36: 0 | AD36: 0 | AE36: 0 | AF36: 0 | AG36: 0 | AH36: 0 | AI36: 0 | AJ36: 0 | AK36: 0 | AL36: 0 | AM36: 0 | AN36: 0 | AO36: 0 | AP36: =1-SUM(X36:AN36) -> 0 | AQ36: US | AR36: Other | AU36: 45995 | AV36: 46024.006 | AW36: 0 | AX36: 0 | AY36: 583 | AZ36: 1 | BA36: 0 | BB36: 0 | BC36: 45993 | BD36: 48 | BE36: Dec | BF36: 2025 | BG36: United States | BH36: =VLOOKUP(B36,CookieClicks!D:O,12,FALSE) -> https://grow.method.me/crm-quickbooks/?trc=81&trk=quickbooks crm&trs=USA-QB-G_Ex&campaignid=22265826203&adgroupid=176758613473&adid=734012603510&gad_source=1&gad_campaignid=22265826203&gbraid=0AAAAAD3ItnbZS3z8l6nzYVFFMJ1qRT6ol&gclid=Cj0KCQiAubrJBhCbARIsAHIdxD91Aj2WQqPOZpBBh09mY5kWzXBsLLrHYQVGPGApxr6fWSq1XW-0KsgaAk0GEALw_wcB | BI36: =IFERROR(__xludf.DUMMYFUNCTION("VLOOKUP(REGEXREPLACE(BH36,""[?].*"",""""),ContentBuckets!A:C,2,FALSE)"),"#N/A") -> #N/A | BJ36: =IFERROR(__xludf.DUMMYFUNCTION("VLOOKUP(REGEXREPLACE(BH36,""[?].*"",""""),ContentBuckets!A:C,3,FALSE)"),"#N/A") -> #N/A
A37: 153158 | B37: thenesthomeimprovementcentreinc | C37: 45993.447 | F37: TRUE | G37: FALSE | H37: FALSE | I37: FALSE | J37: Monthly | K37: Method:CRM For QBO | L37: QBO | M37: New | N37: 0 | O37: 54.75 | P37: 0 | Q37: 0 | R37: 28 | S37: US-3 Month Promo(25% off) | T37: Direct | V37: 7225452 | W37: https://www.google.com/ | X37: 0 | Y37: 1 | Z37: 0 | AA37: 0 | AB37: 0 | AC37: 0 | AD37: 0 | AE37: 0 | AF37: 0 | AG37: 0 | AH37: 0 | AI37: 0 | AJ37: 0 | AK37: 0 | AL37: 0 | AM37: 0 | AN37: 0 | AO37: 0 | AP37: =1-SUM(X37:AN37) -> 0 | AQ37: CA | AR37: Other | AU37: 45993 | AV37: 46024.03 | AW37: 0 | AX37: 93603.72 | AY37: 241 | AZ37: 1 | BA37: 0 | BB37: 0 | BC37: 45993 | BD37: 48 | BE37: Dec | BF37: 2025 | BG37: Canada | BH37: =VLOOKUP(B37,CookieClicks!D:O,12,FALSE) -> https://www.method.me/ | BI37: =IFERROR(__xludf.DUMMYFUNCTION("VLOOKUP(REGEXREPLACE(BH37,""[?].*"",""""),ContentBuckets!A:C,2,FALSE)"),"Homepage") -> Homepage | BJ37: =IFERROR(__xludf.DUMMYFUNCTION("VLOOKUP(REGEXREPLACE(BH37,""[?].*"",""""),ContentBuckets!A:C,3,FALSE)"),"Other page") -> Other page
A38: 153159 | B38: garcyusa | C38: 45993.463 | F38: TRUE | G38: FALSE | H38: FALSE | I38: FALSE | J38: Monthly | K38: Method:FieldServices for QBD | L38: QBDT | M38: New | N38: 0 | O38: 54.75 | P38: 0 | Q38: 0 | R38: 28 | S38: US-3 Month Promo(25% off) | T38: Direct | V38: 7225548 | W38: https://www.google.com/ | X38: 0 | Y38: 1 | Z38: 0 | AA38: 0 | AB38: 0 | AC38: 0 | AD38: 0 | AE38: 0 | AF38: 0 | AG38: 0 | AH38: 0 | AI38: 0 | AJ38: 0 | AK38: 0 | AL38: 0 | AM38: 0 | AN38: 0 | AO38: 0 | AP38: =1-SUM(X38:AN38) -> 0 | AQ38: US | AR38: Manufacturing (MWD) | AT38: Manufacturing | AU38: 45993 | AV38: 46023.999 | AW38: 0 | AX38: 0 | AY38: 1 | AZ38: 1 | BA38: 0 | BB38: 0 | BC38: 45993 | BD38: 48 | BE38: Dec | BF38: 2025 | BG38: United States | BH38: =VLOOKUP(B38,CookieClicks!D:O,12,FALSE) -> https://www.method.me/ | BI38: =IFERROR(__xludf.DUMMYFUNCTION("VLOOKUP(REGEXREPLACE(BH38,""[?].*"",""""),ContentBuckets!A:C,2,FALSE)"),"Homepage") -> Homepage | BJ38: =IFERROR(__xludf.DUMMYFUNCTION("VLOOKUP(REGEXREPLACE(BH38,""[?].*"",""""),ContentBuckets!A:C,3,FALSE)"),"Other page") -> Other page
A39: 153160 | B39: vandalenindustries | C39: 45993.469 | E39: 46010.613 | F39: TRUE | G39: FALSE | H39: FALSE | I39: FALSE | J39: Monthly | K39: Method:CRM for QBD | L39: QBDT | M39: New | N39: 318.75 | O39: 318.75 | P39: 0 | Q39: 0 | R39: 28 | S39: US-3 Month Promo(25% off) | T39: Direct | V39: 7224722 | X39: 0 | Y39: 0 | Z39: 0 | AA39: 1 | AB39: 0 | AC39: 0 | AD39: 0 | AE39: 0 | AF39: 0 | AG39: 0 | AH39: 0 | AI39: 0 | AJ39: 0 | AK39: 0 | AL39: 0 | AM39: 0 | AN39: 0 | AO39: 0 | AP39: =1-SUM(X39:AN39) -> 0 | AQ39: US | AR39: Construction | AT39: retail | AU39: 45996 | AV39: 46024.04 | AW39: 36 | AX39: 3509037 | AY39: 2882 | AZ39: 5 | BA39: 0 | BB39: 3 | BC39: 45993 | BD39: 48 | BE39: Dec | BF39: 2025 | BG39: United States | BH39: =VLOOKUP(B39,CookieClicks!D:O,12,FALSE) -> https://grow.method.me/crm-quickbooks/?trc=81&trk=quickbooks crm&trs=USA-QB-G_Ex&campaignid=22265826203&adgroupid=176758613473&adid=734012603510&gad_source=1&gad_campaignid=22265826203&gbraid=0AAAAAD3ItnbZS3z8l6nzYVFFMJ1qRT6ol&gclid=Cj0KCQiAubrJBhCbARIsAHIdxD9TJfHqIbvGNWgRIlJBUeVw2pz6Co67n1sZyTh7dICR2olwrmUWYYYaAty5EALw_wcB | BI39: =IFERROR(__xludf.DUMMYFUNCTION("VLOOKUP(REGEXREPLACE(BH39,""[?].*"",""""),ContentBuckets!A:C,2,FALSE)"),"#N/A") -> #N/A | BJ39: =IFERROR(__xludf.DUMMYFUNCTION("VLOOKUP(REGEXREPLACE(BH39,""[?].*"",""""),ContentBuckets!A:C,3,FALSE)"),"#N/A") -> #N/A
A40: 153161 | B40: pizzahurt | C40: 45993.474 | F40: TRUE | G40: FALSE | H40: FALSE | I40: FALSE | J40: Monthly | K40: Method:CRM | L40: QuickBooks | M40: New | N40: 0 | O40: 44.25 | P40: 0 | Q40: 0 | R40: 0 | S40: US-3 Month Promo(25% off) | T40: Direct | V40: 7225705 | X40: 0 | Y40: 0 | Z40: 0 | AA40: 1 | AB40: 0 | AC40: 0 | AD40: 0 | AE40: 0 | AF40: 0 | AG40: 0 | AH40: 0 | AI40: 0 | AJ40: 0 | AK40: 0 | AL40: 0 | AM40: 0 | AN40: 0 | AO40: 0 | AP40: =1-SUM(X40:AN40) -> 0 | AV40: 46024.02 | AW40: 0 | AX40: 0 | AY40: 0 | AZ40: 1 | BA40: 0 | BB40: 0 | BC40: 45993 | BD40: 48 | BE40: Dec | BF40: 2025 | BG40: United States | BH40: =VLOOKUP(B40,CookieClicks!D:O,12,FALSE) -> https://grow.method.me/crm-quickbooks/?trk=capterra&trc=78&trs=Capterra_destinationURL&utm_source=capterra&utm_medium=cpc&utm_campaign=destinationURL&gdmcid=c29c73e3-2013-4457-9593-8e7a2867d847 | BI40: =IFERROR(__xludf.DUMMYFUNCTION("VLOOKUP(REGEXREPLACE(BH40,""[?].*"",""""),ContentBuckets!A:C,2,FALSE)"),"#N/A") -> #N/A | BJ40: =IFERROR(__xludf.DUMMYFUNCTION("VLOOKUP(REGEXREPLACE(BH40,""[?].*"",""""),ContentBuckets!A:C,3,FALSE)"),"#N/A") -> #N/A
...

Sheet CookieClicks
A1: CookieClickID | B1: CreatedDate | C1: CookieID | D1: CompanyAccount | E1: SignUpDate | F1: AttributionAmount | G1: Cost | H1: CampaignOriginal | I1: SplitOriginal | J1: CampaignAdjusted | K1: CampaignAdjustedType | L1: SplitAdjusted | M1: Keyword | N1: Referrer | O1: URL | P1: BrowserInfo | Q1: IPAddress | R1: IsToBeIgnored | S1: AttributionType | T1: LastAdjusted | U1: Day | V1: Week | W1: Month | X1: Year | Y1: AdjustedByRule | Z1: SyncRegion | AA1: SignUpCountry | AB1: IsConversionExeption | AC1: AppName | AD1: AccountingPlatform
A2: 7989715 | B2: 45991.99 | C2: 7217712 | D2: multdoor | E2: 45991.991 | F2: 1 | G2: 0 | J2: SEO | K2: SEO | L2: Google | M2: DirectSEO | N2: https://www.google.com/ | O2: https://www.method.me/ | P2: Mozilla/5.0 (Macintosh; Intel Mac OS X 10_15_7) AppleWebKit/605.1.15 (KHTML, like Gecko) Version/18.5 Safari/605.1.15 | Q2: 104.28.133.33 | R2: FALSE | S2: U | T2: 45991.992 | U2: 45991 | V2: 47 | W2: Nov | X2: 2025 | Y2: 130-SEO: google (DirectSEO) | Z2: CA | AA2: Canada | AB2: FALSE | AC2: QBO | AD2: New
A3: 7990183 | B3: 45992.128 | C3: 7218180 | D3: alromanimechanicalworkshop6 | E3: 45992.129 | F3: 1 | G3: 0 | J3: SEO | K3: SEO | L3: Google | M3: DirectSEO | N3: https://www.google.com/ | O3: https://www.method.me/ | P3: Mozilla/5.0 (Windows NT 10.0; Win64; x64) AppleWebKit/537.36 (KHTML, like Gecko) Chrome/142.0.0.0 Safari/537.36 | Q3: 188.70.49.221 | R3: FALSE | S3: U | T3: 45992.131 | U3: 45992 | V3: 48 | W3: Dec | X3: 2025 | Y3: 130-SEO: google (DirectSEO) | Z3: KW | AA3: Kuwait | AB3: FALSE | AC3: QBO | AD3: New
A4: 7990312 | B4: 45992.175 | C4: 7218307 | D4: student26 | E4: 45992.176 | F4: 1 | G4: 0 | J4: Other - Generic | K4: Other | M4: DirectSEO | N4: https://claude.ai/ | O4: https://www.method.me/blog/construction-project-success-crm-solution/ | P4: Mozilla/5.0 (Windows NT 10.0; Win64; x64) AppleWebKit/537.36 (KHTML, like Gecko) Chrome/142.0.0.0 Safari/537.36 | Q4: 140.213.148.239 | R4: FALSE | S4: U | T4: 45992.177 | U4: 45992 | V4: 48 | W4: Dec | X4: 2025 | Y4: 500-Other: catch-all remainders (DirectSEO) | AA4: Indonesia | AB4: FALSE | AC4: QuickBooks | AD4: New
A5: 7976046 | B5: 45988.269 | C5: 7204189 | D5: healthcaremaintenanceservices | E5: 45992.326 | F5: 1 | G5: 0 | J5: SEO | K5: SEO | L5: Google | M5: DirectSEO | N5: https://www.google.com/ | O5: https://www.method.me/blog/quickbooks-customer-portal/ | P5: Mozilla/5.0 (Windows NT 10.0; Win64; x64) AppleWebKit/537.36 (KHTML, like Gecko) Chrome/142.0.0.0 Safari/537.36 Edg/142.0.0.0 | Q5: 200.12.168.23 | R5: FALSE | S5: U | T5: 45992.327 | U5: 45988 | V5: 47 | W5: Nov | X5: 2025 | Y5: 130-SEO: google (DirectSEO) | Z5: US | AA5: United States | AB5: FALSE | AC5: QBO | AD5: New
A6: 7943172 | B6: 45981.349 | C6: 7171808 | D6: customoutdoorkitchens | E6: 45992.336 | F6: 1 | G6: 0 | J6: SEO | K6: SEO | L6: Google | M6: DirectSEO | N6: https://www.google.com/ | O6: https://www.method.me/ | P6: Mozilla/5.0 (Windows NT 10.0; Win64; x64) AppleWebKit/537.36 (KHTML, like Gecko) Chrome/142.0.0.0 Safari/537.36 | Q6: 94.140.11.156 | R6: FALSE | S6: U | T6: 45992.338 | U6: 45981 | V6: 46 | W6: Nov | X6: 2025 | Y6: 130-SEO: google (DirectSEO) | Z6: US | AA6: United States | AB6: FALSE | AC6: QBO | AD6: New
A7: 7940245 | B7: 45980.624 | C7: 7168930 | D7: manexusa | E7: 45992.342 | F7: 1 | G7: 0 | J7: Direct | K7: Direct | L7: blank | M7: DirectSEO | O7: http://signup.method.me/methodcrm | P7: Mozilla/5.0 (Windows NT 10.0; Win64; x64) AppleWebKit/537.36 (KHTML, like Gecko) Chrome/142.0.0.0 Safari/537.36 Edg/142.0.0.0 | Q7: 69.202.176.104, 52.9.26.127 | R7: FALSE | S7: U | T7: 46000.338 | U7: 45980 | V7: 46 | W7: Nov | X7: 2025 | Y7: 50-Direct: Referrer Blank (Direct) | AA7: United States | AB7: TRUE | AC7: QuickBooks | AD7: New
A8: 7990876 | B8: 45992.341 | C8: 7218855 | D8: reddoorpestcontrol2 | E8: 45992.347 | F8: 1 | G8: 0 | J8: Direct | K8: Direct | L8: blank | M8: DirectSEO | O8: https://signin.method.me/Password/Reset?rpcode=-nZQ0G03B%2bIuTre9Gdsw3ggkv!rw%3du%3dJPbRgJ7a-UmqVNiskXhWYwfMQB8a5 | P8: Mozilla/5.0 (iPhone; CPU iPhone OS 18_6_2 like Mac OS X) AppleWebKit/605.1.15 (KHTML, like Gecko) CriOS/142.0.7444.148 Mobile/15E148 Safari/604.1 | Q8: 65.24.101.202 | R8: FALSE | S8: U | T8: 45992.348 | U8: 45992 | V8: 48 | W8: Dec | X8: 2025 | Y8: 50-Direct: Referrer Blank (Direct) | Z8: US | AA8: United States | AB8: FALSE | AC8: QBO | AD8: New
A9: 7940245 | B9: 45980.624 | C9: 7168930 | D9: manexusa2 | E9: 45992.362 | F9: 1 | G9: 0 | J9: Direct | K9: Direct | L9: blank | M9: DirectSEO | O9: http://signup.method.me/methodcrm | P9: Mozilla/5.0 (Windows NT 10.0; Win64; x64) AppleWebKit/537.36 (KHTML, like Gecko) Chrome/142.0.0.0 Safari/537.36 Edg/142.0.0.0 | Q9: 69.202.176.104, 52.9.26.127 | R9: FALSE | S9: U | T9: 46000.338 | U9: 45980 | V9: 46 | W9: Nov | X9: 2025 | Y9: 50-Direct: Referrer Blank (Direct) | Z9: US | AA9: United States | AB9: TRUE | AC9: QBDT | AD9: New
A10: 7982156 | B10: 45989.695 | C10: 7210242 | D10: jlbcompanies | E10: 45992.416 | F10: 1 | G10: 0 | J10: SEO | K10: SEO | L10: Google | M10: DirectSEO | N10: https://www.google.com/ | O10: https://www.method.me/ | P10: Mozilla/5.0 (Macintosh; Intel Mac OS X 10_15_7) AppleWebKit/537.36 (KHTML, like Gecko) Chrome/142.0.0.0 Safari/537.36 | Q10: 74.244.21.218 | R10: FALSE | S10: U | T10: 45992.417 | U10: 45989 | V10: 47 | W10: Nov | X10: 2025 | Y10: 130-SEO: google (DirectSEO) | Z10: US | AA10: United States | AB10: FALSE | AC10: QBO | AD10: New
A11: 7962989 | B11: 45985.632 | C11: 7191321 | D11: ssisanitary | E11: 45992.461 | F11: 1 | G11: 0 | J11: SEO | K11: SEO | L11: Google | M11: DirectSEO | N11: https://www.google.com/ | O11: https://www.method.me/ | P11: Mozilla/5.0 (Windows NT 10.0; Win64; x64) AppleWebKit/537.36 (KHTML, like Gecko) Chrome/142.0.0.0 Safari/537.36 | Q11: 66.41.215.134 | R11: FALSE | S11: U | T11: 45992.463 | U11: 45985 | V11: 47 | W11: Nov | X11: 2025 | Y11: 130-SEO: google (DirectSEO) | Z11: US | AA11: United States | AB11: FALSE | AC11: QBO | AD11: New
A12: 7992024 | B12: 45992.474 | C12: 7219935 | D12: highendcompaniesllc | E12: 45992.476 | F12: 1 | G12: 0 | J12: SEO | K12: SEO | L12: Google | M12: DirectSEO | N12: https://www.google.com/ | O12: https://www.method.me/ | P12: Mozilla/5.0 (Macintosh; Intel Mac OS X 10_15_7) AppleWebKit/605.1.15 (KHTML, like Gecko) Version/18.0.1 Safari/605.1.15 | Q12: 70.170.147.21 | R12: FALSE | S12: U | T12: 45992.478 | U12: 45992 | V12: 48 | W12: Dec | X12: 2025 | Y12: 130-SEO: google (DirectSEO) | Z12: US | AA12: United States | AB12: FALSE | AC12: QBO | AD12: New
A13: 7992242 | B13: 45992.497 | C13: 7220141 | D13: jirehtransmissionsllc | E13: 45992.497 | F13: 1 | G13: 0 | H13: Bing | I13: USA-G-QB-Bing | J13: Bing | K13: Pay Per Click | L13: USA-G-QB-Bing | M13: how_to_add_signature_in_quickbooks_online | N13: https://www.bing.com/ | O13: https://grow.method.me/crm-quickbooks/?trc=86&trk=how to add signature in quickbooks online&trs=USA-G-QB-Bing&msclkid=557a0cff02eb14d3c64065d2caeb7896&utm_source=bing&utm_medium=cpc&utm_campaign=US - Generic 2020&utm_term=how to add signature in quickbooks online&utm_content=Generic | P13: Mozilla/5.0 (Windows NT 10.0; Win64; x64) AppleWebKit/537.36 (KHTML, like Gecko) Chrome/138.0.0.0 Safari/537.36 Edg/138.0.0.0 | Q13: 142.79.74.157 | R13: FALSE | S13: U | T13: 45992.499 | U13: 45992 | V13: 48 | W13: Dec | X13: 2025 | Y13: - | Z13: US | AA13: United States | AB13: FALSE | AC13: QBO | AD13: New
A14: 7413817 | B14: 45838.512 | C14: 6659644 | D14: waycosalesinc | E14: 45992.517 | F14: 1 | G14: 0 | H14: AdWords | I14: US-QBInt | J14: AdWords | K14: Pay Per Click | L14: US-QBInt | M14: crm_integrates_with_quickbooks | N14: https://www.google.com/ | O14: https://grow.method.me/crm-quickbooks/?trc=81&trk=crm integrates with quickbooks&trs=US-QBInt&campaignid=1543381580&adgroupid=100383660218&adid=424373886646&gad_source=1&gad_campaignid=1543381580&gclid=Cj0KCQjw64jDBhDXARIsABkk8J7ukkus1kvinzQTfDBa9T3cwLPvsAUFxay55glRRXyqwvQ1Qif88XkaAgwwEALw_wcB | P14: Mozilla/5.0 (Windows NT 10.0; Win64; x64) AppleWebKit/537.36 (KHTML, like Gecko) Chrome/134.0.0.0 Safari/537.36 OPR/119.0.0.0 | Q14: 76.166.152.133 | R14: FALSE | S14: U | T14: 45992.519 | U14: 45838 | V14: 26 | W14: Jun | X14: 2025 | Y14: - | Z14: US | AA14: United States | AB14: FALSE | AC14: QBO | AD14: New
A15: 7992525 | B15: 45992.531 | C15: 7220412 | D15: aeromarinebiotechllc | E15: 45992.532 | F15: 1 | G15: 0 | J15: Intuit App Card Traffic | K15: OPN - Other Peoples Networks | L15: Intuit | M15: DirectSEO | N15: https://appcenter.intuit.com/ | O15: https://signup.method.me/QBOAppstoreSignup?offering=methodcrm | P15: Mozilla/5.0 (Windows NT 10.0; Win64; x64) AppleWebKit/537.36 (KHTML, like Gecko) Chrome/142.0.0.0 Safari/537.36 Edg/142.0.0.0 | Q15: 65.184.140.156 | R15: FALSE | S15: U | T15: 45992.533 | U15: 45992 | V15: 48 | W15: Dec | X15: 2025 | Y15: 179-ReferralLink: intuit (OPN) - App center | Z15: US | AA15: United States | AB15: FALSE | AC15: QBO | AD15: New
A16: 7992707 | B16: 45992.554 | C16: 7220589 | D16: whitingdesignandelectric | E16: 45992.56 | F16: 1 | G16: 0 | H16: AdWords | I16: USA-QB-G_Ex | J16: AdWords | K16: Pay Per Click | L16: USA-QB-G_Ex | M16: quickbooks_crm | N16: https://www.google.com/ | O16: https://grow.method.me/crm-quickbooks/?trc=81&trk=quickbooks crm&trs=USA-QB-G_Ex&campaignid=22265826203&adgroupid=176758613473&adid=734012603510&gad_source=1&gad_campaignid=22265826203&gbraid=0AAAAAD3ItnbQ-scslMn1OtVxbVSWxN2mJ&gclid=CjwKCAiAlrXJBhBAEiwA-5pgwvitKEc_ApMEwccMJJ-0vo8UrY40YDAv2UXM6GNodmORrMYKZy6gOhoC3A0QAvD_BwE | P16: Mozilla/5.0 (Macintosh; Intel Mac OS X 10_15_7) AppleWebKit/537.36 (KHTML, like Gecko) Chrome/142.0.0.0 Safari/537.36 | Q16: 174.162.141.142 | R16: FALSE | S16: U | T16: 45992.561 | U16: 45992 | V16: 48 | W16: Dec | X16: 2025 | Y16: - | AA16: United States | AB16: FALSE | AC16: QBO | AD16: New
A17: 7929360 | B17: 45978.595 | C17: 7158239 | D17: mastercraneandhoist | E17: 45992.584 | F17: 0 | G17: 0 | M17: DirectSEO | N17: https://candhcraneservices.method.me/ | O17: https://signin.method.me/error?errorCode=165&returnUrl=https%3A%2F%2Fcandhcraneservices.method.me%2Fapps%2FDefault.aspx%23%2Ff71e8a16-2653-4e1e-89d3-37753dce28a2 | P17: Mozilla/5.0 (Windows NT 10.0; Win64; x64) AppleWebKit/537.36 (KHTML, like Gecko) Chrome/142.0.0.0 Safari/537.36 Edg/142.0.0.0 | Q17: 139.94.200.69 | R17: TRUE | S17: U | T17: 45992.585 | U17: 45978 | V17: 46 | W17: Nov | X17: 2025 | Y17: 10-Ignore Referrer https method.me | Z17: US | AA17: United States | AB17: FALSE | AC17: QBO | AD17: New
A18: 7992930 | B18: 45992.583 | C18: 7220805 | D18: grety | E18: 45992.584 | F18: 1 | G18: 0 | J18: Direct | K18: Direct | L18: blank | M18: DirectSEO | O18: http://signup.method.me/methodcrm?_gl=1*16dqon3*_gcl_au*NjAzNTg3NTQzLjE3NjQ2MDk3Mjc.*_ga*MjEyOTUxMjU4MC4xNzY0NjA5NzM0*_ga_L2HEZNW53E*czE3NjQ2MDk3MzQkbzEkZzAkdDE3NjQ2MDk3MzUkajU5JGwwJGgxNjczNjM2NjYx&_ga=2.54480033.848033626.1764609734-2129512580.1764609734 | P18: Mozilla/5.0 (Windows NT 10.0; Win64; x64) AppleWebKit/537.36 (KHTML, like Gecko) Chrome/142.0.0.0 Safari/537.36 | Q18: 205.250.238.119, 52.9.26.127 | R18: FALSE | S18: U | T18: 45992.585 | U18: 45992 | V18: 48 | W18: Dec | X18: 2025 | Y18: 50-Direct: Referrer Blank (Direct) | AA18: Canada | AB18: TRUE | AC18: QBDT | AD18: New
A19: 7993203 | B19: 45992.613 | C19: 7221061 | D19: danielaziz | E19: 45992.613 | F19: 1 | G19: 0 | J19: Direct | K19: Direct | L19: blank | M19: DirectSEO | O19: https://signin.method.me/?returnUrl=https%3A%2F%2Fumjca.methodportal.com%2Fapps%2F | P19: Mozilla/5.0 (iPhone; CPU iPhone OS 18_6_2 like Mac OS X) AppleWebKit/605.1.15 (KHTML, like Gecko) Version/18.6 Mobile/15E148 Safari/604.1 | Q19: 100.2.9.141 | R19: FALSE | S19: U | T19: 45992.615 | U19: 45992 | V19: 48 | W19: Dec | X19: 2025 | Y19: 50-Direct: Referrer Blank (Direct) | AA19: United States | AB19: FALSE | AC19: QuickBooks | AD19: New
