Workbook

Sheet AccountSummary (New)
A1: SyncType | B1: All | C1: QBDT | D1: QBDT | E1: QBO | F1: QBO | G1: Xero | H1: none | I1: All | J1: QBDT | K1: QBDT | L1: QBO | M1: QBO | N1: Xero | O1: none | P1: All | Q1: QBDT | R1: QBDT | S1: QBO | T1: QBO | U1: Xero | V1: none | W1: All
A2: Platform | B2: All | C2: Classic | D2: New | E2: Classic | F2: New | G2: New | H2: New | I2: All | J2: Classic | K2: New | L2: Classic | M2: New | N2: New | O2: New | P2: All | Q2: Classic | R2: New | S2: Classic | T2: New | U2: New | V2: New | W2: All
A3: Channel | B3: All | C3: Referred | D3: Referred | E3: Referred | F3: Referred | G3: Referred | H3: Referred | I3: Referred | J3: Managed | K3: Managed | L3: Managed | M3: Managed | N3: Managed | O3: Managed | P3: Managed | Q3: Direct | R3: Direct | S3: Direct | T3: Direct | U3: Direct | V3: Direct | W3: Direct
A4: *Trialers*
A5: Trials started this month | B5: =I5+P5+W5 -> 0 | C5: =COUNTIFS(Accounts!$E:$E,'AccountSummary (New)'!C$1,Accounts!$G:$G,'AccountSummary (New)'!C$2,Accounts!$F:$F,'AccountSummary (New)'!C$3,Accounts!$B:$B,"none",Accounts!$BF:$BF,FALSE) -> 0 | D5: =COUNTIFS(Accounts!$E:$E,'AccountSummary (New)'!D$1,Accounts!$G:$G,'AccountSummary (New)'!D$2,Accounts!$F:$F,'AccountSummary (New)'!D$3,Accounts!$B:$B,"none",Accounts!$BF:$BF,FALSE) -> 0 | E5: =COUNTIFS(Accounts!$E:$E,'AccountSummary (New)'!E$1,Accounts!$G:$G,'AccountSummary (New)'!E$2,Accounts!$F:$F,'AccountSummary (New)'!E$3,Accounts!$B:$B,"none",Accounts!$BF:$BF,FALSE) -> 0 | F5: =COUNTIFS(Accounts!$E:$E,'AccountSummary (New)'!F$1,Accounts!$G:$G,'AccountSummary (New)'!F$2,Accounts!$F:$F,'AccountSummary (New)'!F$3,Accounts!$B:$B,"none",Accounts!$BF:$BF,FALSE) -> 0 | G5: =COUNTIFS(Accounts!$E:$E,'AccountSummary (New)'!G$1,Accounts!$G:$G,'AccountSummary (New)'!G$2,Accounts!$F:$F,'AccountSummary (New)'!G$3,Accounts!$B:$B,"none",Accounts!$BF:$BF,FALSE) -> 0 | H5: =COUNTIFS(Accounts!$E:$E,'AccountSummary (New)'!H$1,Accounts!$G:$G,'AccountSummary (New)'!H$2,Accounts!$F:$F,'AccountSummary (New)'!H$3,Accounts!$B:$B,"none",Accounts!$BF:$BF,FALSE)+COUNTIFS(Accounts!$E:$E,"QuickBooks",Accounts!$G:$G,'AccountSummary (New)'!H$2,Accounts!$F:$F,'AccountSummary (New)'!H$3,Accounts!$B:$B,"none",Accounts!$BF:$BF,FALSE) -> 0 | I5: =SUM(C5:H5) -> 0 | J5: =COUNTIFS(Accounts!$E:$E,'AccountSummary (New)'!J$1,Accounts!$G:$G,'AccountSummary (New)'!J$2,Accounts!$F:$F,'AccountSummary (New)'!J$3,Accounts!$B:$B,"none",Accounts!$BF:$BF,FALSE) -> 0 | K5: =COUNTIFS(Accounts!$E:$E,'AccountSummary (New)'!K$1,Accounts!$G:$G,'AccountSummary (New)'!K$2,Accounts!$F:$F,'AccountSummary (New)'!K$3,Accounts!$B:$B,"none",Accounts!$BF:$BF,FALSE) -> 0 | L5: =COUNTIFS(Accounts!$E:$E,'AccountSummary (New)'!L$1,Accounts!$G:$G,'AccountSummary (New)'!L$2,Accounts!$F:$F,'AccountSummary (New)'!L$3,Accounts!$B:$B,"none",Accounts!$BF:$BF,FALSE) -> 0 | M5: =COUNTIFS(Accounts!$E:$E,'AccountSummary (New)'!M$1,Accounts!$G:$G,'AccountSummary (New)'!M$2,Accounts!$F:$F,'AccountSummary (New)'!M$3,Accounts!$B:$B,"none",Accounts!$BF:$BF,FALSE) -> 0 | N5: =COUNTIFS(Accounts!$E:$E,'AccountSummary (New)'!N$1,Accounts!$G:$G,'AccountSummary (New)'!N$2,Accounts!$F:$F,'AccountSummary (New)'!N$3,Accounts!$B:$B,"none",Accounts!$BF:$BF,FALSE) -> 0 | O5: =COUNTIFS(Accounts!$E:$E,'AccountSummary (New)'!O$1,Accounts!$G:$G,'AccountSummary (New)'!O$2,Accounts!$F:$F,'AccountSummary (New)'!O$3,Accounts!$B:$B,"none",Accounts!$BF:$BF,FALSE)+COUNTIFS(Accounts!$E:$E,"QuickBooks",Accounts!$G:$G,'AccountSummary (New)'!O$2,Accounts!$F:$F,'AccountSummary (New)'!O$3,Accounts!$B:$B,"none",Accounts!$BF:$BF,FALSE) -> 0 | P5: =SUM(J5:O5) -> 0 | Q5: =COUNTIFS(Accounts!$E:$E,'AccountSummary (New)'!Q$1,Accounts!$G:$G,'AccountSummary (New)'!Q$2,Accounts!$F:$F,'AccountSummary (New)'!Q$3,Accounts!$B:$B,"none",Accounts!$BF:$BF,FALSE) -> 0 | R5: =COUNTIFS(Accounts!$E:$E,'AccountSummary (New)'!R$1,Accounts!$G:$G,'AccountSummary (New)'!R$2,Accounts!$F:$F,'AccountSummary (New)'!R$3,Accounts!$B:$B,"none",Accounts!$BF:$BF,FALSE) -> 0 | S5: =COUNTIFS(Accounts!$E:$E,'AccountSummary (New)'!S$1,Accounts!$G:$G,'AccountSummary (New)'!S$2,Accounts!$F:$F,'AccountSummary (New)'!S$3,Accounts!$B:$B,"none",Accounts!$BF:$BF,FALSE) -> 0 | T5: =COUNTIFS(Accounts!$E:$E,'AccountSummary (New)'!T$1,Accounts!$G:$G,'AccountSummary (New)'!T$2,Accounts!$F:$F,'AccountSummary (New)'!T$3,Accounts!$B:$B,"none",Accounts!$BF:$BF,FALSE) -> 0 | U5: =COUNTIFS(Accounts!$E:$E,'AccountSummary (New)'!U$1,Accounts!$G:$G,'AccountSummary (New)'!U$2,Accounts!$F:$F,'AccountSummary (New)'!U$3,Accounts!$B:$B,"none",Accounts!$BF:$BF,FALSE) -> 0 | V5: =COUNTIFS(Accounts!$E:$E,'AccountSummary (New)'!V$1,Accounts!$G:$G,'AccountSummary (New)'!V$2,Accounts!$F:$F,'AccountSummary (New)'!V$3,Accounts!$B:$B,"none",Accounts!$BF:$BF,FALSE)+COUNTIFS(Accounts!$E:$E,"QuickBooks",Accounts!$G:$G,'AccountSummary (New)'!V$2,Accounts!$F:$F,'AccountSummary (New)'!V$3,Accounts!$B:$B,"none",Accounts!$BF:$BF,FALSE) -> 0 | W5: =SUM(Q5:V5) -> 0
A7: Made their first payment | B7: =I7+P7+W7 -> 0 | C7: =COUNTIFS(Accounts!$E:$E,'AccountSummary (New)'!C$1,Accounts!$G:$G,'AccountSummary (New)'!C$2,Accounts!$F:$F,'AccountSummary (New)'!C$3,Accounts!$W:$W,1) -> 0 | D7: =COUNTIFS(Accounts!$E:$E,'AccountSummary (New)'!D$1,Accounts!$G:$G,'AccountSummary (New)'!D$2,Accounts!$F:$F,'AccountSummary (New)'!D$3,Accounts!$W:$W,1) -> 0 | E7: =COUNTIFS(Accounts!$E:$E,'AccountSummary (New)'!E$1,Accounts!$G:$G,'AccountSummary (New)'!E$2,Accounts!$F:$F,'AccountSummary (New)'!E$3,Accounts!$W:$W,1) -> 0 | F7: =COUNTIFS(Accounts!$E:$E,'AccountSummary (New)'!F$1,Accounts!$G:$G,'AccountSummary (New)'!F$2,Accounts!$F:$F,'AccountSummary (New)'!F$3,Accounts!$W:$W,1) -> 0 | G7: =COUNTIFS(Accounts!$E:$E,'AccountSummary (New)'!G$1,Accounts!$G:$G,'AccountSummary (New)'!G$2,Accounts!$F:$F,'AccountSummary (New)'!G$3,Accounts!$W:$W,1) -> 0 | H7: =COUNTIFS(Accounts!$E:$E,'AccountSummary (New)'!H$1,Accounts!$G:$G,'AccountSummary (New)'!H$2,Accounts!$F:$F,'AccountSummary (New)'!H$3,Accounts!$W:$W,1) -> 0 | I7: =SUM(C7:H7) -> 0 | J7: =COUNTIFS(Accounts!$E:$E,'AccountSummary (New)'!J$1,Accounts!$G:$G,'AccountSummary (New)'!J$2,Accounts!$F:$F,'AccountSummary (New)'!J$3,Accounts!$W:$W,1) -> 0 | K7: =COUNTIFS(Accounts!$E:$E,'AccountSummary (New)'!K$1,Accounts!$G:$G,'AccountSummary (New)'!K$2,Accounts!$F:$F,'AccountSummary (New)'!K$3,Accounts!$W:$W,1) -> 0 | L7: =COUNTIFS(Accounts!$E:$E,'AccountSummary (New)'!L$1,Accounts!$G:$G,'AccountSummary (New)'!L$2,Accounts!$F:$F,'AccountSummary (New)'!L$3,Accounts!$W:$W,1) -> 0 | M7: =COUNTIFS(Accounts!$E:$E,'AccountSummary (New)'!M$1,Accounts!$G:$G,'AccountSummary (New)'!M$2,Accounts!$F:$F,'AccountSummary (New)'!M$3,Accounts!$W:$W,1) -> 0 | N7: =COUNTIFS(Accounts!$E:$E,'AccountSummary (New)'!N$1,Accounts!$G:$G,'AccountSummary (New)'!N$2,Accounts!$F:$F,'AccountSummary (New)'!N$3,Accounts!$W:$W,1) -> 0 | O7: =COUNTIFS(Accounts!$E:$E,'AccountSummary (New)'!O$1,Accounts!$G:$G,'AccountSummary (New)'!O$2,Accounts!$F:$F,'AccountSummary (New)'!O$3,Accounts!$W:$W,1) -> 0 | P7: =SUM(J7:O7) -> 0 | Q7: =COUNTIFS(Accounts!$E:$E,'AccountSummary (New)'!Q$1,Accounts!$G:$G,'AccountSummary (New)'!Q$2,Accounts!$F:$F,'AccountSummary (New)'!Q$3,Accounts!$W:$W,1) -> 0 | R7: =COUNTIFS(Accounts!$E:$E,'AccountSummary (New)'!R$1,Accounts!$G:$G,'AccountSummary (New)'!R$2,Accounts!$F:$F,'AccountSummary (New)'!R$3,Accounts!$W:$W,1) -> 0 | S7: =COUNTIFS(Accounts!$E:$E,'AccountSummary (New)'!S$1,Accounts!$G:$G,'AccountSummary (New)'!S$2,Accounts!$F:$F,'AccountSummary (New)'!S$3,Accounts!$W:$W,1) -> 0 | T7: =COUNTIFS(Accounts!$E:$E,'AccountSummary (New)'!T$1,Accounts!$G:$G,'AccountSummary (New)'!T$2,Accounts!$F:$F,'AccountSummary (New)'!T$3,Accounts!$W:$W,1) -> 0 | U7: =COUNTIFS(Accounts!$E:$E,'AccountSummary (New)'!U$1,Accounts!$G:$G,'AccountSummary (New)'!U$2,Accounts!$F:$F,'AccountSummary (New)'!U$3,Accounts!$W:$W,1) -> 0 | V7: =COUNTIFS(Accounts!$E:$E,'AccountSummary (New)'!V$1,Accounts!$G:$G,'AccountSummary (New)'!V$2,Accounts!$F:$F,'AccountSummary (New)'!V$3,Accounts!$W:$W,1) -> 0 | W7: =SUM(Q7:V7) -> 0
A8: Packs per Account | B8: =IF(B7=0,0,SUMIFS(Accounts!$L:$L,Accounts!$W:$W,1)/B7) -> 0 | C8: =IF(C7=0,0,SUMIFS(Accounts!$L:$L,Accounts!$E:$E,'AccountSummary (New)'!C$1,Accounts!$G:$G,'AccountSummary (New)'!C$2,Accounts!$F:$F,'AccountSummary (New)'!C$3,Accounts!$W:$W,1)/C7) -> 0 | D8: =IF(D7=0,0,SUMIFS(Accounts!$L:$L,Accounts!$E:$E,'AccountSummary (New)'!D$1,Accounts!$G:$G,'AccountSummary (New)'!D$2,Accounts!$F:$F,'AccountSummary (New)'!D$3,Accounts!$W:$W,1)/D7) -> 0 | E8: =IF(E7=0,0,SUMIFS(Accounts!$L:$L,Accounts!$E:$E,'AccountSummary (New)'!E$1,Accounts!$G:$G,'AccountSummary (New)'!E$2,Accounts!$F:$F,'AccountSummary (New)'!E$3,Accounts!$W:$W,1)/E7) -> 0 | F8: =IF(F7=0,0,SUMIFS(Accounts!$L:$L,Accounts!$E:$E,'AccountSummary (New)'!F$1,Accounts!$G:$G,'AccountSummary (New)'!F$2,Accounts!$F:$F,'AccountSummary (New)'!F$3,Accounts!$W:$W,1)/F7) -> 0 | G8: =IF(G7=0,0,SUMIFS(Accounts!$L:$L,Accounts!$E:$E,'AccountSummary (New)'!G$1,Accounts!$G:$G,'AccountSummary (New)'!G$2,Accounts!$F:$F,'AccountSummary (New)'!G$3,Accounts!$W:$W,1)/G7) -> 0 | H8: =IF(H7=0,0,SUMIFS(Accounts!$L:$L,Accounts!$E:$E,'AccountSummary (New)'!H$1,Accounts!$G:$G,'AccountSummary (New)'!H$2,Accounts!$F:$F,'AccountSummary (New)'!H$3,Accounts!$W:$W,1)/H7) -> 0 | I8: =IF(I7=0,0,SUMIFS(Accounts!$L:$L,Accounts!$F:$F,'AccountSummary (New)'!I$3,Accounts!$W:$W,1)/I7) -> 0 | J8: =IF(J7=0,0,SUMIFS(Accounts!$L:$L,Accounts!$E:$E,'AccountSummary (New)'!J$1,Accounts!$G:$G,'AccountSummary (New)'!J$2,Accounts!$F:$F,'AccountSummary (New)'!J$3,Accounts!$W:$W,1)/J7) -> 0 | K8: =IF(K7=0,0,SUMIFS(Accounts!$L:$L,Accounts!$E:$E,'AccountSummary (New)'!K$1,Accounts!$G:$G,'AccountSummary (New)'!K$2,Accounts!$F:$F,'AccountSummary (New)'!K$3,Accounts!$W:$W,1)/K7) -> 0 | L8: =IF(L7=0,0,SUMIFS(Accounts!$L:$L,Accounts!$E:$E,'AccountSummary (New)'!L$1,Accounts!$G:$G,'AccountSummary (New)'!L$2,Accounts!$F:$F,'AccountSummary (New)'!L$3,Accounts!$W:$W,1)/L7) -> 0 | M8: =IF(M7=0,0,SUMIFS(Accounts!$L:$L,Accounts!$E:$E,'AccountSummary (New)'!M$1,Accounts!$G:$G,'AccountSummary (New)'!M$2,Accounts!$F:$F,'AccountSummary (New)'!M$3,Accounts!$W:$W,1)/M7) -> 0 | N8: =IF(N7=0,0,SUMIFS(Accounts!$L:$L,Accounts!$E:$E,'AccountSummary (New)'!N$1,Accounts!$G:$G,'AccountSummary (New)'!N$2,Accounts!$F:$F,'AccountSummary (New)'!N$3,Accounts!$W:$W,1)/N7) -> 0 | O8: =IF(O7=0,0,SUMIFS(Accounts!$L:$L,Accounts!$E:$E,'AccountSummary (New)'!O$1,Accounts!$G:$G,'AccountSummary (New)'!O$2,Accounts!$F:$F,'AccountSummary (New)'!O$3,Accounts!$W:$W,1)/O7) -> 0 | P8: =IF(P7=0,0,SUMIFS(Accounts!$L:$L,Accounts!$F:$F,'AccountSummary (New)'!P$3,Accounts!$W:$W,1)/P7) -> 0 | Q8: =IF(Q7=0,0,SUMIFS(Accounts!$L:$L,Accounts!$E:$E,'AccountSummary (New)'!Q$1,Accounts!$G:$G,'AccountSummary (New)'!Q$2,Accounts!$F:$F,'AccountSummary (New)'!Q$3,Accounts!$W:$W,1)/Q7) -> 0 | R8: =IF(R7=0,0,SUMIFS(Accounts!$L:$L,Accounts!$E:$E,'AccountSummary (New)'!R$1,Accounts!$G:$G,'AccountSummary (New)'!R$2,Accounts!$F:$F,'AccountSummary (New)'!R$3,Accounts!$W:$W,1)/R7) -> 0 | S8: =IF(S7=0,0,SUMIFS(Accounts!$L:$L,Accounts!$E:$E,'AccountSummary (New)'!S$1,Accounts!$G:$G,'AccountSummary (New)'!S$2,Accounts!$F:$F,'AccountSummary (New)'!S$3,Accounts!$W:$W,1)/S7) -> 0 | T8: =IF(T7=0,0,SUMIFS(Accounts!$L:$L,Accounts!$E:$E,'AccountSummary (New)'!T$1,Accounts!$G:$G,'AccountSummary (New)'!T$2,Accounts!$F:$F,'AccountSummary (New)'!T$3,Accounts!$W:$W,1)/T7) -> 0 | U8: =IF(U7=0,0,SUMIFS(Accounts!$L:$L,Accounts!$E:$E,'AccountSummary (New)'!U$1,Accounts!$G:$G,'AccountSummary (New)'!U$2,Accounts!$F:$F,'AccountSummary (New)'!U$3,Accounts!$W:$W,1)/U7) -> 0 | V8: =IF(V7=0,0,SUMIFS(Accounts!$L:$L,Accounts!$E:$E,'AccountSummary (New)'!V$1,Accounts!$G:$G,'AccountSummary (New)'!V$2,Accounts!$F:$F,'AccountSummary (New)'!V$3,Accounts!$W:$W,1)/V7) -> 0 | W8: =IF(W7=0,0,SUMIFS(Accounts!$L:$L,Accounts!$F:$F,'AccountSummary (New)'!W$3,Accounts!$W:$W,1)/W7) -> 0
A9: Users per Account | B9: =IF(B7=0,0,SUMIFS(Accounts!$M:$M,Accounts!$W:$W,1)/B7) -> 0 | C9: =IF(C7=0,0,SUMIFS(Accounts!$M:$M,Accounts!$E:$E,'AccountSummary (New)'!C$1,Accounts!$G:$G,'AccountSummary (New)'!C$2,Accounts!$F:$F,'AccountSummary (New)'!C$3,Accounts!$W:$W,1)/C7) -> 0 | D9: =IF(D7=0,0,SUMIFS(Accounts!$M:$M,Accounts!$E:$E,'AccountSummary (New)'!D$1,Accounts!$G:$G,'AccountSummary (New)'!D$2,Accounts!$F:$F,'AccountSummary (New)'!D$3,Accounts!$W:$W,1)/D7) -> 0 | E9: =IF(E7=0,0,SUMIFS(Accounts!$M:$M,Accounts!$E:$E,'AccountSummary (New)'!E$1,Accounts!$G:$G,'AccountSummary (New)'!E$2,Accounts!$F:$F,'AccountSummary (New)'!E$3,Accounts!$W:$W,1)/E7) -> 0 | F9: =IF(F7=0,0,SUMIFS(Accounts!$M:$M,Accounts!$E:$E,'AccountSummary (New)'!F$1,Accounts!$G:$G,'AccountSummary (New)'!F$2,Accounts!$F:$F,'AccountSummary (New)'!F$3,Accounts!$W:$W,1)/F7) -> 0 | G9: =IF(G7=0,0,SUMIFS(Accounts!$M:$M,Accounts!$E:$E,'AccountSummary (New)'!G$1,Accounts!$G:$G,'AccountSummary (New)'!G$2,Accounts!$F:$F,'AccountSummary (New)'!G$3,Accounts!$W:$W,1)/G7) -> 0 | H9: =IF(H7=0,0,SUMIFS(Accounts!$M:$M,Accounts!$E:$E,'AccountSummary (New)'!H$1,Accounts!$G:$G,'AccountSummary (New)'!H$2,Accounts!$F:$F,'AccountSummary (New)'!H$3,Accounts!$W:$W,1)/H7) -> 0 | I9: =IF(I7=0,0,SUMIFS(Accounts!$M:$M,Accounts!$F:$F,'AccountSummary (New)'!I$3,Accounts!$W:$W,1)/I7) -> 0 | J9: =IF(J7=0,0,SUMIFS(Accounts!$M:$M,Accounts!$E:$E,'AccountSummary (New)'!J$1,Accounts!$G:$G,'AccountSummary (New)'!J$2,Accounts!$F:$F,'AccountSummary (New)'!J$3,Accounts!$W:$W,1)/J7) -> 0 | K9: =IF(K7=0,0,SUMIFS(Accounts!$M:$M,Accounts!$E:$E,'AccountSummary (New)'!K$1,Accounts!$G:$G,'AccountSummary (New)'!K$2,Accounts!$F:$F,'AccountSummary (New)'!K$3,Accounts!$W:$W,1)/K7) -> 0 | L9: =IF(L7=0,0,SUMIFS(Accounts!$M:$M,Accounts!$E:$E,'AccountSummary (New)'!L$1,Accounts!$G:$G,'AccountSummary (New)'!L$2,Accounts!$F:$F,'AccountSummary (New)'!L$3,Accounts!$W:$W,1)/L7) -> 0 | M9: =IF(M7=0,0,SUMIFS(Accounts!$M:$M,Accounts!$E:$E,'AccountSummary (New)'!M$1,Accounts!$G:$G,'AccountSummary (New)'!M$2,Accounts!$F:$F,'AccountSummary (New)'!M$3,Accounts!$W:$W,1)/M7) -> 0 | N9: =IF(N7=0,0,SUMIFS(Accounts!$M:$M,Accounts!$E:$E,'AccountSummary (New)'!N$1,Accounts!$G:$G,'AccountSummary (New)'!N$2,Accounts!$F:$F,'AccountSummary (New)'!N$3,Accounts!$W:$W,1)/N7) -> 0 | O9: =IF(O7=0,0,SUMIFS(Accounts!$M:$M,Accounts!$E:$E,'AccountSummary (New)'!O$1,Accounts!$G:$G,'AccountSummary (New)'!O$2,Accounts!$F:$F,'AccountSummary (New)'!O$3,Accounts!$W:$W,1)/O7) -> 0 | P9: =IF(P7=0,0,SUMIFS(Accounts!$M:$M,Accounts!$F:$F,'AccountSummary (New)'!P$3,Accounts!$W:$W,1)/P7) -> 0 | Q9: =IF(Q7=0,0,SUMIFS(Accounts!$M:$M,Accounts!$E:$E,'AccountSummary (New)'!Q$1,Accounts!$G:$G,'AccountSummary (New)'!Q$2,Accounts!$F:$F,'AccountSummary (New)'!Q$3,Accounts!$W:$W,1)/Q7) -> 0 | R9: =IF(R7=0,0,SUMIFS(Accounts!$M:$M,Accounts!$E:$E,'AccountSummary (New)'!R$1,Accounts!$G:$G,'AccountSummary (New)'!R$2,Accounts!$F:$F,'AccountSummary (New)'!R$3,Accounts!$W:$W,1)/R7) -> 0 | S9: =IF(S7=0,0,SUMIFS(Accounts!$M:$M,Accounts!$E:$E,'AccountSummary (New)'!S$1,Accounts!$G:$G,'AccountSummary (New)'!S$2,Accounts!$F:$F,'AccountSummary (New)'!S$3,Accounts!$W:$W,1)/S7) -> 0 | T9: =IF(T7=0,0,SUMIFS(Accounts!$M:$M,Accounts!$E:$E,'AccountSummary (New)'!T$1,Accounts!$G:$G,'AccountSummary (New)'!T$2,Accounts!$F:$F,'AccountSummary (New)'!T$3,Accounts!$W:$W,1)/T7) -> 0 | U9: =IF(U7=0,0,SUMIFS(Accounts!$M:$M,Accounts!$E:$E,'AccountSummary (New)'!U$1,Accounts!$G:$G,'AccountSummary (New)'!U$2,Accounts!$F:$F,'AccountSummary (New)'!U$3,Accounts!$W:$W,1)/U7) -> 0 | V9: =IF(V7=0,0,SUMIFS(Accounts!$M:$M,Accounts!$E:$E,'AccountSummary (New)'!V$1,Accounts!$G:$G,'AccountSummary (New)'!V$2,Accounts!$F:$F,'AccountSummary (New)'!V$3,Accounts!$W:$W,1)/V7) -> 0 | W9: =IF(W7=0,0,SUMIFS(Accounts!$M:$M,Accounts!$F:$F,'AccountSummary (New)'!W$3,Accounts!$W:$W,1)/W7) -> 0
A10: ARPC First Invoice | B10: =IF(B7=0,0,B11/B7) -> 0 | C10: =IF(C7=0,0,C11/C7) -> 0 | D10: =IF(D7=0,0,D11/D7) -> 0 | E10: =IF(E7=0,0,E11/E7) -> 0 | F10: =IF(F7=0,0,F11/F7) -> 0 | G10: =IF(G7=0,0,G11/G7) -> 0 | H10: =IF(H7=0,0,H11/H7) -> 0 | I10: =IF(I7=0,0,I11/I7) -> 0 | ... W10: =IF(W7=0,0,W11/W7) -> 0
A11: Total SaaS from Trialers | B11: =I11+P11+W11 -> 0 | C11: =SUMIFS(Accounts!$I:$I,Accounts!$E:$E,'AccountSummary (New)'!C$1,Accounts!$G:$G,'AccountSummary (New)'!C$2,Accounts!$F:$F,'AccountSummary (New)'!C$3,Accounts!$W:$W,1) -> 0 | D11: =SUMIFS(Accounts!$I:$I,Accounts!$E:$E,'AccountSummary (New)'!D$1,Accounts!$G:$G,'AccountSummary (New)'!D$2,Accounts!$F:$F,'AccountSummary (New)'!D$3,Accounts!$W:$W,1) -> 0 | E11: =SUMIFS(Accounts!$I:$I,Accounts!$E:$E,'AccountSummary (New)'!E$1,Accounts!$G:$G,'AccountSummary (New)'!E$2,Accounts!$F:$F,'AccountSummary (New)'!E$3,Accounts!$W:$W,1) -> 0 | F11: =SUMIFS(Accounts!$I:$I,Accounts!$E:$E,'AccountSummary (New)'!F$1,Accounts!$G:$G,'AccountSummary (New)'!F$2,Accounts!$F:$F,'AccountSummary (New)'!F$3,Accounts!$W:$W,1) -> 0 | G11: =SUMIFS(Accounts!$I:$I,Accounts!$E:$E,'AccountSummary (New)'!G$1,Accounts!$G:$G,'AccountSummary (New)'!G$2,Accounts!$F:$F,'AccountSummary (New)'!G$3,Accounts!$W:$W,1) -> 0 | H11: =SUMIFS(Accounts!$I:$I,Accounts!$E:$E,'AccountSummary (New)'!H$1,Accounts!$G:$G,'AccountSummary (New)'!H$2,Accounts!$F:$F,'AccountSummary (New)'!H$3,Accounts!$W:$W,1) -> 0 | I11: =SUM(C11:F11) -> 0 | J11: =SUMIFS(Accounts!$I:$I,Accounts!$E:$E,'AccountSummary (New)'!J$1,Accounts!$G:$G,'AccountSummary (New)'!J$2,Accounts!$F:$F,'AccountSummary (New)'!J$3,Accounts!$W:$W,1) -> 0 | K11: =SUMIFS(Accounts!$I:$I,Accounts!$E:$E,'AccountSummary (New)'!K$1,Accounts!$G:$G,'AccountSummary (New)'!K$2,Accounts!$F:$F,'AccountSummary (New)'!K$3,Accounts!$W:$W,1) -> 0 | L11: =SUMIFS(Accounts!$I:$I,Accounts!$E:$E,'AccountSummary (New)'!L$1,Accounts!$G:$G,'AccountSummary (New)'!L$2,Accounts!$F:$F,'AccountSummary (New)'!L$3,Accounts!$W:$W,1) -> 0 | M11: =SUMIFS(Accounts!$I:$I,Accounts!$E:$E,'AccountSummary (New)'!M$1,Accounts!$G:$G,'AccountSummary (New)'!M$2,Accounts!$F:$F,'AccountSummary (New)'!M$3,Accounts!$W:$W,1) -> 0 | N11: =SUMIFS(Accounts!$I:$I,Accounts!$E:$E,'AccountSummary (New)'!N$1,Accounts!$G:$G,'AccountSummary (New)'!N$2,Accounts!$F:$F,'AccountSummary (New)'!N$3,Accounts!$W:$W,1) -> 0 | O11: =SUMIFS(Accounts!$I:$I,Accounts!$E:$E,'AccountSummary (New)'!O$1,Accounts!$G:$G,'AccountSummary (New)'!O$2,Accounts!$F:$F,'AccountSummary (New)'!O$3,Accounts!$W:$W,1) -> 0 | P11: =SUM(J11:M11) -> 0 | Q11: =SUMIFS(Accounts!$I:$I,Accounts!$E:$E,'AccountSummary (New)'!Q$1,Accounts!$G:$G,'AccountSummary (New)'!Q$2,Accounts!$F:$F,'AccountSummary (New)'!Q$3,Accounts!$W:$W,1) -> 0 | R11: =SUMIFS(Accounts!$I:$I,Accounts!$E:$E,'AccountSummary (New)'!R$1,Accounts!$G:$G,'AccountSummary (New)'!R$2,Accounts!$F:$F,'AccountSummary (New)'!R$3,Accounts!$W:$W,1) -> 0 | S11: =SUMIFS(Accounts!$I:$I,Accounts!$E:$E,'AccountSummary (New)'!S$1,Accounts!$G:$G,'AccountSummary (New)'!S$2,Accounts!$F:$F,'AccountSummary (New)'!S$3,Accounts!$W:$W,1) -> 0 | T11: =SUMIFS(Accounts!$I:$I,Accounts!$E:$E,'AccountSummary (New)'!T$1,Accounts!$G:$G,'AccountSummary (New)'!T$2,Accounts!$F:$F,'AccountSummary (New)'!T$3,Accounts!$W:$W,1) -> 0 | U11: =SUMIFS(Accounts!$I:$I,Accounts!$E:$E,'AccountSummary (New)'!U$1,Accounts!$G:$G,'AccountSummary (New)'!U$2,Accounts!$F:$F,'AccountSummary (New)'!U$3,Accounts!$W:$W,1) -> 0 | V11: =SUMIFS(Accounts!$I:$I,Accounts!$E:$E,'AccountSummary (New)'!V$1,Accounts!$G:$G,'AccountSummary (New)'!V$2,Accounts!$F:$F,'AccountSummary (New)'!V$3,Accounts!$W:$W,1) -> 0 | W11: =SUM(Q11:V11) -> 0
A13: Trialers Lost in month they paid
A14: % who cancel | B14: =IF(B7=0,0,B15/B7) -> 0 | C14: =IF(C7=0,0,C15/C7) -> 0 | D14: =IF(D7=0,0,D15/D7) -> 0 | E14: =IF(E7=0,0,E15/E7) -> 0 | F14: =IF(F7=0,0,F15/F7) -> 0 | G14: =IF(G7=0,0,G15/G7) -> 0 | H14: =IF(H7=0,0,H15/H7) -> 0 | I14: =IF(I7=0,0,I15/I7) -> 0 | ... W14: =IF(W7=0,0,W15/W7) -> 0
A15: Paid but cancelled before EOM | B15: =I15+P15+W15 -> 0 | C15: =COUNTIFS(Accounts!$E:$E,'AccountSummary (New)'!C$1,Accounts!$G:$G,'AccountSummary (New)'!C$2,Accounts!$F:$F,'AccountSummary (New)'!C$3,Accounts!$W:$W,1,Accounts!$C:$C,"Lost") -> 0 | D15: =COUNTIFS(Accounts!$E:$E,'AccountSummary (New)'!D$1,Accounts!$G:$G,'AccountSummary (New)'!D$2,Accounts!$F:$F,'AccountSummary (New)'!D$3,Accounts!$W:$W,1,Accounts!$C:$C,"Lost") -> 0 | E15: =COUNTIFS(Accounts!$E:$E,'AccountSummary (New)'!E$1,Accounts!$G:$G,'AccountSummary (New)'!E$2,Accounts!$F:$F,'AccountSummary (New)'!E$3,Accounts!$W:$W,1,Accounts!$C:$C,"Lost") -> 0 | F15: =COUNTIFS(Accounts!$E:$E,'AccountSummary (New)'!F$1,Accounts!$G:$G,'AccountSummary (New)'!F$2,Accounts!$F:$F,'AccountSummary (New)'!F$3,Accounts!$W:$W,1,Accounts!$C:$C,"Lost") -> 0 | G15: =COUNTIFS(Accounts!$E:$E,'AccountSummary (New)'!G$1,Accounts!$G:$G,'AccountSummary (New)'!G$2,Accounts!$F:$F,'AccountSummary (New)'!G$3,Accounts!$W:$W,1,Accounts!$C:$C,"Lost") -> 0 | H15: =COUNTIFS(Accounts!$E:$E,'AccountSummary (New)'!H$1,Accounts!$G:$G,'AccountSummary (New)'!H$2,Accounts!$F:$F,'AccountSummary (New)'!H$3,Accounts!$W:$W,1,Accounts!$C:$C,"Lost") -> 0 | I15: =SUM(C15:H15) -> 0 | J15: =COUNTIFS(Accounts!$E:$E,'AccountSummary (New)'!J$1,Accounts!$G:$G,'AccountSummary (New)'!J$2,Accounts!$F:$F,'AccountSummary (New)'!J$3,Accounts!$W:$W,1,Accounts!$C:$C,"Lost") -> 0 | K15: =COUNTIFS(Accounts!$E:$E,'AccountSummary (New)'!K$1,Accounts!$G:$G,'AccountSummary (New)'!K$2,Accounts!$F:$F,'AccountSummary (New)'!K$3,Accounts!$W:$W,1,Accounts!$C:$C,"Lost") -> 0 | L15: =COUNTIFS(Accounts!$E:$E,'AccountSummary (New)'!L$1,Accounts!$G:$G,'AccountSummary (New)'!L$2,Accounts!$F:$F,'AccountSummary (New)'!L$3,Accounts!$W:$W,1,Accounts!$C:$C,"Lost") -> 0 | M15: =COUNTIFS(Accounts!$E:$E,'AccountSummary (New)'!M$1,Accounts!$G:$G,'AccountSummary (New)'!M$2,Accounts!$F:$F,'AccountSummary (New)'!M$3,Accounts!$W:$W,1,Accounts!$C:$C,"Lost") -> 0 | N15: =COUNTIFS(Accounts!$E:$E,'AccountSummary (New)'!N$1,Accounts!$G:$G,'AccountSummary (New)'!N$2,Accounts!$F:$F,'AccountSummary (New)'!N$3,Accounts!$W:$W,1,Accounts!$C:$C,"Lost") -> 0 | O15: =COUNTIFS(Accounts!$E:$E,'AccountSummary (New)'!O$1,Accounts!$G:$G,'AccountSummary (New)'!O$2,Accounts!$F:$F,'AccountSummary (New)'!O$3,Accounts!$W:$W,1,Accounts!$C:$C,"Lost") -> 0 | P15: =SUM(J15:O15) -> 0 | Q15: =COUNTIFS(Accounts!$E:$E,'AccountSummary (New)'!Q$1,Accounts!$G:$G,'AccountSummary (New)'!Q$2,Accounts!$F:$F,'AccountSummary (New)'!Q$3,Accounts!$W:$W,1,Accounts!$C:$C,"Lost") -> 0 | R15: =COUNTIFS(Accounts!$E:$E,'AccountSummary (New)'!R$1,Accounts!$G:$G,'AccountSummary (New)'!R$2,Accounts!$F:$F,'AccountSummary (New)'!R$3,Accounts!$W:$W,1,Accounts!$C:$C,"Lost") -> 0 | S15: =COUNTIFS(Accounts!$E:$E,'AccountSummary (New)'!S$1,Accounts!$G:$G,'AccountSummary (New)'!S$2,Accounts!$F:$F,'AccountSummary (New)'!S$3,Accounts!$W:$W,1,Accounts!$C:$C,"Lost") -> 0 | T15: =COUNTIFS(Accounts!$E:$E,'AccountSummary (New)'!T$1,Accounts!$G:$G,'AccountSummary (New)'!T$2,Accounts!$F:$F,'AccountSummary (New)'!T$3,Accounts!$W:$W,1,Accounts!$C:$C,"Lost") -> 0 | U15: =COUNTIFS(Accounts!$E:$E,'AccountSummary (New)'!U$1,Accounts!$G:$G,'AccountSummary (New)'!U$2,Accounts!$F:$F,'AccountSummary (New)'!U$3,Accounts!$W:$W,1,Accounts!$C:$C,"Lost") -> 0 | V15: =COUNTIFS(Accounts!$E:$E,'AccountSummary (New)'!V$1,Accounts!$G:$G,'AccountSummary (New)'!V$2,Accounts!$F:$F,'AccountSummary (New)'!V$3,Accounts!$W:$W,1,Accounts!$C:$C,"Lost") -> 0 | W15: =SUM(Q15:V15) -> 0
A16: Net: Paid, retained EOM | B16: =I16+P16+W16 -> 0 | C16: =C7-C15 -> 0 | D16: =D7-D15 -> 0 | E16: =E7-E15 -> 0 | F16: =F7-F15 -> 0 | G16: =G7-G15 -> 0 | H16: =H7-H15 -> 0 | I16: =SUM(C16:H16) -> 0 | J16: =J7-J15 -> 0 | K16: =K7-K15 -> 0 | L16: =L7-L15 -> 0 | M16: =M7-M15 -> 0 | N16: =N7-N15 -> 0 | O16: =O7-O15 -> 0 | P16: =SUM(J16:O16) -> 0 | Q16: =Q7-Q15 -> 0 | R16: =R7-R15 -> 0 | S16: =S7-S15 -> 0 | T16: =T7-T15 -> 0 | U16: =U7-U15 -> 0 | V16: =V7-V15 -> 0 | W16: =SUM(Q16:V16) -> 0
A18: *Paying Customers*
A19: Starting Count BOM | B19: =I19+P19+W19 -> 1 | C19: =COUNTIFS(Accounts!$E:$E,'AccountSummary (New)'!C$1,Accounts!$G:$G,'AccountSummary (New)'!C$2,Accounts!$F:$F,'AccountSummary (New)'!C$3,Accounts!$B:$B,"Customer") -> 0 | D19: =COUNTIFS(Accounts!$E:$E,'AccountSummary (New)'!D$1,Accounts!$G:$G,'AccountSummary (New)'!D$2,Accounts!$F:$F,'AccountSummary (New)'!D$3,Accounts!$B:$B,"Customer") -> 0 | E19: =COUNTIFS(Accounts!$E:$E,'AccountSummary (New)'!E$1,Accounts!$G:$G,'AccountSummary (New)'!E$2,Accounts!$F:$F,'AccountSummary (New)'!E$3,Accounts!$B:$B,"Customer") -> 0 | F19: =COUNTIFS(Accounts!$E:$E,'AccountSummary (New)'!F$1,Accounts!$G:$G,'AccountSummary (New)'!F$2,Accounts!$F:$F,'AccountSummary (New)'!F$3,Accounts!$B:$B,"Customer") -> 0 | G19: =COUNTIFS(Accounts!$E:$E,'AccountSummary (New)'!G$1,Accounts!$G:$G,'AccountSummary (New)'!G$2,Accounts!$F:$F,'AccountSummary (New)'!G$3,Accounts!$B:$B,"Customer") -> 0 | H19: =COUNTIFS(Accounts!$E:$E,'AccountSummary (New)'!H$1,Accounts!$G:$G,'AccountSummary (New)'!H$2,Accounts!$F:$F,'AccountSummary (New)'!H$3,Accounts!$B:$B,"Customer") -> 0 | I19: =SUM(C19:H19) -> 0 | J19: =COUNTIFS(Accounts!$E:$E,'AccountSummary (New)'!J$1,Accounts!$G:$G,'AccountSummary (New)'!J$2,Accounts!$F:$F,'AccountSummary (New)'!J$3,Accounts!$B:$B,"Customer") -> 0 | K19: =COUNTIFS(Accounts!$E:$E,'AccountSummary (New)'!K$1,Accounts!$G:$G,'AccountSummary (New)'!K$2,Accounts!$F:$F,'AccountSummary (New)'!K$3,Accounts!$B:$B,"Customer") -> 0 | L19: =COUNTIFS(Accounts!$E:$E,'AccountSummary (New)'!L$1,Accounts!$G:$G,'AccountSummary (New)'!L$2,Accounts!$F:$F,'AccountSummary (New)'!L$3,Accounts!$B:$B,"Customer") -> 0 | M19: =COUNTIFS(Accounts!$E:$E,'AccountSummary (New)'!M$1,Accounts!$G:$G,'AccountSummary (New)'!M$2,Accounts!$F:$F,'AccountSummary (New)'!M$3,Accounts!$B:$B,"Customer") -> 0 | N19: =COUNTIFS(Accounts!$E:$E,'AccountSummary (New)'!N$1,Accounts!$G:$G,'AccountSummary (New)'!N$2,Accounts!$F:$F,'AccountSummary (New)'!N$3,Accounts!$B:$B,"Customer") -> 0 | O19: =COUNTIFS(Accounts!$E:$E,'AccountSummary (New)'!O$1,Accounts!$G:$G,'AccountSummary (New)'!O$2,Accounts!$F:$F,'AccountSummary (New)'!O$3,Accounts!$B:$B,"Customer") -> 0 | P19: =SUM(J19:O19) -> 0 | Q19: =COUNTIFS(Accounts!$E:$E,'AccountSummary (New)'!Q$1,Accounts!$G:$G,'AccountSummary (New)'!Q$2,Accounts!$F:$F,'AccountSummary (New)'!Q$3,Accounts!$B:$B,"Customer") -> 0 | R19: =COUNTIFS(Accounts!$E:$E,'AccountSummary (New)'!R$1,Accounts!$G:$G,'AccountSummary (New)'!R$2,Accounts!$F:$F,'AccountSummary (New)'!R$3,Accounts!$B:$B,"Customer") -> 1 | S19: =COUNTIFS(Accounts!$E:$E,'AccountSummary (New)'!S$1,Accounts!$G:$G,'AccountSummary (New)'!S$2,Accounts!$F:$F,'AccountSummary (New)'!S$3,Accounts!$B:$B,"Customer") -> 0 | T19: =COUNTIFS(Accounts!$E:$E,'AccountSummary (New)'!T$1,Accounts!$G:$G,'AccountSummary (New)'!T$2,Accounts!$F:$F,'AccountSummary (New)'!T$3,Accounts!$B:$B,"Customer") -> 0 | U19: =COUNTIFS(Accounts!$E:$E,'AccountSummary (New)'!U$1,Accounts!$G:$G,'AccountSummary (New)'!U$2,Accounts!$F:$F,'AccountSummary (New)'!U$3,Accounts!$B:$B,"Customer") -> 0 | V19: =COUNTIFS(Accounts!$E:$E,'AccountSummary (New)'!V$1,Accounts!$G:$G,'AccountSummary (New)'!V$2,Accounts!$F:$F,'AccountSummary (New)'!V$3,Accounts!$B:$B,"Customer") -> 0 | W19: =SUM(Q19:V19) -> 1
A21: 0-30 day cohort as of BOM
A22: Total % of Paying Customers | B22: =IF(B$19=0,0,(B24+B25)/B$19) -> 0 | C22: =IF(C$19=0,0,(C24+C25)/C$19) -> 0 | D22: =IF(D$19=0,0,(D24+D25)/D$19) -> 0 | E22: =IF(E$19=0,0,(E24+E25)/E$19) -> 0 | F22: =IF(F$19=0,0,(F24+F25)/F$19) -> 0 | G22: =IF(G$19=0,0,(G24+G25)/G$19) -> 0 | H22: =IF(H$19=0,0,(H24+H25)/H$19) -> 0 | I22: =IF(I$19=0,0,(I24+I25)/I$19) -> 0 | ... W22: =IF(W$19=0,0,(W24+W25)/W$19) -> 0
A23: Loss % | B23: =IF((B24+B25)=0,0,B24/(B24+B25)) -> 0 | C23: =IF((C24+C25)=0,0,C24/(C24+C25)) -> 0 | D23: =IF((D24+D25)=0,0,D24/(D24+D25)) -> 0 | E23: =IF((E24+E25)=0,0,E24/(E24+E25)) -> 0 | F23: =IF((F24+F25)=0,0,F24/(F24+F25)) -> 0 | G23: =IF((G24+G25)=0,0,G24/(G24+G25)) -> 0 | H23: =IF((H24+H25)=0,0,H24/(H24+H25)) -> 0 | I23: =IF((I24+I25)=0,0,I24/(I24+I25)) -> 0 | ... W23: =IF((W24+W25)=0,0,W24/(W24+W25)) -> 0
A24: Lost Count | B24: =I24+P24+W24 -> 0 | C24: =COUNTIFS(Accounts!$E:$E,'AccountSummary (New)'!C$1,Accounts!$G:$G,'AccountSummary (New)'!C$2,Accounts!$F:$F,'AccountSummary (New)'!C$3,Accounts!$B:$B,"Customer",Accounts!$C:$C,"Lost",Accounts!$H:$H,"<="&30) -> 0 | D24: =COUNTIFS(Accounts!$E:$E,'AccountSummary (New)'!D$1,Accounts!$G:$G,'AccountSummary (New)'!D$2,Accounts!$F:$F,'AccountSummary (New)'!D$3,Accounts!$B:$B,"Customer",Accounts!$C:$C,"Lost",Accounts!$H:$H,"<="&30) -> 0 | E24: =COUNTIFS(Accounts!$E:$E,'AccountSummary (New)'!E$1,Accounts!$G:$G,'AccountSummary (New)'!E$2,Accounts!$F:$F,'AccountSummary (New)'!E$3,Accounts!$B:$B,"Customer",Accounts!$C:$C,"Lost",Accounts!$H:$H,"<="&30) -> 0 | F24: =COUNTIFS(Accounts!$E:$E,'AccountSummary (New)'!F$1,Accounts!$G:$G,'AccountSummary (New)'!F$2,Accounts!$F:$F,'AccountSummary (New)'!F$3,Accounts!$B:$B,"Customer",Accounts!$C:$C,"Lost",Accounts!$H:$H,"<="&30) -> 0 | G24: =COUNTIFS(Accounts!$E:$E,'AccountSummary (New)'!G$1,Accounts!$G:$G,'AccountSummary (New)'!G$2,Accounts!$F:$F,'AccountSummary (New)'!G$3,Accounts!$B:$B,"Customer",Accounts!$C:$C,"Lost",Accounts!$H:$H,"<="&30) -> 0 | H24: =COUNTIFS(Accounts!$E:$E,'AccountSummary (New)'!H$1,Accounts!$G:$G,'AccountSummary (New)'!H$2,Accounts!$F:$F,'AccountSummary (New)'!H$3,Accounts!$B:$B,"Customer",Accounts!$C:$C,"Lost",Accounts!$H:$H,"<="&30) -> 0 | I24: =SUM(C24:H24) -> 0 | J24: =COUNTIFS(Accounts!$E:$E,'AccountSummary (New)'!J$1,Accounts!$G:$G,'AccountSummary (New)'!J$2,Accounts!$F:$F,'AccountSummary (New)'!J$3,Accounts!$B:$B,"Customer",Accounts!$C:$C,"Lost",Accounts!$H:$H,"<="&30) -> 0 | K24: =COUNTIFS(Accounts!$E:$E,'AccountSummary (New)'!K$1,Accounts!$G:$G,'AccountSummary (New)'!K$2,Accounts!$F:$F,'AccountSummary (New)'!K$3,Accounts!$B:$B,"Customer",Accounts!$C:$C,"Lost",Accounts!$H:$H,"<="&30) -> 0 | L24: =COUNTIFS(Accounts!$E:$E,'AccountSummary (New)'!L$1,Accounts!$G:$G,'AccountSummary (New)'!L$2,Accounts!$F:$F,'AccountSummary (New)'!L$3,Accounts!$B:$B,"Customer",Accounts!$C:$C,"Lost",Accounts!$H:$H,"<="&30) -> 0 | M24: =COUNTIFS(Accounts!$E:$E,'AccountSummary (New)'!M$1,Accounts!$G:$G,'AccountSummary (New)'!M$2,Accounts!$F:$F,'AccountSummary (New)'!M$3,Accounts!$B:$B,"Customer",Accounts!$C:$C,"Lost",Accounts!$H:$H,"<="&30) -> 0 | N24: =COUNTIFS(Accounts!$E:$E,'AccountSummary (New)'!N$1,Accounts!$G:$G,'AccountSummary (New)'!N$2,Accounts!$F:$F,'AccountSummary (New)'!N$3,Accounts!$B:$B,"Customer",Accounts!$C:$C,"Lost",Accounts!$H:$H,"<="&30) -> 0 | O24: =COUNTIFS(Accounts!$E:$E,'AccountSummary (New)'!O$1,Accounts!$G:$G,'AccountSummary (New)'!O$2,Accounts!$F:$F,'AccountSummary (New)'!O$3,Accounts!$B:$B,"Customer",Accounts!$C:$C,"Lost",Accounts!$H:$H,"<="&30) -> 0 | P24: =SUM(J24:O24) -> 0 | Q24: =COUNTIFS(Accounts!$E:$E,'AccountSummary (New)'!Q$1,Accounts!$G:$G,'AccountSummary (New)'!Q$2,Accounts!$F:$F,'AccountSummary (New)'!Q$3,Accounts!$B:$B,"Customer",Accounts!$C:$C,"Lost",Accounts!$H:$H,"<="&30) -> 0 | R24: =COUNTIFS(Accounts!$E:$E,'AccountSummary (New)'!R$1,Accounts!$G:$G,'AccountSummary (New)'!R$2,Accounts!$F:$F,'AccountSummary (New)'!R$3,Accounts!$B:$B,"Customer",Accounts!$C:$C,"Lost",Accounts!$H:$H,"<="&30) -> 0 | S24: =COUNTIFS(Accounts!$E:$E,'AccountSummary (New)'!S$1,Accounts!$G:$G,'AccountSummary (New)'!S$2,Accounts!$F:$F,'AccountSummary (New)'!S$3,Accounts!$B:$B,"Customer",Accounts!$C:$C,"Lost",Accounts!$H:$H,"<="&30) -> 0 | T24: =COUNTIFS(Accounts!$E:$E,'AccountSummary (New)'!T$1,Accounts!$G:$G,'AccountSummary (New)'!T$2,Accounts!$F:$F,'AccountSummary (New)'!T$3,Accounts!$B:$B,"Customer",Accounts!$C:$C,"Lost",Accounts!$H:$H,"<="&30) -> 0 | U24: =COUNTIFS(Accounts!$E:$E,'AccountSummary (New)'!U$1,Accounts!$G:$G,'AccountSummary (New)'!U$2,Accounts!$F:$F,'AccountSummary (New)'!U$3,Accounts!$B:$B,"Customer",Accounts!$C:$C,"Lost",Accounts!$H:$H,"<="&30) -> 0 | V24: =COUNTIFS(Accounts!$E:$E,'AccountSummary (New)'!V$1,Accounts!$G:$G,'AccountSummary (New)'!V$2,Accounts!$F:$F,'AccountSummary (New)'!V$3,Accounts!$B:$B,"Customer",Accounts!$C:$C,"Lost",Accounts!$H:$H,"<="&30) -> 0 | W24: =SUM(Q24:V24) -> 0
A25: Retained Count | B25: =I25+P25+W25 -> 0 | C25: =COUNTIFS(Accounts!$E:$E,'AccountSummary (New)'!C$1,Accounts!$G:$G,'AccountSummary (New)'!C$2,Accounts!$F:$F,'AccountSummary (New)'!C$3,Accounts!$B:$B,"Customer",Accounts!$C:$C,"Customer",Accounts!$H:$H,"<="&30) -> 0 | D25: =COUNTIFS(Accounts!$E:$E,'AccountSummary (New)'!D$1,Accounts!$G:$G,'AccountSummary (New)'!D$2,Accounts!$F:$F,'AccountSummary (New)'!D$3,Accounts!$B:$B,"Customer",Accounts!$C:$C,"Customer",Accounts!$H:$H,"<="&30) -> 0 | E25: =COUNTIFS(Accounts!$E:$E,'AccountSummary (New)'!E$1,Accounts!$G:$G,'AccountSummary (New)'!E$2,Accounts!$F:$F,'AccountSummary (New)'!E$3,Accounts!$B:$B,"Customer",Accounts!$C:$C,"Customer",Accounts!$H:$H,"<="&30) -> 0 | F25: =COUNTIFS(Accounts!$E:$E,'AccountSummary (New)'!F$1,Accounts!$G:$G,'AccountSummary (New)'!F$2,Accounts!$F:$F,'AccountSummary (New)'!F$3,Accounts!$B:$B,"Customer",Accounts!$C:$C,"Customer",Accounts!$H:$H,"<="&30) -> 0 | G25: =COUNTIFS(Accounts!$E:$E,'AccountSummary (New)'!G$1,Accounts!$G:$G,'AccountSummary (New)'!G$2,Accounts!$F:$F,'AccountSummary (New)'!G$3,Accounts!$B:$B,"Customer",Accounts!$C:$C,"Customer",Accounts!$H:$H,"<="&30) -> 0 | H25: =COUNTIFS(Accounts!$E:$E,'AccountSummary (New)'!H$1,Accounts!$G:$G,'AccountSummary (New)'!H$2,Accounts!$F:$F,'AccountSummary (New)'!H$3,Accounts!$B:$B,"Customer",Accounts!$C:$C,"Customer",Accounts!$H:$H,"<="&30) -> 0 | I25: =SUM(C25:H25) -> 0 | J25: =COUNTIFS(Accounts!$E:$E,'AccountSummary (New)'!J$1,Accounts!$G:$G,'AccountSummary (New)'!J$2,Accounts!$F:$F,'AccountSummary (New)'!J$3,Accounts!$B:$B,"Customer",Accounts!$C:$C,"Customer",Accounts!$H:$H,"<="&30) -> 0 | K25: =COUNTIFS(Accounts!$E:$E,'AccountSummary (New)'!K$1,Accounts!$G:$G,'AccountSummary (New)'!K$2,Accounts!$F:$F,'AccountSummary (New)'!K$3,Accounts!$B:$B,"Customer",Accounts!$C:$C,"Customer",Accounts!$H:$H,"<="&30) -> 0 | L25: =COUNTIFS(Accounts!$E:$E,'AccountSummary (New)'!L$1,Accounts!$G:$G,'AccountSummary (New)'!L$2,Accounts!$F:$F,'AccountSummary (New)'!L$3,Accounts!$B:$B,"Customer",Accounts!$C:$C,"Customer",Accounts!$H:$H,"<="&30) -> 0 | M25: =COUNTIFS(Accounts!$E:$E,'AccountSummary (New)'!M$1,Accounts!$G:$G,'AccountSummary (New)'!M$2,Accounts!$F:$F,'AccountSummary (New)'!M$3,Accounts!$B:$B,"Customer",Accounts!$C:$C,"Customer",Accounts!$H:$H,"<="&30) -> 0 | N25: =COUNTIFS(Accounts!$E:$E,'AccountSummary (New)'!N$1,Accounts!$G:$G,'AccountSummary (New)'!N$2,Accounts!$F:$F,'AccountSummary (New)'!N$3,Accounts!$B:$B,"Customer",Accounts!$C:$C,"Customer",Accounts!$H:$H,"<="&30) -> 0 | O25: =COUNTIFS(Accounts!$E:$E,'AccountSummary (New)'!O$1,Accounts!$G:$G,'AccountSummary (New)'!O$2,Accounts!$F:$F,'AccountSummary (New)'!O$3,Accounts!$B:$B,"Customer",Accounts!$C:$C,"Customer",Accounts!$H:$H,"<="&30) -> 0 | P25: =SUM(J25:O25) -> 0 | Q25: =COUNTIFS(Accounts!$E:$E,'AccountSummary (New)'!Q$1,Accounts!$G:$G,'AccountSummary (New)'!Q$2,Accounts!$F:$F,'AccountSummary (New)'!Q$3,Accounts!$B:$B,"Customer",Accounts!$C:$C,"Customer",Accounts!$H:$H,"<="&30) -> 0 | R25: =COUNTIFS(Accounts!$E:$E,'AccountSummary (New)'!R$1,Accounts!$G:$G,'AccountSummary (New)'!R$2,Accounts!$F:$F,'AccountSummary (New)'!R$3,Accounts!$B:$B,"Customer",Accounts!$C:$C,"Customer",Accounts!$H:$H,"<="&30) -> 0 | S25: =COUNTIFS(Accounts!$E:$E,'AccountSummary (New)'!S$1,Accounts!$G:$G,'AccountSummary (New)'!S$2,Accounts!$F:$F,'AccountSummary (New)'!S$3,Accounts!$B:$B,"Customer",Accounts!$C:$C,"Customer",Accounts!$H:$H,"<="&30) -> 0 | T25: =COUNTIFS(Accounts!$E:$E,'AccountSummary (New)'!T$1,Accounts!$G:$G,'AccountSummary (New)'!T$2,Accounts!$F:$F,'AccountSummary (New)'!T$3,Accounts!$B:$B,"Customer",Accounts!$C:$C,"Customer",Accounts!$H:$H,"<="&30) -> 0 | U25: =COUNTIFS(Accounts!$E:$E,'AccountSummary (New)'!U$1,Accounts!$G:$G,'AccountSummary (New)'!U$2,Accounts!$F:$F,'AccountSummary (New)'!U$3,Accounts!$B:$B,"Customer",Accounts!$C:$C,"Customer",Accounts!$H:$H,"<="&30) -> 0 | V25: =COUNTIFS(Accounts!$E:$E,'AccountSummary (New)'!V$1,Accounts!$G:$G,'AccountSummary (New)'!V$2,Accounts!$F:$F,'AccountSummary (New)'!V$3,Accounts!$B:$B,"Customer",Accounts!$C:$C,"Customer",Accounts!$H:$H,"<="&30) -> 0 | W25: =SUM(Q25:V25) -> 0
A26: Packs per Account | B26: =IF(B25=0,0,SUMIFS(Accounts!$L:$L,Accounts!$W:$W,0,Accounts!$C:$C,"Customer",Accounts!$H:$H,"<="&30)/B25) -> 0 | C26: =IF(C25=0,0,SUMIFS(Accounts!$L:$L,Accounts!$E:$E,'AccountSummary (New)'!C$1,Accounts!$G:$G,'AccountSummary (New)'!C$2,Accounts!$F:$F,'AccountSummary (New)'!C$3,Accounts!$W:$W,0,Accounts!$C:$C,"Customer",Accounts!$H:$H,"<="&30)/C25) -> 0 | D26: =IF(D25=0,0,SUMIFS(Accounts!$L:$L,Accounts!$E:$E,'AccountSummary (New)'!D$1,Accounts!$G:$G,'AccountSummary (New)'!D$2,Accounts!$F:$F,'AccountSummary (New)'!D$3,Accounts!$W:$W,0,Accounts!$C:$C,"Customer",Accounts!$H:$H,"<="&30)/D25) -> 0 | E26: =IF(E25=0,0,SUMIFS(Accounts!$L:$L,Accounts!$E:$E,'AccountSummary (New)'!E$1,Accounts!$G:$G,'AccountSummary (New)'!E$2,Accounts!$F:$F,'AccountSummary (New)'!E$3,Accounts!$W:$W,0,Accounts!$C:$C,"Customer",Accounts!$H:$H,"<="&30)/E25) -> 0 | F26: =IF(F25=0,0,SUMIFS(Accounts!$L:$L,Accounts!$E:$E,'AccountSummary (New)'!F$1,Accounts!$G:$G,'AccountSummary (New)'!F$2,Accounts!$F:$F,'AccountSummary (New)'!F$3,Accounts!$W:$W,0,Accounts!$C:$C,"Customer",Accounts!$H:$H,"<="&30)/F25) -> 0 | G26: =IF(G25=0,0,SUMIFS(Accounts!$L:$L,Accounts!$E:$E,'AccountSummary (New)'!G$1,Accounts!$G:$G,'AccountSummary (New)'!G$2,Accounts!$F:$F,'AccountSummary (New)'!G$3,Accounts!$W:$W,0,Accounts!$C:$C,"Customer",Accounts!$H:$H,"<="&30)/G25) -> 0 | H26: =IF(H25=0,0,SUMIFS(Accounts!$L:$L,Accounts!$E:$E,'AccountSummary (New)'!H$1,Accounts!$G:$G,'AccountSummary (New)'!H$2,Accounts!$F:$F,'AccountSummary (New)'!H$3,Accounts!$W:$W,0,Accounts!$C:$C,"Customer",Accounts!$H:$H,"<="&30)/H25) -> 0 | I26: =IF(I25=0,0,SUMIFS(Accounts!$L:$L,Accounts!$F:$F,'AccountSummary (New)'!I$3,Accounts!$W:$W,0,Accounts!$C:$C,"Customer",Accounts!$H:$H,"<="&30)/I25) -> 0 | J26: =IF(J25=0,0,SUMIFS(Accounts!$L:$L,Accounts!$E:$E,'AccountSummary (New)'!J$1,Accounts!$G:$G,'AccountSummary (New)'!J$2,Accounts!$F:$F,'AccountSummary (New)'!J$3,Accounts!$W:$W,0,Accounts!$C:$C,"Customer",Accounts!$H:$H,"<="&30)/J25) -> 0 | K26: =IF(K25=0,0,SUMIFS(Accounts!$L:$L,Accounts!$E:$E,'AccountSummary (New)'!K$1,Accounts!$G:$G,'AccountSummary (New)'!K$2,Accounts!$F:$F,'AccountSummary (New)'!K$3,Accounts!$W:$W,0,Accounts!$C:$C,"Customer",Accounts!$H:$H,"<="&30)/K25) -> 0 | L26: =IF(L25=0,0,SUMIFS(Accounts!$L:$L,Accounts!$E:$E,'AccountSummary (New)'!L$1,Accounts!$G:$G,'AccountSummary (New)'!L$2,Accounts!$F:$F,'AccountSummary (New)'!L$3,Accounts!$W:$W,0,Accounts!$C:$C,"Customer",Accounts!$H:$H,"<="&30)/L25) -> 0 | M26: =IF(M25=0,0,SUMIFS(Accounts!$L:$L,Accounts!$E:$E,'AccountSummary (New)'!M$1,Accounts!$G:$G,'AccountSummary (New)'!M$2,Accounts!$F:$F,'AccountSummary (New)'!M$3,Accounts!$W:$W,0,Accounts!$C:$C,"Customer",Accounts!$H:$H,"<="&30)/M25) -> 0 | N26: =IF(N25=0,0,SUMIFS(Accounts!$L:$L,Accounts!$E:$E,'AccountSummary (New)'!N$1,Accounts!$G:$G,'AccountSummary (New)'!N$2,Accounts!$F:$F,'AccountSummary (New)'!N$3,Accounts!$W:$W,0,Accounts!$C:$C,"Customer",Accounts!$H:$H,"<="&30)/N25) -> 0 | O26: =IF(O25=0,0,SUMIFS(Accounts!$L:$L,Accounts!$E:$E,'AccountSummary (New)'!O$1,Accounts!$G:$G,'AccountSummary (New)'!O$2,Accounts!$F:$F,'AccountSummary (New)'!O$3,Accounts!$W:$W,0,Accounts!$C:$C,"Customer",Accounts!$H:$H,"<="&30)/O25) -> 0 | P26: =IF(P25=0,0,SUMIFS(Accounts!$L:$L,Accounts!$F:$F,'AccountSummary (New)'!P$3,Accounts!$W:$W,0,Accounts!$C:$C,"Customer",Accounts!$H:$H,"<="&30)/P25) -> 0 | Q26: =IF(Q25=0,0,SUMIFS(Accounts!$L:$L,Accounts!$E:$E,'AccountSummary (New)'!Q$1,Accounts!$G:$G,'AccountSummary (New)'!Q$2,Accounts!$F:$F,'AccountSummary (New)'!Q$3,Accounts!$W:$W,0,Accounts!$C:$C,"Customer",Accounts!$H:$H,"<="&30)/Q25) -> 0 | R26: =IF(R25=0,0,SUMIFS(Accounts!$L:$L,Accounts!$E:$E,'AccountSummary (New)'!R$1,Accounts!$G:$G,'AccountSummary (New)'!R$2,Accounts!$F:$F,'AccountSummary (New)'!R$3,Accounts!$W:$W,0,Accounts!$C:$C,"Customer",Accounts!$H:$H,"<="&30)/R25) -> 0 | S26: =IF(S25=0,0,SUMIFS(Accounts!$L:$L,Accounts!$E:$E,'AccountSummary (New)'!S$1,Accounts!$G:$G,'AccountSummary (New)'!S$2,Accounts!$F:$F,'AccountSummary (New)'!S$3,Accounts!$W:$W,0,Accounts!$C:$C,"Customer",Accounts!$H:$H,"<="&30)/S25) -> 0 | T26: =IF(T25=0,0,SUMIFS(Accounts!$L:$L,Accounts!$E:$E,'AccountSummary (New)'!T$1,Accounts!$G:$G,'AccountSummary (New)'!T$2,Accounts!$F:$F,'AccountSummary (New)'!T$3,Accounts!$W:$W,0,Accounts!$C:$C,"Customer",Accounts!$H:$H,"<="&30)/T25) -> 0 | U26: =IF(U25=0,0,SUMIFS(Accounts!$L:$L,Accounts!$E:$E,'AccountSummary (New)'!U$1,Accounts!$G:$G,'AccountSummary (New)'!U$2,Accounts!$F:$F,'AccountSummary (New)'!U$3,Accounts!$W:$W,0,Accounts!$C:$C,"Customer",Accounts!$H:$H,"<="&30)/U25) -> 0 | V26: =IF(V25=0,0,SUMIFS(Accounts!$L:$L,Accounts!$E:$E,'AccountSummary (New)'!V$1,Accounts!$G:$G,'AccountSummary (New)'!V$2,Accounts!$F:$F,'AccountSummary (New)'!V$3,Accounts!$W:$W,0,Accounts!$C:$C,"Customer",Accounts!$H:$H,"<="&30)/V25) -> 0 | W26: =IF(W25=0,0,SUMIFS(Accounts!$L:$L,Accounts!$F:$F,'AccountSummary (New)'!W$3,Accounts!$W:$W,0,Accounts!$C:$C,"Customer",Accounts!$H:$H,"<="&30)/W25) -> 0
A27: Users per Account | B27: =IF(B25=0,0,SUMIFS(Accounts!$M:$M,Accounts!$W:$W,0,Accounts!$C:$C,"Customer",Accounts!$H:$H,"<="&30)/B25) -> 0 | C27: =IF(C25=0,0,SUMIFS(Accounts!$M:$M,Accounts!$E:$E,'AccountSummary (New)'!C$1,Accounts!$G:$G,'AccountSummary (New)'!C$2,Accounts!$F:$F,'AccountSummary (New)'!C$3,Accounts!$W:$W,0,Accounts!$C:$C,"Customer",Accounts!$H:$H,"<="&30)/C25) -> 0 | D27: =IF(D25=0,0,SUMIFS(Accounts!$M:$M,Accounts!$E:$E,'AccountSummary (New)'!D$1,Accounts!$G:$G,'AccountSummary (New)'!D$2,Accounts!$F:$F,'AccountSummary (New)'!D$3,Accounts!$W:$W,0,Accounts!$C:$C,"Customer",Accounts!$H:$H,"<="&30)/D25) -> 0 | E27: =IF(E25=0,0,SUMIFS(Accounts!$M:$M,Accounts!$E:$E,'AccountSummary (New)'!E$1,Accounts!$G:$G,'AccountSummary (New)'!E$2,Accounts!$F:$F,'AccountSummary (New)'!E$3,Accounts!$W:$W,0,Accounts!$C:$C,"Customer",Accounts!$H:$H,"<="&30)/E25) -> 0 | F27: =IF(F25=0,0,SUMIFS(Accounts!$M:$M,Accounts!$E:$E,'AccountSummary (New)'!F$1,Accounts!$G:$G,'AccountSummary (New)'!F$2,Accounts!$F:$F,'AccountSummary (New)'!F$3,Accounts!$W:$W,0,Accounts!$C:$C,"Customer",Accounts!$H:$H,"<="&30)/F25) -> 0 | G27: =IF(G25=0,0,SUMIFS(Accounts!$M:$M,Accounts!$E:$E,'AccountSummary (New)'!G$1,Accounts!$G:$G,'AccountSummary (New)'!G$2,Accounts!$F:$F,'AccountSummary (New)'!G$3,Accounts!$W:$W,0,Accounts!$C:$C,"Customer",Accounts!$H:$H,"<="&30)/G25) -> 0 | H27: =IF(H25=0,0,SUMIFS(Accounts!$M:$M,Accounts!$E:$E,'AccountSummary (New)'!H$1,Accounts!$G:$G,'AccountSummary (New)'!H$2,Accounts!$F:$F,'AccountSummary (New)'!H$3,Accounts!$W:$W,0,Accounts!$C:$C,"Customer",Accounts!$H:$H,"<="&30)/H25) -> 0 | I27: =IF(I25=0,0,SUMIFS(Accounts!$M:$M,Accounts!$F:$F,'AccountSummary (New)'!I$3,Accounts!$W:$W,0,Accounts!$C:$C,"Customer",Accounts!$H:$H,"<="&30)/I25) -> 0 | J27: =IF(J25=0,0,SUMIFS(Accounts!$M:$M,Accounts!$E:$E,'AccountSummary (New)'!J$1,Accounts!$G:$G,'AccountSummary (New)'!J$2,Accounts!$F:$F,'AccountSummary (New)'!J$3,Accounts!$W:$W,0,Accounts!$C:$C,"Customer",Accounts!$H:$H,"<="&30)/J25) -> 0 | K27: =IF(K25=0,0,SUMIFS(Accounts!$M:$M,Accounts!$E:$E,'AccountSummary (New)'!K$1,Accounts!$G:$G,'AccountSummary (New)'!K$2,Accounts!$F:$F,'AccountSummary (New)'!K$3,Accounts!$W:$W,0,Accounts!$C:$C,"Customer",Accounts!$H:$H,"<="&30)/K25) -> 0 | L27: =IF(L25=0,0,SUMIFS(Accounts!$M:$M,Accounts!$E:$E,'AccountSummary (New)'!L$1,Accounts!$G:$G,'AccountSummary (New)'!L$2,Accounts!$F:$F,'AccountSummary (New)'!L$3,Accounts!$W:$W,0,Accounts!$C:$C,"Customer",Accounts!$H:$H,"<="&30)/L25) -> 0 | M27: =IF(M25=0,0,SUMIFS(Accounts!$M:$M,Accounts!$E:$E,'AccountSummary (New)'!M$1,Accounts!$G:$G,'AccountSummary (New)'!M$2,Accounts!$F:$F,'AccountSummary (New)'!M$3,Accounts!$W:$W,0,Accounts!$C:$C,"Customer",Accounts!$H:$H,"<="&30)/M25) -> 0 | N27: =IF(N25=0,0,SUMIFS(Accounts!$M:$M,Accounts!$E:$E,'AccountSummary (New)'!N$1,Accounts!$G:$G,'AccountSummary (New)'!N$2,Accounts!$F:$F,'AccountSummary (New)'!N$3,Accounts!$W:$W,0,Accounts!$C:$C,"Customer",Accounts!$H:$H,"<="&30)/N25) -> 0 | O27: =IF(O25=0,0,SUMIFS(Accounts!$M:$M,Accounts!$E:$E,'AccountSummary (New)'!O$1,Accounts!$G:$G,'AccountSummary (New)'!O$2,Accounts!$F:$F,'AccountSummary (New)'!O$3,Accounts!$W:$W,0,Accounts!$C:$C,"Customer",Accounts!$H:$H,"<="&30)/O25) -> 0 | P27: =IF(P25=0,0,SUMIFS(Accounts!$M:$M,Accounts!$F:$F,'AccountSummary (New)'!P$3,Accounts!$W:$W,0,Accounts!$C:$C,"Customer",Accounts!$H:$H,"<="&30)/P25) -> 0 | Q27: =IF(Q25=0,0,SUMIFS(Accounts!$M:$M,Accounts!$E:$E,'AccountSummary (New)'!Q$1,Accounts!$G:$G,'AccountSummary (New)'!Q$2,Accounts!$F:$F,'AccountSummary (New)'!Q$3,Accounts!$W:$W,0,Accounts!$C:$C,"Customer",Accounts!$H:$H,"<="&30)/Q25) -> 0 | R27: =IF(R25=0,0,SUMIFS(Accounts!$M:$M,Accounts!$E:$E,'AccountSummary (New)'!R$1,Accounts!$G:$G,'AccountSummary (New)'!R$2,Accounts!$F:$F,'AccountSummary (New)'!R$3,Accounts!$W:$W,0,Accounts!$C:$C,"Customer",Accounts!$H:$H,"<="&30)/R25) -> 0 | S27: =IF(S25=0,0,SUMIFS(Accounts!$M:$M,Accounts!$E:$E,'AccountSummary (New)'!S$1,Accounts!$G:$G,'AccountSummary (New)'!S$2,Accounts!$F:$F,'AccountSummary (New)'!S$3,Accounts!$W:$W,0,Accounts!$C:$C,"Customer",Accounts!$H:$H,"<="&30)/S25) -> 0 | T27: =IF(T25=0,0,SUMIFS(Accounts!$M:$M,Accounts!$E:$E,'AccountSummary (New)'!T$1,Accounts!$G:$G,'AccountSummary (New)'!T$2,Accounts!$F:$F,'AccountSummary (New)'!T$3,Accounts!$W:$W,0,Accounts!$C:$C,"Customer",Accounts!$H:$H,"<="&30)/T25) -> 0 | U27: =IF(U25=0,0,SUMIFS(Accounts!$M:$M,Accounts!$E:$E,'AccountSummary (New)'!U$1,Accounts!$G:$G,'AccountSummary (New)'!U$2,Accounts!$F:$F,'AccountSummary (New)'!U$3,Accounts!$W:$W,0,Accounts!$C:$C,"Customer",Accounts!$H:$H,"<="&30)/U25) -> 0 | V27: =IF(V25=0,0,SUMIFS(Accounts!$M:$M,Accounts!$E:$E,'AccountSummary (New)'!V$1,Accounts!$G:$G,'AccountSummary (New)'!V$2,Accounts!$F:$F,'AccountSummary (New)'!V$3,Accounts!$W:$W,0,Accounts!$C:$C,"Customer",Accounts!$H:$H,"<="&30)/V25) -> 0 | W27: =IF(W25=0,0,SUMIFS(Accounts!$M:$M,Accounts!$F:$F,'AccountSummary (New)'!W$3,Accounts!$W:$W,0,Accounts!$C:$C,"Customer",Accounts!$H:$H,"<="&30)/W25) -> 0
A28: ARPC | B28: =IF(B25=0,0,B29/B25) -> 0 | C28: =IF(C25=0,0,C29/C25) -> 0 | D28: =IF(D25=0,0,D29/D25) -> 0 | E28: =IF(E25=0,0,E29/E25) -> 0 | F28: =IF(F25=0,0,F29/F25) -> 0 | G28: =IF(G25=0,0,G29/G25) -> 0 | H28: =IF(H25=0,0,H29/H25) -> 0 | I28: =IF(I25=0,0,I29/I25) -> 0 | ... W28: =IF(W25=0,0,W29/W25) -> 0
A29: SaaS | B29: =I29+P29+W29 -> 0 | C29: =SUMIFS(Accounts!$I:$I,Accounts!$E:$E,'AccountSummary (New)'!C$1,Accounts!$G:$G,'AccountSummary (New)'!C$2,Accounts!$F:$F,'AccountSummary (New)'!C$3,Accounts!$W:$W,0,Accounts!$C:$C,"Customer",Accounts!$H:$H,"<="&30) -> 0 | D29: =SUMIFS(Accounts!$I:$I,Accounts!$E:$E,'AccountSummary (New)'!D$1,Accounts!$G:$G,'AccountSummary (New)'!D$2,Accounts!$F:$F,'AccountSummary (New)'!D$3,Accounts!$W:$W,0,Accounts!$C:$C,"Customer",Accounts!$H:$H,"<="&30) -> 0 | E29: =SUMIFS(Accounts!$I:$I,Accounts!$E:$E,'AccountSummary (New)'!E$1,Accounts!$G:$G,'AccountSummary (New)'!E$2,Accounts!$F:$F,'AccountSummary (New)'!E$3,Accounts!$W:$W,0,Accounts!$C:$C,"Customer",Accounts!$H:$H,"<="&30) -> 0 | F29: =SUMIFS(Accounts!$I:$I,Accounts!$E:$E,'AccountSummary (New)'!F$1,Accounts!$G:$G,'AccountSummary (New)'!F$2,Accounts!$F:$F,'AccountSummary (New)'!F$3,Accounts!$W:$W,0,Accounts!$C:$C,"Customer",Accounts!$H:$H,"<="&30) -> 0 | G29: =SUMIFS(Accounts!$I:$I,Accounts!$E:$E,'AccountSummary (New)'!G$1,Accounts!$G:$G,'AccountSummary (New)'!G$2,Accounts!$F:$F,'AccountSummary (New)'!G$3,Accounts!$W:$W,0,Accounts!$C:$C,"Customer",Accounts!$H:$H,"<="&30) -> 0 | H29: =SUMIFS(Accounts!$I:$I,Accounts!$E:$E,'AccountSummary (New)'!H$1,Accounts!$G:$G,'AccountSummary (New)'!H$2,Accounts!$F:$F,'AccountSummary (New)'!H$3,Accounts!$W:$W,0,Accounts!$C:$C,"Customer",Accounts!$H:$H,"<="&30) -> 0 | I29: =SUM(C29:H29) -> 0 | J29: =SUMIFS(Accounts!$I:$I,Accounts!$E:$E,'AccountSummary (New)'!J$1,Accounts!$G:$G,'AccountSummary (New)'!J$2,Accounts!$F:$F,'AccountSummary (New)'!J$3,Accounts!$W:$W,0,Accounts!$C:$C,"Customer",Accounts!$H:$H,"<="&30) -> 0 | K29: =SUMIFS(Accounts!$I:$I,Accounts!$E:$E,'AccountSummary (New)'!K$1,Accounts!$G:$G,'AccountSummary (New)'!K$2,Accounts!$F:$F,'AccountSummary (New)'!K$3,Accounts!$W:$W,0,Accounts!$C:$C,"Customer",Accounts!$H:$H,"<="&30) -> 0 | L29: =SUMIFS(Accounts!$I:$I,Accounts!$E:$E,'AccountSummary (New)'!L$1,Accounts!$G:$G,'AccountSummary (New)'!L$2,Accounts!$F:$F,'AccountSummary (New)'!L$3,Accounts!$W:$W,0,Accounts!$C:$C,"Customer",Accounts!$H:$H,"<="&30) -> 0 | M29: =SUMIFS(Accounts!$I:$I,Accounts!$E:$E,'AccountSummary (New)'!M$1,Accounts!$G:$G,'AccountSummary (New)'!M$2,Accounts!$F:$F,'AccountSummary (New)'!M$3,Accounts!$W:$W,0,Accounts!$C:$C,"Customer",Accounts!$H:$H,"<="&30) -> 0 | N29: =SUMIFS(Accounts!$I:$I,Accounts!$E:$E,'AccountSummary (New)'!N$1,Accounts!$G:$G,'AccountSummary (New)'!N$2,Accounts!$F:$F,'AccountSummary (New)'!N$3,Accounts!$W:$W,0,Accounts!$C:$C,"Customer",Accounts!$H:$H,"<="&30) -> 0 | O29: =SUMIFS(Accounts!$I:$I,Accounts!$E:$E,'AccountSummary (New)'!O$1,Accounts!$G:$G,'AccountSummary (New)'!O$2,Accounts!$F:$F,'AccountSummary (New)'!O$3,Accounts!$W:$W,0,Accounts!$C:$C,"Customer",Accounts!$H:$H,"<="&30) -> 0 | P29: =SUM(J29:O29) -> 0 | Q29: =SUMIFS(Accounts!$I:$I,Accounts!$E:$E,'AccountSummary (New)'!Q$1,Accounts!$G:$G,'AccountSummary (New)'!Q$2,Accounts!$F:$F,'AccountSummary (New)'!Q$3,Accounts!$W:$W,0,Accounts!$C:$C,"Customer",Accounts!$H:$H,"<="&30) -> 0 | R29: =SUMIFS(Accounts!$I:$I,Accounts!$E:$E,'AccountSummary (New)'!R$1,Accounts!$G:$G,'AccountSummary (New)'!R$2,Accounts!$F:$F,'AccountSummary (New)'!R$3,Accounts!$W:$W,0,Accounts!$C:$C,"Customer",Accounts!$H:$H,"<="&30) -> 0 | S29: =SUMIFS(Accounts!$I:$I,Accounts!$E:$E,'AccountSummary (New)'!S$1,Accounts!$G:$G,'AccountSummary (New)'!S$2,Accounts!$F:$F,'AccountSummary (New)'!S$3,Accounts!$W:$W,0,Accounts!$C:$C,"Customer",Accounts!$H:$H,"<="&30) -> 0 | T29: =SUMIFS(Accounts!$I:$I,Accounts!$E:$E,'AccountSummary (New)'!T$1,Accounts!$G:$G,'AccountSummary (New)'!T$2,Accounts!$F:$F,'AccountSummary (New)'!T$3,Accounts!$W:$W,0,Accounts!$C:$C,"Customer",Accounts!$H:$H,"<="&30) -> 0 | U29: =SUMIFS(Accounts!$I:$I,Accounts!$E:$E,'AccountSummary (New)'!U$1,Accounts!$G:$G,'AccountSummary (New)'!U$2,Accounts!$F:$F,'AccountSummary (New)'!U$3,Accounts!$W:$W,0,Accounts!$C:$C,"Customer",Accounts!$H:$H,"<="&30) -> 0 | V29: =SUMIFS(Accounts!$I:$I,Accounts!$E:$E,'AccountSummary (New)'!V$1,Accounts!$G:$G,'AccountSummary (New)'!V$2,Accounts!$F:$F,'AccountSummary (New)'!V$3,Accounts!$W:$W,0,Accounts!$C:$C,"Customer",Accounts!$H:$H,"<="&30) -> 0 | W29: =SUM(Q29:V29) -> 0
A30: 31-60 day cohort as of BOM
A31: Total % of Paying Customers | B31: =IF(B$19=0,0,(B33+B34)/B$19) -> 0 | C31: =IF(C$19=0,0,(C33+C34)/C$19) -> 0 | D31: =IF(D$19=0,0,(D33+D34)/D$19) -> 0 | E31: =IF(E$19=0,0,(E33+E34)/E$19) -> 0 | F31: =IF(F$19=0,0,(F33+F34)/F$19) -> 0 | G31: =IF(G$19=0,0,(G33+G34)/G$19) -> 0 | H31: =IF(H$19=0,0,(H33+H34)/H$19) -> 0 | I31: =IF(I$19=0,0,(I33+I34)/I$19) -> 0 | ... W31: =IF(W$19=0,0,(W33+W34)/W$19) -> 0
A32: Loss % | B32: =IF((B33+B34)=0,0,B33/(B33+B34)) -> 0 | C32: =IF((C33+C34)=0,0,C33/(C33+C34)) -> 0 | D32: =IF((D33+D34)=0,0,D33/(D33+D34)) -> 0 | E32: =IF((E33+E34)=0,0,E33/(E33+E34)) -> 0 | F32: =IF((F33+F34)=0,0,F33/(F33+F34)) -> 0 | G32: =IF((G33+G34)=0,0,G33/(G33+G34)) -> 0 | H32: =IF((H33+H34)=0,0,H33/(H33+H34)) -> 0 | I32: =IF((I33+I34)=0,0,I33/(I33+I34)) -> 0 | ... W32: =IF((W33+W34)=0,0,W33/(W33+W34)) -> 0
A33: Lost Count | B33: =I33+P33+W33 -> 0 | C33: =COUNTIFS(Accounts!$E:$E,'AccountSummary (New)'!C$1,Accounts!$G:$G,'AccountSummary (New)'!C$2,Accounts!$F:$F,'AccountSummary (New)'!C$3,Accounts!$B:$B,"Customer",Accounts!$C:$C,"Lost",Accounts!$H:$H,">"&30,Accounts!$H:$H,"<="&60) -> 0 | D33: =COUNTIFS(Accounts!$E:$E,'AccountSummary (New)'!D$1,Accounts!$G:$G,'AccountSummary (New)'!D$2,Accounts!$F:$F,'AccountSummary (New)'!D$3,Accounts!$B:$B,"Customer",Accounts!$C:$C,"Lost",Accounts!$H:$H,">"&30,Accounts!$H:$H,"<="&60) -> 0 | E33: =COUNTIFS(Accounts!$E:$E,'AccountSummary (New)'!E$1,Accounts!$G:$G,'AccountSummary (New)'!E$2,Accounts!$F:$F,'AccountSummary (New)'!E$3,Accounts!$B:$B,"Customer",Accounts!$C:$C,"Lost",Accounts!$H:$H,">"&30,Accounts!$H:$H,"<="&60) -> 0 | F33: =COUNTIFS(Accounts!$E:$E,'AccountSummary (New)'!F$1,Accounts!$G:$G,'AccountSummary (New)'!F$2,Accounts!$F:$F,'AccountSummary (New)'!F$3,Accounts!$B:$B,"Customer",Accounts!$C:$C,"Lost",Accounts!$H:$H,">"&30,Accounts!$H:$H,"<="&60) -> 0 | G33: =COUNTIFS(Accounts!$E:$E,'AccountSummary (New)'!G$1,Accounts!$G:$G,'AccountSummary (New)'!G$2,Accounts!$F:$F,'AccountSummary (New)'!G$3,Accounts!$B:$B,"Customer",Accounts!$C:$C,"Lost",Accounts!$H:$H,">"&30,Accounts!$H:$H,"<="&60) -> 0 | H33: =COUNTIFS(Accounts!$E:$E,'AccountSummary (New)'!H$1,Accounts!$G:$G,'AccountSummary (New)'!H$2,Accounts!$F:$F,'AccountSummary (New)'!H$3,Accounts!$B:$B,"Customer",Accounts!$C:$C,"Lost",Accounts!$H:$H,">"&30,Accounts!$H:$H,"<="&60) -> 0 | I33: =SUM(C33:H33) -> 0 | J33: =COUNTIFS(Accounts!$E:$E,'AccountSummary (New)'!J$1,Accounts!$G:$G,'AccountSummary (New)'!J$2,Accounts!$F:$F,'AccountSummary (New)'!J$3,Accounts!$B:$B,"Customer",Accounts!$C:$C,"Lost",Accounts!$H:$H,">"&30,Accounts!$H:$H,"<="&60) -> 0 | K33: =COUNTIFS(Accounts!$E:$E,'AccountSummary (New)'!K$1,Accounts!$G:$G,'AccountSummary (New)'!K$2,Accounts!$F:$F,'AccountSummary (New)'!K$3,Accounts!$B:$B,"Customer",Accounts!$C:$C,"Lost",Accounts!$H:$H,">"&30,Accounts!$H:$H,"<="&60) -> 0 | L33: =COUNTIFS(Accounts!$E:$E,'AccountSummary (New)'!L$1,Accounts!$G:$G,'AccountSummary (New)'!L$2,Accounts!$F:$F,'AccountSummary (New)'!L$3,Accounts!$B:$B,"Customer",Accounts!$C:$C,"Lost",Accounts!$H:$H,">"&30,Accounts!$H:$H,"<="&60) -> 0 | M33: =COUNTIFS(Accounts!$E:$E,'AccountSummary (New)'!M$1,Accounts!$G:$G,'AccountSummary (New)'!M$2,Accounts!$F:$F,'AccountSummary (New)'!M$3,Accounts!$B:$B,"Customer",Accounts!$C:$C,"Lost",Accounts!$H:$H,">"&30,Accounts!$H:$H,"<="&60) -> 0 | N33: =COUNTIFS(Accounts!$E:$E,'AccountSummary (New)'!N$1,Accounts!$G:$G,'AccountSummary (New)'!N$2,Accounts!$F:$F,'AccountSummary (New)'!N$3,Accounts!$B:$B,"Customer",Accounts!$C:$C,"Lost",Accounts!$H:$H,">"&30,Accounts!$H:$H,"<="&60) -> 0 | O33: =COUNTIFS(Accounts!$E:$E,'AccountSummary (New)'!O$1,Accounts!$G:$G,'AccountSummary (New)'!O$2,Accounts!$F:$F,'AccountSummary (New)'!O$3,Accounts!$B:$B,"Customer",Accounts!$C:$C,"Lost",Accounts!$H:$H,">"&30,Accounts!$H:$H,"<="&60) -> 0 | P33: =SUM(J33:O33) -> 0 | Q33: =COUNTIFS(Accounts!$E:$E,'AccountSummary (New)'!Q$1,Accounts!$G:$G,'AccountSummary (New)'!Q$2,Accounts!$F:$F,'AccountSummary (New)'!Q$3,Accounts!$B:$B,"Customer",Accounts!$C:$C,"Lost",Accounts!$H:$H,">"&30,Accounts!$H:$H,"<="&60) -> 0 | R33: =COUNTIFS(Accounts!$E:$E,'AccountSummary (New)'!R$1,Accounts!$G:$G,'AccountSummary (New)'!R$2,Accounts!$F:$F,'AccountSummary (New)'!R$3,Accounts!$B:$B,"Customer",Accounts!$C:$C,"Lost",Accounts!$H:$H,">"&30,Accounts!$H:$H,"<="&60) -> 0 | S33: =COUNTIFS(Accounts!$E:$E,'AccountSummary (New)'!S$1,Accounts!$G:$G,'AccountSummary (New)'!S$2,Accounts!$F:$F,'AccountSummary (New)'!S$3,Accounts!$B:$B,"Customer",Accounts!$C:$C,"Lost",Accounts!$H:$H,">"&30,Accounts!$H:$H,"<="&60) -> 0 | T33: =COUNTIFS(Accounts!$E:$E,'AccountSummary (New)'!T$1,Accounts!$G:$G,'AccountSummary (New)'!T$2,Accounts!$F:$F,'AccountSummary (New)'!T$3,Accounts!$B:$B,"Customer",Accounts!$C:$C,"Lost",Accounts!$H:$H,">"&30,Accounts!$H:$H,"<="&60) -> 0 | U33: =COUNTIFS(Accounts!$E:$E,'AccountSummary (New)'!U$1,Accounts!$G:$G,'AccountSummary (New)'!U$2,Accounts!$F:$F,'AccountSummary (New)'!U$3,Accounts!$B:$B,"Customer",Accounts!$C:$C,"Lost",Accounts!$H:$H,">"&30,Accounts!$H:$H,"<="&60) -> 0 | V33: =COUNTIFS(Accounts!$E:$E,'AccountSummary (New)'!V$1,Accounts!$G:$G,'AccountSummary (New)'!V$2,Accounts!$F:$F,'AccountSummary (New)'!V$3,Accounts!$B:$B,"Customer",Accounts!$C:$C,"Lost",Accounts!$H:$H,">"&30,Accounts!$H:$H,"<="&60) -> 0 | W33: =SUM(Q33:V33) -> 0
