Workbook

Sheet Customers
A1: CompanyAccount | B1: CustomerGroupingPeriod1 | C1: CustomerGroupingPeriod2 | D1: DiscountOtherSaaSPeriod1 | E1: DiscountOtherSaaSPeriod2 | F1: DiscountOtherPSPeriod1 | G1: DiscountOtherPSPeriod2 | H1: DiscountPrepayPortionPeriod1 | I1: DiscountPrepayPortionPeriod2 | J1: InvoiceGrouping | K1: LiabilityPortionPeriod1 | L1: LiabilityPortionPeriod2 | M1: PackPaidCountPeriod1 | N1: PackPaidCountPeriod2 | O1: PlatformTogglePeriod1 | P1: PlatformTogglePeriod2 | Q1: PSExpenseAmountPeriod1 | R1: PSExpenseAmountPeriod2 | S1: PSIncomeAmountPeriod1 | T1: PSIncomeAmountPeriod2 | U1: SaasExpensePeriod1 | V1: SaasExpensePeriod2 | W1: SaaSIncomeAmountClassicPeriod1 | X1: SaaSIncomeAmountClassicPeriod2 | Y1: SaaSIncomeAmountNewPeriod1 | Z1: SaaSIncomeAmountNewPeriod2 | AA1: SaaSPayTypePeriod1 | AB1: SaaSPayTypePeriod2 | AC1: SalesRepSaaSPeriod1 | AD1: SalesRepSaaSPeriod2 | AE1: UncategorizedPortionPeriod1 | AF1: UncategorizedPortionPeriod2 | AG1: UserPaidCountPeriod1 | AH1: UserPaidCountPeriod2 | AI1: SaaSNetPeriod1 | AJ1: SaaSNetPeriod2 | AK1: SaaSExpandNew | AL1: SaaSExpansionUp | AM1: SaaSNoChange | AN1: SaaSContractionCancel | AO1: SaaSContractionDown | AP1: Currency | AQ1: CustomerRecordID | AR1: PerPayExpriyPeriod1 | AS1: PerPayExpriyPeriod2
A2: duralinesystemsinc2 | B2: ExistingCustomerEOM | C2: ExistingCustomerEOM | D2: 0 | E2: 0 | F2: -263.5 | G2: -108.5 | H2: 0 | I2: 0 | K2: 0 | L2: 0 | M2: 5 | N2: 5 | O2: New | P2: New | Q2: 0 | R2: 0 | S2: 2635 | T2: 1085 | U2: 0 | V2: 0 | W2: 0 | X2: 0 | Y2: 1090 | Z2: 1099 | AA2: Monthly | AB2: Monthly | AC2: HaPat | AD2: HaPat | AE2: 0 | AF2: 0 | AG2: 15 | AH2: 15 | AI2: ==W2+ Y2+D2+H2 | AJ2: ==X2+Z2+E2+I2 | AK2: ==IF(AI2=0,AJ2,0) | AL2: ==IF(AND(AI2>0,AJ2>AI2),AJ2-AI2,0) | AM2: ==IF(AI2=AJ2,AJ2,0) | AN2: ==IF(AJ2=0,AI2,0) | AO2: ==IF(AND(AJ2>0,AJ2<AI2),AI2-AJ2,0) | AP2: US-Accounts Receivable | AQ2: 156531 | AR2: 0 | AS2: 0
A3: foreigntaxcpa | B3: ExistingCustomerEOM | C3: ExistingCustomerEOM | D3: 0 | E3: 0 | F3: -46.5 | G3: 0 | H3: -140 | I3: 0 | K3: -420 | L3: 0 | M3: 3 | N3: 3 | O3: unknown | P3: unknown | Q3: 0 | R3: -77.5 | S3: 465 | T3: 77.5 | U3: 0 | V3: 0 | W3: 0 | X3: 0 | Y3: 885 | Z3: 956 | AA3: Prepay | AB3: Monthly | AC3: PhuPh | AD3: PhuPh | AE3: 0 | AF3: 0 | AG3: 14 | AH3: 16 | AI3: ==W3+ Y3+D3+H3 | AJ3: ==X3+Z3+E3+I3 | AK3: ==IF(AI3=0,AJ3,0) | AL3: ==IF(AND(AI3>0,AJ3>AI3),AJ3-AI3,0) | AM3: ==IF(AI3=AJ3,AJ3,0) | AN3: ==IF(AJ3=0,AI3,0) | AO3: ==IF(AND(AJ3>0,AJ3<AI3),AI3-AJ3,0) | AP3: US-Accounts Receivable | AQ3: 175034 | AR3: 0 | AS3: 0
A4: alerthomewatch | B4: ExistingCustomerEOM | C4: ExistingCustomerEOM | D4: 0 | E4: 0 | F4: 0 | G4: 0 | H4: 0 | I4: 0 | K4: 0 | L4: 0 | M4: 1 | N4: 1 | O4: New | P4: New | Q4: 0 | R4: 0 | S4: 0 | T4: 0 | U4: 0 | V4: 0 | W4: 0 | X4: 0 | Y4: 84 | Z4: 84 | AA4: Monthly | AB4: Monthly | AC4: PhuPh | AD4: PhuPh | AE4: 0 | AF4: 0 | AG4: 3 | AH4: 3 | AI4: ==W4+ Y4+D4+H4 | AJ4: ==X4+Z4+E4+I4 | AK4: ==IF(AI4=0,AJ4,0) | AL4: ==IF(AND(AI4>0,AJ4>AI4),AJ4-AI4,0) | AM4: ==IF(AI4=AJ4,AJ4,0) | AN4: ==IF(AJ4=0,AI4,0) | AO4: ==IF(AND(AJ4>0,AJ4<AI4),AI4-AJ4,0) | AP4: US-Accounts Receivable | AQ4: 96657 | AR4: 0 | AS4: 0
A5: CarlsonConcierge | B5: ExistingCustomerEOM | C5: ExistingCustomerEOM | D5: -11.2 | E5: -11.2 | F5: 0 | G5: 0 | H5: 0 | I5: 0 | K5: 0 | L5: 0 | M5: 1 | N5: 1 | O5: New | P5: New | Q5: 0 | R5: 0 | S5: 0 | T5: 0 | U5: 0 | V5: 0 | W5: 0 | X5: 0 | Y5: 56 | Z5: 56 | AA5: Monthly | AB5: Monthly | AC5: PhuPh | AD5: PhuPh | AE5: 0 | AF5: 0 | AG5: 2 | AH5: 2 | AI5: ==W5+ Y5+D5+H5 | AJ5: ==X5+Z5+E5+I5 | AK5: ==IF(AI5=0,AJ5,0) | AL5: ==IF(AND(AI5>0,AJ5>AI5),AJ5-AI5,0) | AM5: ==IF(AI5=AJ5,AJ5,0) | AN5: ==IF(AJ5=0,AI5,0) | AO5: ==IF(AND(AJ5>0,AJ5<AI5),AI5-AJ5,0) | AP5: US-Accounts Receivable | AQ5: 86456 | AR5: 0 | AS5: 0
A6: hwmadison | B6: ExistingCustomerEOM | C6: ExistingCustomerEOM | D6: 0 | E6: 0 | F6: 0 | G6: 0 | H6: 0 | I6: 0 | K6: 0 | L6: 0 | M6: 1 | N6: 1 | O6: New | P6: New | Q6: 0 | R6: 0 | S6: 0 | T6: 0 | U6: 0 | V6: 0 | W6: 0 | X6: 0 | Y6: 56 | Z6: 56 | AA6: Monthly | AB6: Monthly | AC6: PhuPh | AD6: PhuPh | AE6: 0 | AF6: 0 | AG6: 2 | AH6: 2 | AI6: ==W6+ Y6+D6+H6 | AJ6: ==X6+Z6+E6+I6 | AK6: ==IF(AI6=0,AJ6,0) | AL6: ==IF(AND(AI6>0,AJ6>AI6),AJ6-AI6,0) | AM6: ==IF(AI6=AJ6,AJ6,0) | AN6: ==IF(AJ6=0,AI6,0) | AO6: ==IF(AND(AJ6>0,AJ6<AI6),AI6-AJ6,0) | AP6: US-Accounts Receivable | AQ6: 132775 | AR6: 0 | AS6: 0
A7: leddy | B7: ExistingCustomerEOM | C7: ExistingCustomerEOM | D7: 0 | E7: 0 | F7: 0 | G7: 0 | H7: 0 | I7: 0 | K7: 0 | L7: 0 | M7: 1 | N7: 1 | O7: New | P7: New | Q7: 0 | R7: 0 | S7: 0 | T7: 0 | U7: 0 | V7: 0 | W7: 0 | X7: 0 | Y7: 28 | Z7: 28 | AA7: Monthly | AB7: Monthly | AC7: PhuPh | AD7: PhuPh | AE7: 0 | AF7: 0 | AG7: 1 | AH7: 1 | AI7: ==W7+ Y7+D7+H7 | AJ7: ==X7+Z7+E7+I7 | AK7: ==IF(AI7=0,AJ7,0) | AL7: ==IF(AND(AI7>0,AJ7>AI7),AJ7-AI7,0) | AM7: ==IF(AI7=AJ7,AJ7,0) | AN7: ==IF(AJ7=0,AI7,0) | AO7: ==IF(AND(AJ7>0,AJ7<AI7),AI7-AJ7,0) | AP7: US-Accounts Receivable | AQ7: 148689 | AR7: 0 | AS7: 0
A8: beyonddetailedsolutions | B8: ExistingCustomerEOM | C8: ExistingCustomerEOM | D8: 0 | E8: 0 | F8: 0 | G8: 0 | H8: -3 | I8: -3 | K8: -25 | L8: -25 | M8: 1 | N8: 1 | O8: New | P8: New | Q8: 0 | R8: 0 | S8: 0 | T8: 0 | U8: 0 | V8: 0 | W8: 0 | X8: 0 | Y8: 28 | Z8: 28 | AA8: Prepay | AB8: Prepay | AC8: PhuPh | AD8: PhuPh | AE8: 0 | AF8: 0 | AG8: 1 | AH8: 1 | AI8: ==W8+ Y8+D8+H8 | AJ8: ==X8+Z8+E8+I8 | AK8: ==IF(AI8=0,AJ8,0) | AL8: ==IF(AND(AI8>0,AJ8>AI8),AJ8-AI8,0) | AM8: ==IF(AI8=AJ8,AJ8,0) | AN8: ==IF(AJ8=0,AI8,0) | AO8: ==IF(AND(AJ8>0,AJ8<AI8),AI8-AJ8,0) | AP8: US-Accounts Receivable | AQ8: 150052 | AR8: 0 | AS8: 0
A9: guardianangel | B9: ExistingCustomerEOM | C9: ExistingCustomerEOM | D9: 0 | E9: 0 | F9: 0 | G9: 0 | H9: 0 | I9: 0 | K9: 0 | L9: 0 | M9: 0 | N9: 0 | O9: unknown | P9: unknown | Q9: 0 | R9: 0 | S9: 0 | T9: 0 | U9: 0 | V9: 0 | W9: 0 | X9: 0 | Y9: 0 | Z9: 0 | AE9: 0 | AF9: 0 | AG9: 0 | AH9: 0 | AI9: ==W9+ Y9+D9+H9 | AJ9: ==X9+Z9+E9+I9 | AK9: ==IF(AI9=0,AJ9,0) | AL9: ==IF(AND(AI9>0,AJ9>AI9),AJ9-AI9,0) | AM9: ==IF(AI9=AJ9,AJ9,0) | AN9: ==IF(AJ9=0,AI9,0) | AO9: ==IF(AND(AJ9>0,AJ9<AI9),AI9-AJ9,0) | AP9: US-Accounts Receivable | AQ9: 150132 | AR9: 0 | AS9: 0
A10: alliedhomewatch2 | B10: ExistingCustomerEOM | D10: 0 | E10: 0 | F10: 0 | G10: 0 | H10: 0 | I10: 0 | K10: 0 | L10: 0 | M10: 1 | N10: 0 | O10: New | Q10: 0 | R10: 0 | S10: 0 | T10: 0 | U10: 0 | V10: 0 | W10: 0 | X10: 0 | Y10: 28 | Z10: 0 | AA10: Monthly | AC10: PhuPh | AE10: 0 | AF10: 0 | AG10: 1 | AH10: 0 | AI10: ==W10+ Y10+D10+H10 | AJ10: ==X10+Z10+E10+I10 | AK10: ==IF(AI10=0,AJ10,0) | AL10: ==IF(AND(AI10>0,AJ10>AI10),AJ10-AI10,0) | AM10: ==IF(AI10=AJ10,AJ10,0) | AN10: ==IF(AJ10=0,AI10,0) | AO10: ==IF(AND(AJ10>0,AJ10<AI10),AI10-AJ10,0) | AP10: US-Accounts Receivable | AQ10: 152940 | AR10: 0 | AS10: 0
A11: casanapleshomewatch | B11: ExistingCustomerEOM | C11: ExistingCustomerEOM | D11: 0 | E11: 0 | F11: 0 | G11: 0 | H11: 0 | I11: 0 | K11: 0 | L11: 0 | M11: 1 | N11: 1 | O11: New | P11: New | Q11: 0 | R11: 0 | S11: 0 | T11: 0 | U11: 0 | V11: 0 | W11: 0 | X11: 0 | Y11: 28 | Z11: 28 | AA11: Monthly | AB11: Monthly | AC11: PhuPh | AD11: PhuPh | AE11: 0 | AF11: 0 | AG11: 1 | AH11: 1 | AI11: ==W11+ Y11+D11+H11 | AJ11: ==X11+Z11+E11+I11 | AK11: ==IF(AI11=0,AJ11,0) | AL11: ==IF(AND(AI11>0,AJ11>AI11),AJ11-AI11,0) | AM11: ==IF(AI11=AJ11,AJ11,0) | AN11: ==IF(AJ11=0,AI11,0) | AO11: ==IF(AND(AJ11>0,AJ11<AI11),AI11-AJ11,0) | AP11: US-Accounts Receivable | AQ11: 159752 | AR11: 0 | AS11: 0
A12: rimrocksoftware | B12: TrialerCancelled | D12: 0 | E12: 0 | F12: 0 | G12: 0 | H12: 0 | I12: 0 | K12: 0 | L12: 0 | M12: 2 | N12: 0 | O12: New | Q12: 0 | R12: 0 | S12: 0 | T12: 0 | U12: 0 | V12: 0 | W12: 0 | X12: 0 | Y12: 40 | Z12: 0 | AA12: Monthly | AC12: PhuPh | AE12: 0 | AF12: 0 | AG12: 1 | AH12: 0 | AI12: ==W12+ Y12+D12+H12 | AJ12: ==X12+Z12+E12+I12 | AK12: ==IF(AI12=0,AJ12,0) | AL12: ==IF(AND(AI12>0,AJ12>AI12),AJ12-AI12,0) | AM12: ==IF(AI12=AJ12,AJ12,0) | AN12: ==IF(AJ12=0,AI12,0) | AO12: ==IF(AND(AJ12>0,AJ12<AI12),AI12-AJ12,0) | AP12: US-Accounts Receivable | AQ12: 177742 | AR12: 0 | AS12: 0
A13: lightconsultancy | B13: ExistingCustomerEOM | C13: ExistingCustomerEOM | D13: -101 | E13: -101 | F13: 0 | G13: 0 | H13: 0 | I13: 0 | K13: 0 | L13: 0 | M13: 4 | N13: 4 | O13: New | P13: New | Q13: 0 | R13: 0 | S13: 0 | T13: 0 | U13: 0 | V13: 0 | W13: 0 | X13: 0 | Y13: 101 | Z13: 101 | AA13: Monthly | AB13: Monthly | AC13: PhuPh | AD13: PhuPh | AE13: 0 | AF13: 0 | AG13: 2 | AH13: 2 | AI13: ==W13+ Y13+D13+H13 | AJ13: ==X13+Z13+E13+I13 | AK13: ==IF(AI13=0,AJ13,0) | AL13: ==IF(AND(AI13>0,AJ13>AI13),AJ13-AI13,0) | AM13: ==IF(AI13=AJ13,AJ13,0) | AN13: ==IF(AJ13=0,AI13,0) | AO13: ==IF(AND(AJ13>0,AJ13<AI13),AI13-AJ13,0) | AP13: US-Accounts Receivable | AQ13: 173877 | AR13: 0 | AS13: 0
A14: upfrontservices | B14: NewCustomerEOM | C14: ExistingCustomerEOM | D14: 0 | E14: 0 | F14: 0 | G14: 0 | H14: 0 | I14: 0 | K14: 0 | L14: 0 | M14: 6 | N14: 6 | O14: New | P14: New | Q14: 0 | R14: 0 | S14: 0 | T14: 0 | U14: 0 | V14: 0 | W14: 0 | X14: 0 | Y14: 553 | Z14: 836 | AA14: Monthly | AB14: Monthly | AC14: PhuPh | AD14: PhuPh | AE14: 0 | AF14: 0 | AG14: 10 | AH14: 10 | AI14: ==W14+ Y14+D14+H14 | AJ14: ==X14+Z14+E14+I14 | AK14: ==IF(AI14=0,AJ14,0) | AL14: ==IF(AND(AI14>0,AJ14>AI14),AJ14-AI14,0) | AM14: ==IF(AI14=AJ14,AJ14,0) | AN14: ==IF(AJ14=0,AI14,0) | AO14: ==IF(AND(AJ14>0,AJ14<AI14),AI14-AJ14,0) | AP14: US-Accounts Receivable | AQ14: 176322 | AR14: 0 | AS14: 0
A15: ceo40groupinc | B15: NewCustomerEOM | C15: ExistingCustomerEOM | D15: 0 | E15: 0 | F15: 0 | G15: 0 | H15: 0 | I15: 0 | K15: 0 | L15: 0 | M15: 3 | N15: 3 | O15: New | P15: New | Q15: 0 | R15: 0 | S15: 0 | T15: 0 | U15: 0 | V15: 0 | W15: 0 | X15: 0 | Y15: 49 | Z15: 151 | AA15: Monthly | AB15: Monthly | AC15: ChWon | AD15: UrRao | AE15: 0 | AF15: 0 | AG15: 1 | AH15: 4 | AI15: ==W15+ Y15+D15+H15 | AJ15: ==X15+Z15+E15+I15 | AK15: ==IF(AI15=0,AJ15,0) | AL15: ==IF(AND(AI15>0,AJ15>AI15),AJ15-AI15,0) | AM15: ==IF(AI15=AJ15,AJ15,0) | AN15: ==IF(AJ15=0,AI15,0) | AO15: ==IF(AND(AJ15>0,AJ15<AI15),AI15-AJ15,0) | AP15: US-Accounts Receivable | AQ15: 176317 | AR15: 0 | AS15: 0
A16: theatticdepot2 | B16: NewCustomerEOM | C16: ExistingCustomerEOM | D16: 0 | E16: 0 | F16: 0 | G16: 0 | H16: -30.5 | I16: -16.2 | K16: -91.5 | L16: -145.8 | M16: 5 | N16: 5 | O16: New | P16: New | Q16: 0 | R16: 0 | S16: 0 | T16: 0 | U16: 0 | V16: 0 | W16: 0 | X16: 0 | Y16: 122 | Z16: 162 | AA16: Prepay | AB16: Prepay | AC16: ChWon | AD16: SukSa | AE16: 0 | AF16: 0 | AG16: 2 | AH16: 3 | AI16: ==W16+ Y16+D16+H16 | AJ16: ==X16+Z16+E16+I16 | AK16: ==IF(AI16=0,AJ16,0) | AL16: ==IF(AND(AI16>0,AJ16>AI16),AJ16-AI16,0) | AM16: ==IF(AI16=AJ16,AJ16,0) | AN16: ==IF(AJ16=0,AI16,0) | AO16: ==IF(AND(AJ16>0,AJ16<AI16),AI16-AJ16,0) | AP16: US-Accounts Receivable | AQ16: 176326 | AR16: 0 | AS16: 0
A17: pipemonsterplumbingllc | B17: NewCustChurn | D17: 0 | E17: 0 | F17: 0 | G17: 0 | H17: 0 | I17: 0 | K17: 0 | L17: 0 | M17: 4 | N17: 0 | O17: New | Q17: 0 | R17: 0 | S17: 0 | T17: 0 | U17: 0 | V17: 0 | W17: 0 | X17: 0 | Y17: 183 | Z17: 0 | AA17: Monthly | AC17: ChWon | AE17: 0 | AF17: 0 | AG17: 3 | AH17: 0 | AI17: ==W17+ Y17+D17+H17 | AJ17: ==X17+Z17+E17+I17 | AK17: ==IF(AI17=0,AJ17,0) | AL17: ==IF(AND(AI17>0,AJ17>AI17),AJ17-AI17,0) | AM17: ==IF(AI17=AJ17,AJ17,0) | AN17: ==IF(AJ17=0,AI17,0) | AO17: ==IF(AND(AJ17>0,AJ17<AI17),AI17-AJ17,0) | AP17: US-Accounts Receivable | AQ17: 176314 | AR17: 0 | AS17: 0
A18: hallknifeandforge | B18: ExistingCustomerEOM | C18: ExistingCustomerEOM | D18: 0 | E18: 0 | F18: 0 | G18: 0 | H18: 0 | I18: 0 | K18: 0 | L18: 0 | M18: 3 | N18: 3 | O18: New | P18: New | Q18: 0 | R18: 0 | S18: 0 | T18: 0 | U18: 0 | V18: 0 | W18: 0 | X18: 0 | Y18: 52 | Z18: 52 | AA18: Monthly | AB18: Monthly | AC18: JaiPa | AD18: JaiPa | AE18: 0 | AF18: 0 | AG18: 1 | AH18: 1 | AI18: ==W18+ Y18+D18+H18 | AJ18: ==X18+Z18+E18+I18 | AK18: ==IF(AI18=0,AJ18,0) | AL18: ==IF(AND(AI18>0,AJ18>AI18),AJ18-AI18,0) | AM18: ==IF(AI18=AJ18,AJ18,0) | AN18: ==IF(AJ18=0,AI18,0) | AO18: ==IF(AND(AJ18>0,AJ18<AI18),AI18-AJ18,0) | AP18: CAN-Accounts Receivable | AQ18: 168753 | AR18: 0 | AS18: 0
A19: ethiopiancommunityassociationofgreaterphil | B19: ExistingCustomerEOM | D19: 0 | E19: 0 | F19: 0 | G19: 0 | H19: -3 | I19: 0 | K19: -25 | L19: 0 | M19: 1 | N19: 0 | O19: New | Q19: 0 | R19: 0 | S19: 0 | T19: 0 | U19: 0 | V19: 0 | W19: 0 | X19: 0 | Y19: 28 | Z19: 0 | AA19: Prepay | AC19: RafSy | AE19: 0 | AF19: 0 | AG19: 1 | AH19: 0 | AI19: ==W19+ Y19+D19+H19 | AJ19: ==X19+Z19+E19+I19 | AK19: ==IF(AI19=0,AJ19,0) | AL19: ==IF(AND(AI19>0,AJ19>AI19),AJ19-AI19,0) | AM19: ==IF(AI19=AJ19,AJ19,0) | AN19: ==IF(AJ19=0,AI19,0) | AO19: ==IF(AND(AJ19>0,AJ19<AI19),AI19-AJ19,0) | AP19: US-Accounts Receivable | AQ19: 168777 | AR19: 0 | AS19: 0
A20: fairlanefurniturerestorers3 | B20: ExistingCustomerEOM | C20: ExistingCustomerEOM | D20: 0 | E20: 0 | F20: -155 | G20: -46.5 | H20: 0 | I20: 0 | K20: 0 | L20: 0 | M20: 2 | N20: 2 | O20: unknown | P20: New | Q20: 0 | R20: 0 | S20: 155 | T20: 465 | U20: 0 | V20: 0 | W20: 0 | X20: 0 | Y20: 416 | Z20: 1065 | AA20: Monthly | AB20: Monthly | AC20: PhuPh | AD20: PhuPh | AE20: 0 | AF20: 0 | AG20: 11 | AH20: 6 | AI20: ==W20+ Y20+D20+H20 | AJ20: ==X20+Z20+E20+I20 | AK20: ==IF(AI20=0,AJ20,0) | AL20: ==IF(AND(AI20>0,AJ20>AI20),AJ20-AI20,0) | AM20: ==IF(AI20=AJ20,AJ20,0) | AN20: ==IF(AJ20=0,AI20,0) | AO20: ==IF(AND(AJ20>0,AJ20<AI20),AI20-AJ20,0) | AP20: US-Accounts Receivable | AQ20: 172556 | AR20: 0 | AS20: 0
A21: bieldentalcabinetsrebielcompanyinc | B21: ExistingCustomerEOM | C21: ExistingCustomerEOM | D21: 0 | E21: 0 | F21: 0 | G21: 0 | H21: -24.5 | I21: -11 | K21: -73.5 | L21: -99 | M21: 3 | N21: 4 | O21: unknown | P21: New | Q21: 0 | R21: 0 | S21: 155 | T21: 0 | U21: 0 | V21: 0 | W21: 0 | X21: 0 | Y21: 98 | Z21: 110 | AA21: Prepay | AB21: Prepay | AC21: ChWon | AD21: JaiPa | AE21: 0 | AF21: 0 | AG21: 2 | AH21: 2 | AI21: ==W21+ Y21+D21+H21 | AJ21: ==X21+Z21+E21+I21 | AK21: ==IF(AI21=0,AJ21,0) | AL21: ==IF(AND(AI21>0,AJ21>AI21),AJ21-AI21,0) | AM21: ==IF(AI21=AJ21,AJ21,0) | AN21: ==IF(AJ21=0,AI21,0) | AO21: ==IF(AND(AJ21>0,AJ21<AI21),AI21-AJ21,0) | AP21: US-Accounts Receivable | AQ21: 172829 | AR21: 0 | AS21: 0
A22: baldwinglass | B22: ExistingCustomerEOM | D22: 0 | E22: 0 | F22: 0 | G22: 0 | H22: 0 | I22: 0 | K22: 0 | L22: 0 | M22: 3 | N22: 0 | O22: New | Q22: 0 | R22: 0 | S22: 0 | T22: 0 | U22: 0 | V22: 0 | W22: 0 | X22: 0 | Y22: 49 | Z22: 0 | AA22: Monthly | AC22: ChWon | AE22: 0 | AF22: 0 | AG22: 1 | AH22: 0 | AI22: ==W22+ Y22+D22+H22 | AJ22: ==X22+Z22+E22+I22 | AK22: ==IF(AI22=0,AJ22,0) | AL22: ==IF(AND(AI22>0,AJ22>AI22),AJ22-AI22,0) | AM22: ==IF(AI22=AJ22,AJ22,0) | AN22: ==IF(AJ22=0,AI22,0) | AO22: ==IF(AND(AJ22>0,AJ22<AI22),AI22-AJ22,0) | AP22: US-Accounts Receivable | AQ22: 172574 | AR22: 0 | AS22: 0
A23: tcssllc3 | B23: ExistingCustomerEOM | C23: ExistingCustomerEOM | D23: 0 | E23: 0 | F23: 0 | G23: 0 | H23: 0 | I23: 0 | K23: 0 | L23: 0 | M23: 5 | N23: 5 | O23: unknown | P23: New | Q23: 0 | R23: 0 | S23: 77.5 | T23: 0 | U23: 0 | V23: 0 | W23: 0 | X23: 0 | Y23: 389 | Z23: 407 | AA23: Monthly | AB23: Monthly | AC23: PhuPh | AD23: PhuPh | AE23: 0 | AF23: 0 | AG23: 9 | AH23: 10 | AI23: ==W23+ Y23+D23+H23 | AJ23: ==X23+Z23+E23+I23 | AK23: ==IF(AI23=0,AJ23,0) | AL23: ==IF(AND(AI23>0,AJ23>AI23),AJ23-AI23,0) | AM23: ==IF(AI23=AJ23,AJ23,0) | AN23: ==IF(AJ23=0,AI23,0) | AO23: ==IF(AND(AJ23>0,AJ23<AI23),AI23-AJ23,0) | AP23: US-Accounts Receivable | AQ23: 174386 | AR23: 0 | AS23: 0
A24: boxgangmanufacturing2 | B24: ExistingCustomerEOM | C24: ExistingCustomerEOM | D24: 0 | E24: 0 | F24: 0 | G24: 0 | H24: -58 | I24: 0 | K24: -174 | L24: 0 | M24: 5 | N24: 4 | O24: New | P24: New | Q24: 0 | R24: 0 | S24: 0 | T24: 0 | U24: 0 | V24: 0 | W24: 0 | X24: 0 | Y24: 232 | Z24: 208 | AA24: Prepay | AB24: Monthly | AC24: MikPa | AD24: MikPa | AE24: 0 | AF24: 0 | AG24: 4 | AH24: 4 | AI24: ==W24+ Y24+D24+H24 | AJ24: ==X24+Z24+E24+I24 | AK24: ==IF(AI24=0,AJ24,0) | AL24: ==IF(AND(AI24>0,AJ24>AI24),AJ24-AI24,0) | AM24: ==IF(AI24=AJ24,AJ24,0) | AN24: ==IF(AJ24=0,AI24,0) | AO24: ==IF(AND(AJ24>0,AJ24<AI24),AI24-AJ24,0) | AP24: US-Accounts Receivable | AQ24: 164857 | AR24: 0 | AS24: 0
A25: advprosecurity | B25: ExistingCustomerEOM | C25: ExistingCustomerEOM | D25: 0 | E25: 0 | F25: 0 | G25: 0 | H25: -35 | I25: -30 | K25: -308 | L25: -264 | M25: 3 | N25: 3 | O25: New | P25: New | Q25: 0 | R25: 0 | S25: 0 | T25: 0 | U25: 0 | V25: 0 | W25: 0 | X25: 0 | Y25: 343 | Z25: 294 | AA25: Prepay | AB25: Prepay | AC25: SukSa | AD25: ShaLi | AE25: 0 | AF25: 0 | AG25: 1 | AH25: 6 | AI25: ==W25+ Y25+D25+H25 | AJ25: ==X25+Z25+E25+I25 | AK25: ==IF(AI25=0,AJ25,0) | AL25: ==IF(AND(AI25>0,AJ25>AI25),AJ25-AI25,0) | AM25: ==IF(AI25=AJ25,AJ25,0) | AN25: ==IF(AJ25=0,AI25,0) | AO25: ==IF(AND(AJ25>0,AJ25<AI25),AI25-AJ25,0) | AP25: US-Accounts Receivable | AQ25: 164832 | AR25: 0 | AS25: 0
A26: arianhomecarecorporation | B26: ExistingCustomerEOM | D26: 0 | E26: 0 | F26: 0 | G26: 0 | H26: 0 | I26: 0 | K26: 0 | L26: 0 | M26: 4 | N26: 0 | O26: New | Q26: 0 | R26: 0 | S26: 0 | T26: 0 | U26: 0 | V26: 0 | W26: 0 | X26: 0 | Y26: 184 | Z26: 0 | AA26: Monthly | AC26: PhuPh | AE26: 0 | AF26: 0 | AG26: 4 | AH26: 0 | AI26: ==W26+ Y26+D26+H26 | AJ26: ==X26+Z26+E26+I26 | AK26: ==IF(AI26=0,AJ26,0) | AL26: ==IF(AND(AI26>0,AJ26>AI26),AJ26-AI26,0) | AM26: ==IF(AI26=AJ26,AJ26,0) | AN26: ==IF(AJ26=0,AI26,0) | AO26: ==IF(AND(AJ26>0,AJ26<AI26),AI26-AJ26,0) | AP26: CAN-Accounts Receivable | AQ26: 166319 | AR26: 0 | AS26: 0
A27: agpharma | B27: ExistingCustomerEOM | C27: ExistingCustomerEOM | D27: 0 | E27: 0 | F27: -36.25 | G27: 0 | H27: 0 | I27: 0 | K27: 0 | L27: 0 | M27: 3 | N27: 3 | O27: unknown | P27: New | Q27: 0 | R27: 0 | S27: 725 | T27: 0 | U27: 0 | V27: 0 | W27: 0 | X27: 0 | Y27: 421 | Z27: 479 | AA27: Monthly | AB27: Monthly | AC27: PhuPh | AD27: PhuPh | AE27: 0 | AF27: 0 | AG27: 10 | AH27: 11 | AI27: ==W27+ Y27+D27+H27 | AJ27: ==X27+Z27+E27+I27 | AK27: ==IF(AI27=0,AJ27,0) | AL27: ==IF(AND(AI27>0,AJ27>AI27),AJ27-AI27,0) | AM27: ==IF(AI27=AJ27,AJ27,0) | AN27: ==IF(AJ27=0,AI27,0) | AO27: ==IF(AND(AJ27>0,AJ27<AI27),AI27-AJ27,0) | AP27: US-Accounts Receivable | AQ27: 166164 | AR27: 0 | AS27: 0
A28: bptest | B28: ExistingCustomerEOM | D28: 0 | E28: 0 | F28: 0 | G28: 0 | H28: -8 | I28: 0 | K28: -72 | L28: 0 | M28: 2 | N28: 0 | O28: New | Q28: 0 | R28: 0 | S28: 0 | T28: 0 | U28: 0 | V28: 0 | W28: 0 | X28: 0 | Y28: 80 | Z28: 0 | AA28: Prepay | AC28: RafSy | AE28: 0 | AF28: 0 | AG28: 2 | AH28: 0 | AI28: ==W28+ Y28+D28+H28 | AJ28: ==X28+Z28+E28+I28 | AK28: ==IF(AI28=0,AJ28,0) | AL28: ==IF(AND(AI28>0,AJ28>AI28),AJ28-AI28,0) | AM28: ==IF(AI28=AJ28,AJ28,0) | AN28: ==IF(AJ28=0,AI28,0) | AO28: ==IF(AND(AJ28>0,AJ28<AI28),AI28-AJ28,0) | AP28: US-Accounts Receivable | AQ28: 165958 | AR28: 0 | AS28: 0
A29: permitsbymirza2 | B29: ExistingCustomerEOM | D29: 0 | E29: 0 | F29: 0 | G29: 0 | H29: 0 | I29: 0 | K29: 0 | L29: 0 | M29: 3 | N29: 0 | O29: New | Q29: 0 | R29: 0 | S29: 0 | T29: 0 | U29: 0 | V29: 0 | W29: 0 | X29: 0 | Y29: 89 | Z29: 0 | AA29: Monthly | AC29: RafSy | AE29: 0 | AF29: 0 | AG29: 2 | AH29: 0 | AI29: ==W29+ Y29+D29+H29 | AJ29: ==X29+Z29+E29+I29 | AK29: ==IF(AI29=0,AJ29,0) | AL29: ==IF(AND(AI29>0,AJ29>AI29),AJ29-AI29,0) | AM29: ==IF(AI29=AJ29,AJ29,0) | AN29: ==IF(AJ29=0,AI29,0) | AO29: ==IF(AND(AJ29>0,AJ29<AI29),AI29-AJ29,0) | AP29: US-Accounts Receivable | AQ29: 167628 | AR29: 0 | AS29: 0
A30: trendysurfaces | B30: ExistingCustomerEOM | C30: ExistingCustomerEOM | D30: 0 | E30: 0 | F30: 0 | G30: 0 | H30: 0 | I30: 0 | K30: 0 | L30: 0 | M30: 1 | N30: 1 | O30: New | P30: New | Q30: 0 | R30: 0 | S30: 0 | T30: 0 | U30: 0 | V30: 0 | W30: 0 | X30: 0 | Y30: 84 | Z30: 56 | AA30: Monthly | AB30: Monthly | AC30: RafSy | AD30: RafSy | AE30: 0 | AF30: 0 | AG30: 3 | AH30: 2 | AI30: ==W30+ Y30+D30+H30 | AJ30: ==X30+Z30+E30+I30 | AK30: ==IF(AI30=0,AJ30,0) | AL30: ==IF(AND(AI30>0,AJ30>AI30),AJ30-AI30,0) | AM30: ==IF(AI30=AJ30,AJ30,0) | AN30: ==IF(AJ30=0,AI30,0) | AO30: ==IF(AND(AJ30>0,AJ30<AI30),AI30-AJ30,0) | AP30: US-Accounts Receivable | AQ30: 159898 | AR30: 0 | AS30: 0
A31: tipsyponypartybarllc | B31: ExistingCustomerEOM | C31: ExistingCustomerEOM | D31: 0 | E31: 0 | F31: 0 | G31: 0 | H31: -11 | I31: -11 | K31: -74 | L31: -74 | M31: 6 | N31: 6 | O31: New | P31: New | Q31: 0 | R31: 0 | S31: 0 | T31: 0 | U31: 0 | V31: 0 | W31: 0 | X31: 0 | Y31: 85 | Z31: 85 | AA31: Prepay | AB31: Prepay | AC31: SukSa | AD31: SukSa | AE31: 0 | AF31: 0 | AG31: 1 | AH31: 1 | AI31: ==W31+ Y31+D31+H31 | AJ31: ==X31+Z31+E31+I31 | AK31: ==IF(AI31=0,AJ31,0) | AL31: ==IF(AND(AI31>0,AJ31>AI31),AJ31-AI31,0) | AM31: ==IF(AI31=AJ31,AJ31,0) | AN31: ==IF(AJ31=0,AI31,0) | AO31: ==IF(AND(AJ31>0,AJ31<AI31),AI31-AJ31,0) | AP31: US-Accounts Receivable | AQ31: 161000 | AR31: 0 | AS31: 0
A32: dinosaw2 | B32: ExistingCustomerEOM | C32: ExistingCustomerEOM | D32: 0 | E32: 0 | F32: 0 | G32: 0 | H32: 0 | I32: 0 | K32: 0 | L32: 0 | M32: 4 | N32: 4 | O32: New | P32: New | Q32: 0 | R32: 0 | S32: 0 | T32: 0 | U32: 0 | V32: 0 | W32: 0 | X32: 0 | Y32: 61 | Z32: 61 | AA32: Monthly | AB32: Monthly | AC32: RafSy | AD32: RafSy | AE32: 0 | AF32: 0 | AG32: 1 | AH32: 1 | AI32: ==W32+ Y32+D32+H32 | AJ32: ==X32+Z32+E32+I32 | AK32: ==IF(AI32=0,AJ32,0) | AL32: ==IF(AND(AI32>0,AJ32>AI32),AJ32-AI32,0) | AM32: ==IF(AI32=AJ32,AJ32,0) | AN32: ==IF(AJ32=0,AI32,0) | AO32: ==IF(AND(AJ32>0,AJ32<AI32),AI32-AJ32,0) | AP32: US-Accounts Receivable | AQ32: 160992 | AR32: 0 | AS32: 0
A33: nextsteporlando4 | B33: ExistingCustomerEOM | C33: ExistingCustomerEOM | D33: 0 | E33: 0 | F33: 0 | G33: 0 | H33: 0 | I33: 0 | K33: 0 | L33: 0 | M33: 3 | N33: 3 | O33: New | P33: New | Q33: 0 | R33: 0 | S33: 0 | T33: 0 | U33: 0 | V33: 0 | W33: 0 | X33: 0 | Y33: 52 | Z33: 52 | AA33: Monthly | AB33: Monthly | AC33: SukSa | AD33: SukSa | AE33: 0 | AF33: 0 | AG33: 1 | AH33: 1 | AI33: ==W33+ Y33+D33+H33 | AJ33: ==X33+Z33+E33+I33 | AK33: ==IF(AI33=0,AJ33,0) | AL33: ==IF(AND(AI33>0,AJ33>AI33),AJ33-AI33,0) | AM33: ==IF(AI33=AJ33,AJ33,0) | AN33: ==IF(AJ33=0,AI33,0) | AO33: ==IF(AND(AJ33>0,AJ33<AI33),AI33-AJ33,0) | AP33: US-Accounts Receivable | AQ33: 162151 | AR33: 0 | AS33: 0
A34: turnservllc2 | B34: ExistingCustomerEOM | C34: ExistingCustomerEOM | D34: 0 | E34: 0 | F34: -725 | G34: 0 | H34: 0 | I34: 0 | K34: 0 | L34: 0 | M34: 6 | N34: 6 | O34: unknown | P34: New | Q34: 0 | R34: 0 | S34: 3625 | T34: 0 | U34: 0 | V34: 0 | W34: 0 | X34: 0 | Y34: 1628 | Z34: 1518 | AA34: Monthly | AB34: Monthly | AC34: MikPa | AD34: MikPa | AE34: 0 | AF34: 0 | AG34: 35 | AH34: 23 | AI34: ==W34+ Y34+D34+H34 | AJ34: ==X34+Z34+E34+I34 | AK34: ==IF(AI34=0,AJ34,0) | AL34: ==IF(AND(AI34>0,AJ34>AI34),AJ34-AI34,0) | AM34: ==IF(AI34=AJ34,AJ34,0) | AN34: ==IF(AJ34=0,AI34,0) | AO34: ==IF(AND(AJ34>0,AJ34<AI34),AI34-AJ34,0) | AP34: US-Accounts Receivable | AQ34: 163490 | AR34: 0 | AS34: 0
A35: blackhausflooring | B35: ExistingCustChurn | D35: 0 | E35: 0 | F35: 0 | G35: 0 | H35: -9 | I35: 0 | K35: -64 | L35: 0 | M35: 5 | N35: 0 | O35: unknown | Q35: 0 | R35: 0 | S35: 0 | T35: 0 | U35: 0 | V35: 0 | W35: 0 | X35: 0 | Y35: 73 | Z35: 0 | AA35: Prepay | AC35: JaiPa | AE35: 0 | AF35: 0 | AG35: 1 | AH35: 0 | AI35: ==W35+ Y35+D35+H35 | AJ35: ==X35+Z35+E35+I35 | AK35: ==IF(AI35=0,AJ35,0) | AL35: ==IF(AND(AI35>0,AJ35>AI35),AJ35-AI35,0) | AM35: ==IF(AI35=AJ35,AJ35,0) | AN35: ==IF(AJ35=0,AI35,0) | AO35: ==IF(AND(AJ35>0,AJ35<AI35),AI35-AJ35,0) | AP35: US-Accounts Receivable | AQ35: 163512 | AR35: 0 | AS35: 0
A36: cascadestainlesssolutionsllc | B36: ExistingCustomerEOM | D36: 0 | E36: 0 | F36: 0 | G36: 0 | H36: 0 | I36: 0 | K36: 0 | L36: 0 | M36: 5 | N36: 0 | O36: New | Q36: 0 | R36: 0 | S36: 0 | T36: 0 | U36: 0 | V36: 0 | W36: 0 | X36: 0 | Y36: 122 | Z36: 0 | AA36: Monthly | AC36: SukSa | AE36: 0 | AF36: 0 | AG36: 2 | AH36: 0 | AI36: ==W36+ Y36+D36+H36 | AJ36: ==X36+Z36+E36+I36 | AK36: ==IF(AI36=0,AJ36,0) | AL36: ==IF(AND(AI36>0,AJ36>AI36),AJ36-AI36,0) | AM36: ==IF(AI36=AJ36,AJ36,0) | AN36: ==IF(AJ36=0,AI36,0) | AO36: ==IF(AND(AJ36>0,AJ36<AI36),AI36-AJ36,0) | AP36: US-Accounts Receivable | AQ36: 155176 | AR36: 0 | AS36: 0
A37: colonyroofing | B37: ExistingCustomerEOM | C37: ExistingCustomerEOM | D37: 0 | E37: 0 | F37: 0 | G37: 0 | H37: 0 | I37: 0 | K37: 0 | L37: 0 | M37: 3 | N37: 3 | O37: New | P37: New | Q37: 0 | R37: 0 | S37: 0 | T37: 0 | U37: 0 | V37: 0 | W37: 0 | X37: 0 | Y37: 322 | Z37: 322 | AA37: Monthly | AB37: Monthly | AC37: MikPa | AD37: MikPa | AE37: 0 | AF37: 0 | AG37: 7 | AH37: 7 | AI37: ==W37+ Y37+D37+H37 | AJ37: ==X37+Z37+E37+I37 | AK37: ==IF(AI37=0,AJ37,0) | AL37: ==IF(AND(AI37>0,AJ37>AI37),AJ37-AI37,0) | AM37: ==IF(AI37=AJ37,AJ37,0) | AN37: ==IF(AJ37=0,AI37,0) | AO37: ==IF(AND(AJ37>0,AJ37<AI37),AI37-AJ37,0) | AP37: US-Accounts Receivable | AQ37: 156444 | AR37: 0 | AS37: 0
A38: pioneersourcingsolutionsllc | B38: ExistingCustomerEOM | C38: ExistingCustomerEOM | D38: 0 | E38: 0 | F38: 0 | G38: 0 | H38: -3 | I38: -3 | K38: -25 | L38: -25 | M38: 1 | N38: 1 | O38: New | P38: New | Q38: 0 | R38: 0 | S38: 0 | T38: 0 | U38: 0 | V38: 0 | W38: 0 | X38: 0 | Y38: 28 | Z38: 28 | AA38: Prepay | AB38: Prepay | AC38: RafSy | AD38: RafSy | AE38: 0 | AF38: 0 | AG38: 1 | AH38: 1 | AI38: ==W38+ Y38+D38+H38 | AJ38: ==X38+Z38+E38+I38 | AK38: ==IF(AI38=0,AJ38,0) | AL38: ==IF(AND(AI38>0,AJ38>AI38),AJ38-AI38,0) | AM38: ==IF(AI38=AJ38,AJ38,0) | AN38: ==IF(AJ38=0,AI38,0) | AO38: ==IF(AND(AJ38>0,AJ38<AI38),AI38-AJ38,0) | AP38: US-Accounts Receivable | AQ38: 158737 | AR38: 0 | AS38: 0
A39: jdshouseoftrophies | B39: ExistingCustomerEOM | C39: ExistingCustomerEOM | D39: 0 | E39: 0 | F39: 0 | G39: -155 | H39: 0 | I39: 0 | K39: 0 | L39: 0 | M39: 3 | N39: 3 | O39: New | P39: unknown | Q39: 0 | R39: 0 | S39: 0 | T39: 155 | U39: 0 | V39: 0 | W39: 0 | X39: 0 | Y39: 196 | Z39: 196 | AA39: Monthly | AB39: Monthly | AC39: PhuPh | AD39: PhuPh | AE39: 0 | AF39: 0 | AG39: 4 | AH39: 4 | AI39: ==W39+ Y39+D39+H39 | AJ39: ==X39+Z39+E39+I39 | AK39: ==IF(AI39=0,AJ39,0) | AL39: ==IF(AND(AI39>0,AJ39>AI39),AJ39-AI39,0) | AM39: ==IF(AI39=AJ39,AJ39,0) | AN39: ==IF(AJ39=0,AI39,0) | AO39: ==IF(AND(AJ39>0,AJ39<AI39),AI39-AJ39,0) | AP39: US-Accounts Receivable | AQ39: 158724 | AR39: 0 | AS39: 0
A40: finelinecreativeartscenter | B40: ExistingCustomerEOM | C40: ExistingCustomerEOM | D40: 0 | E40: 0 | F40: 0 | G40: 0 | H40: -5.6 | I40: -5.6 | K40: -50.4 | L40: -50.4 | M40: 1 | N40: 1 | O40: New | P40: New | Q40: 0 | R40: 0 | S40: 0 | T40: 0 | U40: 0 | V40: 0 | W40: 0 | X40: 0 | Y40: 56 | Z40: 56 | AA40: Prepay | AB40: Prepay | AC40: RafSy | AD40: RafSy | AE40: 0 | AF40: 0 | AG40: 2 | AH40: 2 | AI40: ==W40+ Y40+D40+H40 | AJ40: ==X40+Z40+E40+I40 | AK40: ==IF(AI40=0,AJ40,0) | AL40: ==IF(AND(AI40>0,AJ40>AI40),AJ40-AI40,0) | AM40: ==IF(AI40=AJ40,AJ40,0) | AN40: ==IF(AJ40=0,AI40,0) | AO40: ==IF(AND(AJ40>0,AJ40<AI40),AI40-AJ40,0) | AP40: US-Accounts Receivable | AQ40: 158733 | AR40: 0 | AS40: 0
...

Sheet NRR By Customer
A1: Start of Month | B1: Start of Month | C1: Start of Month | D1: Cancellation | E1: Cancellation | F1: Cancellation | G1: Downgrades | H1: Downgrades | I1: Downgrades | J1: Expansion | K1: Expansion | L1: Expansion | M1: New ARR | N1: New ARR | O1: New ARR | P1: Other | Q1: Other | R1: Other | S1: OtherChurn | T1: OtherChurn | U1: OtherChurn | V1: Count | W1: Count | X1: Count
A2: US-Accounts Receivable | B2: CAN-Accounts Receivable | C2: UK-Accounts Receivable | D2: US-Accounts Receivable | E2: CAN-Accounts Receivable | F2: UK-Accounts Receivable | G2: US-Accounts Receivable | H2: CAN-Accounts Receivable | I2: UK-Accounts Receivable | J2: US-Accounts Receivable | K2: CAN-Accounts Receivable | L2: UK-Accounts Receivable | M2: US-Accounts Receivable | N2: CAN-Accounts Receivable | O2: UK-Accounts Receivable | P2: US-Accounts Receivable | Q2: CAN-Accounts Receivable | R2: UK-Accounts Receivable | S2: US-Accounts Receivable | T2: CAN-Accounts Receivable | U2: UK-Accounts Receivable | V2: US-Accounts Receivable | W2: CAN-Accounts Receivable | X2: UK-Accounts Receivable
A3: ==SUMIFS(Customers!AI:AI,Customers!AP:AP,A$2) | B3: ==SUMIFS(Customers!AI:AI,Customers!AP:AP,B$2) | C3: ==SUMIFS(Customers!AI:AI,Customers!AP:AP,C$2) | D3: ==SUMIFS(Customers!AN:AN,Customers!AP:AP,D$2)-S3 | E3: ==SUMIFS(Customers!AN:AN,Customers!AP:AP,E$2)-T3 | F3: ==SUMIFS(Customers!AN:AN,Customers!AP:AP,F$2)-U3 | G3: ==SUMIFS(Customers!AO:AO,Customers!AP:AP,G$2) | H3: ==SUMIFS(Customers!AO:AO,Customers!AP:AP,H$2) | I3: ==SUMIFS(Customers!AO:AO,Customers!AP:AP,I$2) | J3: ==SUMIFS(Customers!AL:AL,Customers!AP:AP,J$2) | K3: ==SUMIFS(Customers!AL:AL,Customers!AP:AP,K$2) | L3: ==SUMIFS(Customers!AL:AL,Customers!AP:AP,L$2) | M3: ==SUMIFS(Customers!AK:AK,Customers!AP:AP,M$2)-P3 | N3: ==SUMIFS(Customers!AK:AK,Customers!AP:AP,N$2)-Q3 | O3: ==SUMIFS(Customers!AK:AK,Customers!AP:AP,O$2)-R3 | P3: ==SUMIFS(Customers!AS:AS,Customers!AP:AP,P$2) | Q3: ==SUMIFS(Customers!AS:AS,Customers!AP:AP,Q$2) | R3: ==SUMIFS(Customers!AS:AS,Customers!AP:AP,R$2) | S3: ==SUMIFS(Customers!AR:AR,Customers!AP:AP,P$2) | T3: ==SUMIFS(Customers!AR:AR,Customers!AP:AP,Q$2) | U3: ==SUMIFS(Customers!AR:AR,Customers!AP:AP,R$2) | V3: ==COUNTIFS(Customers!Z:Z, ">0",Customers!AP:AP,V$2) | W3: ==COUNTIFS(Customers!Z:Z, ">0",Customers!AP:AP,W$2) | X3: ==COUNTIFS(Customers!Z:Z, ">0",Customers!AP:AP,X$2)

Sheet Accounts
A1: CompanyAccount | B1: CustomerGroupingPeriod1 | C1: CustomerGroupingPeriod2 | D1: DiscountOtherSaaSPeriod1 | E1: DiscountOtherSaaSPeriod2 | F1: DiscountOtherPSPeriod1 | G1: DiscountOtherPSPeriod2 | H1: DiscountPrepayPortionPeriod1 | I1: DiscountPrepayPortionPeriod2 | J1: InvoiceGrouping | K1: LiabilityPortionPeriod1 | L1: LiabilityPortionPeriod2 | M1: PackPaidCountPeriod1 | N1: PackPaidCountPeriod2 | O1: PlatformTogglePeriod1 | P1: PlatformTogglePeriod2 | Q1: PSExpenseAmountPeriod1 | R1: PSExpenseAmountPeriod2 | S1: PSIncomeAmountPeriod1 | T1: PSIncomeAmountPeriod2 | U1: SaasExpensePeriod1 | V1: SaasExpensePeriod2 | W1: SaaSIncomeAmountClassicPeriod1 | X1: SaaSIncomeAmountClassicPeriod2 | Y1: SaaSIncomeAmountNewPeriod1 | Z1: SaaSIncomeAmountNewPeriod2 | AA1: SaaSPayTypePeriod1 | AB1: SaaSPayTypePeriod2 | AC1: SalesRepSaaSPeriod1 | AD1: SalesRepSaaSPeriod2 | AE1: UncategorizedPortionPeriod1 | AF1: UncategorizedPortionPeriod2 | AG1: UserPaidCountPeriod1 | AH1: UserPaidCountPeriod2 | AI1: SaaSNetPeriod1 | AJ1: SaaSNetPeriod2 | AK1: SaaSExpandNew | AL1: SaaSExpansionUp | AM1: SaaSNoChange | AN1: SaaSContractionCancel | AO1: SaaSContractionDown | AP1: Currency | AQ1: CustomerRecordID | AR1: PrepPayExpiryPeriod1 | AS1: PrepPayExpiryPeriod2
A2: duralinesystemsinc2 | B2: ExistingCustomerEOM | C2: ExistingCustomerEOM | D2: 0 | E2: 0 | F2: -263.5 | G2: -108.5 | H2: 0 | I2: 0 | K2: 0 | L2: 0 | M2: 5 | N2: 5 | O2: New | P2: New | Q2: 0 | R2: 0 | S2: 2635 | T2: 1085 | U2: 0 | V2: 0 | W2: 0 | X2: 0 | Y2: 1090 | Z2: 1099 | AA2: Monthly | AB2: Monthly | AC2: HaPat | AD2: HaPat | AE2: 0 | AF2: 0 | AG2: 15 | AH2: 15 | AI2: ==W2+ Y2+D2+H2 | AJ2: ==X2+Z2+E2+I2 | AK2: ==IF(AI2=0,AJ2,0) | AL2: ==IF(AND(AI2>0,AJ2>AI2),AJ2-AI2,0) | AM2: ==IF(AI2=AJ2,AJ2,0) | AN2: ==IF(AJ2=0,AI2,0) | AO2: ==IF(AND(AJ2>0,AJ2<AI2),AI2-AJ2,0) | AP2: US-Accounts Receivable | AQ2: 156531 | AR2: 0 | AS2: 0
A3: foreigntaxcpa | B3: ExistingCustomerEOM | C3: ExistingCustomerEOM | D3: 0 | E3: 0 | F3: -46.5 | G3: 0 | H3: -140 | I3: 0 | K3: -420 | L3: 0 | M3: 3 | N3: 3 | O3: unknown | P3: unknown | Q3: 0 | R3: -77.5 | S3: 465 | T3: 77.5 | U3: 0 | V3: 0 | W3: 0 | X3: 0 | Y3: 885 | Z3: 956 | AA3: Prepay | AB3: Monthly | AC3: PhuPh | AD3: PhuPh | AE3: 0 | AF3: 0 | AG3: 14 | AH3: 16 | AI3: ==W3+ Y3+D3+H3 | AJ3: ==X3+Z3+E3+I3 | AK3: ==IF(AI3=0,AJ3,0) | AL3: ==IF(AND(AI3>0,AJ3>AI3),AJ3-AI3,0) | AM3: ==IF(AI3=AJ3,AJ3,0) | AN3: ==IF(AJ3=0,AI3,0) | AO3: ==IF(AND(AJ3>0,AJ3<AI3),AI3-AJ3,0) | AP3: US-Accounts Receivable | AQ3: 175034 | AR3: 0 | AS3: 0
A4: alerthomewatch | B4: ExistingCustomerEOM | C4: ExistingCustomerEOM | D4: 0 | E4: 0 | F4: 0 | G4: 0 | H4: 0 | I4: 0 | K4: 0 | L4: 0 | M4: 1 | N4: 1 | O4: New | P4: New | Q4: 0 | R4: 0 | S4: 0 | T4: 0 | U4: 0 | V4: 0 | W4: 0 | X4: 0 | Y4: 84 | Z4: 84 | AA4: Monthly | AB4: Monthly | AC4: PhuPh | AD4: PhuPh | AE4: 0 | AF4: 0 | AG4: 3 | AH4: 3 | AI4: ==W4+ Y4+D4+H4 | AJ4: ==X4+Z4+E4+I4 | AK4: ==IF(AI4=0,AJ4,0) | AL4: ==IF(AND(AI4>0,AJ4>AI4),AJ4-AI4,0) | AM4: ==IF(AI4=AJ4,AJ4,0) | AN4: ==IF(AJ4=0,AI4,0) | AO4: ==IF(AND(AJ4>0,AJ4<AI4),AI4-AJ4,0) | AP4: US-Accounts Receivable | AQ4: 96657 | AR4: 0 | AS4: 0
A5: CarlsonConcierge | B5: ExistingCustomerEOM | C5: ExistingCustomerEOM | D5: -11.2 | E5: -11.2 | F5: 0 | G5: 0 | H5: 0 | I5: 0 | K5: 0 | L5: 0 | M5: 1 | N5: 1 | O5: New | P5: New | Q5: 0 | R5: 0 | S5: 0 | T5: 0 | U5: 0 | V5: 0 | W5: 0 | X5: 0 | Y5: 56 | Z5: 56 | AA5: Monthly | AB5: Monthly | AC5: PhuPh | AD5: PhuPh | AE5: 0 | AF5: 0 | AG5: 2 | AH5: 2 | AI5: ==W5+ Y5+D5+H5 | AJ5: ==X5+Z5+E5+I5 | AK5: ==IF(AI5=0,AJ5,0) | AL5: ==IF(AND(AI5>0,AJ5>AI5),AJ5-AI5,0) | AM5: ==IF(AI5=AJ5,AJ5,0) | AN5: ==IF(AJ5=0,AI5,0) | AO5: ==IF(AND(AJ5>0,AJ5<AI5),AI5-AJ5,0) | AP5: US-Accounts Receivable | AQ5: 86456 | AR5: 0 | AS5: 0
A6: hwmadison | B6: ExistingCustomerEOM | C6: ExistingCustomerEOM | D6: 0 | E6: 0 | F6: 0 | G6: 0 | H6: 0 | I6: 0 | K6: 0 | L6: 0 | M6: 1 | N6: 1 | O6: New | P6: New | Q6: 0 | R6: 0 | S6: 0 | T6: 0 | U6: 0 | V6: 0 | W6: 0 | X6: 0 | Y6: 56 | Z6: 56 | AA6: Monthly | AB6: Monthly | AC6: PhuPh | AD6: PhuPh | AE6: 0 | AF6: 0 | AG6: 2 | AH6: 2 | AI6: ==W6+ Y6+D6+H6 | AJ6: ==X6+Z6+E6+I6 | AK6: ==IF(AI6=0,AJ6,0) | AL6: ==IF(AND(AI6>0,AJ6>AI6),AJ6-AI6,0) | AM6: ==IF(AI6=AJ6,AJ6,0) | AN6: ==IF(AJ6=0,AI6,0) | AO6: ==IF(AND(AJ6>0,AJ6<AI6),AI6-AJ6,0) | AP6: US-Accounts Receivable | AQ6: 132775 | AR6: 0 | AS6: 0
A7: leddy | B7: ExistingCustomerEOM | C7: ExistingCustomerEOM | D7: 0 | E7: 0 | F7: 0 | G7: 0 | H7: 0 | I7: 0 | K7: 0 | L7: 0 | M7: 1 | N7: 1 | O7: New | P7: New | Q7: 0 | R7: 0 | S7: 0 | T7: 0 | U7: 0 | V7: 0 | W7: 0 | X7: 0 | Y7: 28 | Z7: 28 | AA7: Monthly | AB7: Monthly | AC7: PhuPh | AD7: PhuPh | AE7: 0 | AF7: 0 | AG7: 1 | AH7: 1 | AI7: ==W7+ Y7+D7+H7 | AJ7: ==X7+Z7+E7+I7 | AK7: ==IF(AI7=0,AJ7,0) | AL7: ==IF(AND(AI7>0,AJ7>AI7),AJ7-AI7,0) | AM7: ==IF(AI7=AJ7,AJ7,0) | AN7: ==IF(AJ7=0,AI7,0) | AO7: ==IF(AND(AJ7>0,AJ7<AI7),AI7-AJ7,0) | AP7: US-Accounts Receivable | AQ7: 148689 | AR7: 0 | AS7: 0
A8: beyonddetailedsolutions | B8: ExistingCustomerEOM | C8: ExistingCustomerEOM | D8: 0 | E8: 0 | F8: 0 | G8: 0 | H8: -3 | I8: -3 | K8: -25 | L8: -25 | M8: 1 | N8: 1 | O8: New | P8: New | Q8: 0 | R8: 0 | S8: 0 | T8: 0 | U8: 0 | V8: 0 | W8: 0 | X8: 0 | Y8: 28 | Z8: 28 | AA8: Prepay | AB8: Prepay | AC8: PhuPh | AD8: PhuPh | AE8: 0 | AF8: 0 | AG8: 1 | AH8: 1 | AI8: ==W8+ Y8+D8+H8 | AJ8: ==X8+Z8+E8+I8 | AK8: ==IF(AI8=0,AJ8,0) | AL8: ==IF(AND(AI8>0,AJ8>AI8),AJ8-AI8,0) | AM8: ==IF(AI8=AJ8,AJ8,0) | AN8: ==IF(AJ8=0,AI8,0) | AO8: ==IF(AND(AJ8>0,AJ8<AI8),AI8-AJ8,0) | AP8: US-Accounts Receivable | AQ8: 150052 | AR8: 0 | AS8: 0
A9: guardianangel | B9: ExistingCustomerEOM | C9: ExistingCustomerEOM | D9: 0 | E9: 0 | F9: 0 | G9: 0 | H9: 0 | I9: 0 | K9: 0 | L9: 0 | M9: 0 | N9: 0 | O9: unknown | P9: unknown | Q9: 0 | R9: 0 | S9: 0 | T9: 0 | U9: 0 | V9: 0 | W9: 0 | X9: 0 | Y9: 0 | Z9: 0 | AE9: 0 | AF9: 0 | AG9: 0 | AH9: 0 | AI9: ==W9+ Y9+D9+H9 | AJ9: ==X9+Z9+E9+I9 | AK9: ==IF(AI9=0,AJ9,0) | AL9: ==IF(AND(AI9>0,AJ9>AI9),AJ9-AI9,0) | AM9: ==IF(AI9=AJ9,AJ9,0) | AN9: ==IF(AJ9=0,AI9,0) | AO9: ==IF(AND(AJ9>0,AJ9<AI9),AI9-AJ9,0) | AP9: US-Accounts Receivable | AQ9: 150132 | AR9: 0 | AS9: 0
A10: alliedhomewatch2 | B10: ExistingCustomerEOM | D10: 0 | E10: 0 | F10: 0 | G10: 0 | H10: 0 | I10: 0 | K10: 0 | L10: 0 | M10: 1 | N10: 0 | O10: New | Q10: 0 | R10: 0 | S10: 0 | T10: 0 | U10: 0 | V10: 0 | W10: 0 | X10: 0 | Y10: 28 | Z10: 0 | AA10: Monthly | AC10: PhuPh | AE10: 0 | AF10: 0 | AG10: 1 | AH10: 0 | AI10: ==W10+ Y10+D10+H10 | AJ10: ==X10+Z10+E10+I10 | AK10: ==IF(AI10=0,AJ10,0) | AL10: ==IF(AND(AI10>0,AJ10>AI10),AJ10-AI10,0) | AM10: ==IF(AI10=AJ10,AJ10,0) | AN10: ==IF(AJ10=0,AI10,0) | AO10: ==IF(AND(AJ10>0,AJ10<AI10),AI10-AJ10,0) | AP10: US-Accounts Receivable | AQ10: 152940 | AR10: 0 | AS10: 0
A11: casanapleshomewatch | B11: ExistingCustomerEOM | C11: ExistingCustomerEOM | D11: 0 | E11: 0 | F11: 0 | G11: 0 | H11: 0 | I11: 0 | K11: 0 | L11: 0 | M11: 1 | N11: 1 | O11: New | P11: New | Q11: 0 | R11: 0 | S11: 0 | T11: 0 | U11: 0 | V11: 0 | W11: 0 | X11: 0 | Y11: 28 | Z11: 28 | AA11: Monthly | AB11: Monthly | AC11: PhuPh | AD11: PhuPh | AE11: 0 | AF11: 0 | AG11: 1 | AH11: 1 | AI11: ==W11+ Y11+D11+H11 | AJ11: ==X11+Z11+E11+I11 | AK11: ==IF(AI11=0,AJ11,0) | AL11: ==IF(AND(AI11>0,AJ11>AI11),AJ11-AI11,0) | AM11: ==IF(AI11=AJ11,AJ11,0) | AN11: ==IF(AJ11=0,AI11,0) | AO11: ==IF(AND(AJ11>0,AJ11<AI11),AI11-AJ11,0) | AP11: US-Accounts Receivable | AQ11: 159752 | AR11: 0 | AS11: 0
A12: rimrocksoftware | B12: TrialerCancelled | D12: 0 | E12: 0 | F12: 0 | G12: 0 | H12: 0 | I12: 0 | K12: 0 | L12: 0 | M12: 2 | N12: 0 | O12: New | Q12: 0 | R12: 0 | S12: 0 | T12: 0 | U12: 0 | V12: 0 | W12: 0 | X12: 0 | Y12: 40 | Z12: 0 | AA12: Monthly | AC12: PhuPh | AE12: 0 | AF12: 0 | AG12: 1 | AH12: 0 | AI12: ==W12+ Y12+D12+H12 | AJ12: ==X12+Z12+E12+I12 | AK12: ==IF(AI12=0,AJ12,0) | AL12: ==IF(AND(AI12>0,AJ12>AI12),AJ12-AI12,0) | AM12: ==IF(AI12=AJ12,AJ12,0) | AN12: ==IF(AJ12=0,AI12,0) | AO12: ==IF(AND(AJ12>0,AJ12<AI12),AI12-AJ12,0) | AP12: US-Accounts Receivable | AQ12: 177742 | AR12: 0 | AS12: 0
A13: lightconsultancy | B13: ExistingCustomerEOM | C13: ExistingCustomerEOM | D13: -101 | E13: -101 | F13: 0 | G13: 0 | H13: 0 | I13: 0 | K13: 0 | L13: 0 | M13: 4 | N13: 4 | O13: New | P13: New | Q13: 0 | R13: 0 | S13: 0 | T13: 0 | U13: 0 | V13: 0 | W13: 0 | X13: 0 | Y13: 101 | Z13: 101 | AA13: Monthly | AB13: Monthly | AC13: PhuPh | AD13: PhuPh | AE13: 0 | AF13: 0 | AG13: 2 | AH13: 2 | AI13: ==W13+ Y13+D13+H13 | AJ13: ==X13+Z13+E13+I13 | AK13: ==IF(AI13=0,AJ13,0) | AL13: ==IF(AND(AI13>0,AJ13>AI13),AJ13-AI13,0) | AM13: ==IF(AI13=AJ13,AJ13,0) | AN13: ==IF(AJ13=0,AI13,0) | AO13: ==IF(AND(AJ13>0,AJ13<AI13),AI13-AJ13,0) | AP13: US-Accounts Receivable | AQ13: 173877 | AR13: 0 | AS13: 0
A14: upfrontservices | B14: NewCustomerEOM | C14: ExistingCustomerEOM | D14: 0 | E14: 0 | F14: 0 | G14: 0 | H14: 0 | I14: 0 | K14: 0 | L14: 0 | M14: 6 | N14: 6 | O14: New | P14: New | Q14: 0 | R14: 0 | S14: 0 | T14: 0 | U14: 0 | V14: 0 | W14: 0 | X14: 0 | Y14: 553 | Z14: 836 | AA14: Monthly | AB14: Monthly | AC14: PhuPh | AD14: PhuPh | AE14: 0 | AF14: 0 | AG14: 10 | AH14: 10 | AI14: ==W14+ Y14+D14+H14 | AJ14: ==X14+Z14+E14+I14 | AK14: ==IF(AI14=0,AJ14,0) | AL14: ==IF(AND(AI14>0,AJ14>AI14),AJ14-AI14,0) | AM14: ==IF(AI14=AJ14,AJ14,0) | AN14: ==IF(AJ14=0,AI14,0) | AO14: ==IF(AND(AJ14>0,AJ14<AI14),AI14-AJ14,0) | AP14: US-Accounts Receivable | AQ14: 176322 | AR14: 0 | AS14: 0
A15: ceo40groupinc | B15: NewCustomerEOM | C15: ExistingCustomerEOM | D15: 0 | E15: 0 | F15: 0 | G15: 0 | H15: 0 | I15: 0 | K15: 0 | L15: 0 | M15: 3 | N15: 3 | O15: New | P15: New | Q15: 0 | R15: 0 | S15: 0 | T15: 0 | U15: 0 | V15: 0 | W15: 0 | X15: 0 | Y15: 49 | Z15: 151 | AA15: Monthly | AB15: Monthly | AC15: ChWon | AD15: UrRao | AE15: 0 | AF15: 0 | AG15: 1 | AH15: 4 | AI15: ==W15+ Y15+D15+H15 | AJ15: ==X15+Z15+E15+I15 | AK15: ==IF(AI15=0,AJ15,0) | AL15: ==IF(AND(AI15>0,AJ15>AI15),AJ15-AI15,0) | AM15: ==IF(AI15=AJ15,AJ15,0) | AN15: ==IF(AJ15=0,AI15,0) | AO15: ==IF(AND(AJ15>0,AJ15<AI15),AI15-AJ15,0) | AP15: US-Accounts Receivable | AQ15: 176317 | AR15: 0 | AS15: 0
A16: theatticdepot2 | B16: NewCustomerEOM | C16: ExistingCustomerEOM | D16: 0 | E16: 0 | F16: 0 | G16: 0 | H16: -30.5 | I16: -16.2 | K16: -91.5 | L16: -145.8 | M16: 5 | N16: 5 | O16: New | P16: New | Q16: 0 | R16: 0 | S16: 0 | T16: 0 | U16: 0 | V16: 0 | W16: 0 | X16: 0 | Y16: 122 | Z16: 162 | AA16: Prepay | AB16: Prepay | AC16: ChWon | AD16: SukSa | AE16: 0 | AF16: 0 | AG16: 2 | AH16: 3 | AI16: ==W16+ Y16+D16+H16 | AJ16: ==X16+Z16+E16+I16 | AK16: ==IF(AI16=0,AJ16,0) | AL16: ==IF(AND(AI16>0,AJ16>AI16),AJ16-AI16,0) | AM16: ==IF(AI16=AJ16,AJ16,0) | AN16: ==IF(AJ16=0,AI16,0) | AO16: ==IF(AND(AJ16>0,AJ16<AI16),AI16-AJ16,0) | AP16: US-Accounts Receivable | AQ16: 176326 | AR16: 0 | AS16: 0
A17: pipemonsterplumbingllc | B17: NewCustChurn | D17: 0 | E17: 0 | F17: 0 | G17: 0 | H17: 0 | I17: 0 | K17: 0 | L17: 0 | M17: 4 | N17: 0 | O17: New | Q17: 0 | R17: 0 | S17: 0 | T17: 0 | U17: 0 | V17: 0 | W17: 0 | X17: 0 | Y17: 183 | Z17: 0 | AA17: Monthly | AC17: ChWon | AE17: 0 | AF17: 0 | AG17: 3 | AH17: 0 | AI17: ==W17+ Y17+D17+H17 | AJ17: ==X17+Z17+E17+I17 | AK17: ==IF(AI17=0,AJ17,0) | AL17: ==IF(AND(AI17>0,AJ17>AI17),AJ17-AI17,0) | AM17: ==IF(AI17=AJ17,AJ17,0) | AN17: ==IF(AJ17=0,AI17,0) | AO17: ==IF(AND(AJ17>0,AJ17<AI17),AI17-AJ17,0) | AP17: US-Accounts Receivable | AQ17: 176314 | AR17: 0 | AS17: 0
A18: hallknifeandforge | B18: ExistingCustomerEOM | C18: ExistingCustomerEOM | D18: 0 | E18: 0 | F18: 0 | G18: 0 | H18: 0 | I18: 0 | K18: 0 | L18: 0 | M18: 3 | N18: 3 | O18: New | P18: New | Q18: 0 | R18: 0 | S18: 0 | T18: 0 | U18: 0 | V18: 0 | W18: 0 | X18: 0 | Y18: 52 | Z18: 52 | AA18: Monthly | AB18: Monthly | AC18: JaiPa | AD18: JaiPa | AE18: 0 | AF18: 0 | AG18: 1 | AH18: 1 | AI18: ==W18+ Y18+D18+H18 | AJ18: ==X18+Z18+E18+I18 | AK18: ==IF(AI18=0,AJ18,0) | AL18: ==IF(AND(AI18>0,AJ18>AI18),AJ18-AI18,0) | AM18: ==IF(AI18=AJ18,AJ18,0) | AN18: ==IF(AJ18=0,AI18,0) | AO18: ==IF(AND(AJ18>0,AJ18<AI18),AI18-AJ18,0) | AP18: CAN-Accounts Receivable | AQ18: 168753 | AR18: 0 | AS18: 0
A19: ethiopiancommunityassociationofgreaterphil | B19: ExistingCustomerEOM | D19: 0 | E19: 0 | F19: 0 | G19: 0 | H19: -3 | I19: 0 | K19: -25 | L19: 0 | M19: 1 | N19: 0 | O19: New | Q19: 0 | R19: 0 | S19: 0 | T19: 0 | U19: 0 | V19: 0 | W19: 0 | X19: 0 | Y19: 28 | Z19: 0 | AA19: Prepay | AC19: RafSy | AE19: 0 | AF19: 0 | AG19: 1 | AH19: 0 | AI19: ==W19+ Y19+D19+H19 | AJ19: ==X19+Z19+E19+I19 | AK19: ==IF(AI19=0,AJ19,0) | AL19: ==IF(AND(AI19>0,AJ19>AI19),AJ19-AI19,0) | AM19: ==IF(AI19=AJ19,AJ19,0) | AN19: ==IF(AJ19=0,AI19,0) | AO19: ==IF(AND(AJ19>0,AJ19<AI19),AI19-AJ19,0) | AP19: US-Accounts Receivable | AQ19: 168777 | AR19: 0 | AS19: 0
A20: fairlanefurniturerestorers3 | B20: ExistingCustomerEOM | C20: ExistingCustomerEOM | D20: 0 | E20: 0 | F20: -155 | G20: -46.5 | H20: 0 | I20: 0 | K20: 0 | L20: 0 | M20: 2 | N20: 2 | O20: unknown | P20: unknown | Q20: 0 | R20: 0 | S20: 155 | T20: 465 | U20: 0 | V20: 0 | W20: 0 | X20: 0 | Y20: 416 | Z20: 809 | AA20: Monthly | AB20: Monthly | AC20: PhuPh | AD20: PhuPh | AE20: 0 | AF20: 0 | AG20: 11 | AH20: 13 | AI20: ==W20+ Y20+D20+H20 | AJ20: ==X20+Z20+E20+I20 | AK20: ==IF(AI20=0,AJ20,0) | AL20: ==IF(AND(AI20>0,AJ20>AI20),AJ20-AI20,0) | AM20: ==IF(AI20=AJ20,AJ20,0) | AN20: ==IF(AJ20=0,AI20,0) | AO20: ==IF(AND(AJ20>0,AJ20<AI20),AI20-AJ20,0) | AP20: US-Accounts Receivable | AQ20: 172556 | AR20: 0 | AS20: 0
A21: bieldentalcabinetsrebielcompanyinc | B21: ExistingCustomerEOM | C21: ExistingCustomerEOM | D21: 0 | E21: 0 | F21: 0 | G21: 0 | H21: -24.5 | I21: -11 | K21: -73.5 | L21: -99 | M21: 3 | N21: 4 | O21: unknown | P21: New | Q21: 0 | R21: 0 | S21: 155 | T21: 0 | U21: 0 | V21: 0 | W21: 0 | X21: 0 | Y21: 98 | Z21: 110 | AA21: Prepay | AB21: Prepay | AC21: ChWon | AD21: JaiPa | AE21: 0 | AF21: 0 | AG21: 2 | AH21: 2 | AI21: ==W21+ Y21+D21+H21 | AJ21: ==X21+Z21+E21+I21 | AK21: ==IF(AI21=0,AJ21,0) | AL21: ==IF(AND(AI21>0,AJ21>AI21),AJ21-AI21,0) | AM21: ==IF(AI21=AJ21,AJ21,0) | AN21: ==IF(AJ21=0,AI21,0) | AO21: ==IF(AND(AJ21>0,AJ21<AI21),AI21-AJ21,0) | AP21: US-Accounts Receivable | AQ21: 172829 | AR21: 0 | AS21: 0
A22: baldwinglass | B22: ExistingCustomerEOM | D22: 0 | E22: 0 | F22: 0 | G22: 0 | H22: 0 | I22: 0 | K22: 0 | L22: 0 | M22: 3 | N22: 0 | O22: New | Q22: 0 | R22: 0 | S22: 0 | T22: 0 | U22: 0 | V22: 0 | W22: 0 | X22: 0 | Y22: 49 | Z22: 0 | AA22: Monthly | AC22: ChWon | AE22: 0 | AF22: 0 | AG22: 1 | AH22: 0 | AI22: ==W22+ Y22+D22+H22 | AJ22: ==X22+Z22+E22+I22 | AK22: ==IF(AI22=0,AJ22,0) | AL22: ==IF(AND(AI22>0,AJ22>AI22),AJ22-AI22,0) | AM22: ==IF(AI22=AJ22,AJ22,0) | AN22: ==IF(AJ22=0,AI22,0) | AO22: ==IF(AND(AJ22>0,AJ22<AI22),AI22-AJ22,0) | AP22: US-Accounts Receivable | AQ22: 172574 | AR22: 0 | AS22: 0
A23: tcssllc3 | B23: ExistingCustomerEOM | C23: ExistingCustomerEOM | D23: 0 | E23: 0 | F23: 0 | G23: 0 | H23: 0 | I23: 0 | K23: 0 | L23: 0 | M23: 5 | N23: 5 | O23: unknown | P23: New | Q23: 0 | R23: 0 | S23: 77.5 | T23: 0 | U23: 0 | V23: 0 | W23: 0 | X23: 0 | Y23: 389 | Z23: 407 | AA23: Monthly | AB23: Monthly | AC23: PhuPh | AD23: PhuPh | AE23: 0 | AF23: 0 | AG23: 9 | AH23: 10 | AI23: ==W23+ Y23+D23+H23 | AJ23: ==X23+Z23+E23+I23 | AK23: ==IF(AI23=0,AJ23,0) | AL23: ==IF(AND(AI23>0,AJ23>AI23),AJ23-AI23,0) | AM23: ==IF(AI23=AJ23,AJ23,0) | AN23: ==IF(AJ23=0,AI23,0) | AO23: ==IF(AND(AJ23>0,AJ23<AI23),AI23-AJ23,0) | AP23: US-Accounts Receivable | AQ23: 174386 | AR23: 0 | AS23: 0
A24: boxgangmanufacturing2 | B24: ExistingCustomerEOM | C24: ExistingCustomerEOM | D24: 0 | E24: 0 | F24: 0 | G24: 0 | H24: -58 | I24: 0 | K24: -174 | L24: 0 | M24: 5 | N24: 4 | O24: New | P24: New | Q24: 0 | R24: 0 | S24: 0 | T24: 0 | U24: 0 | V24: 0 | W24: 0 | X24: 0 | Y24: 232 | Z24: 208 | AA24: Prepay | AB24: Monthly | AC24: MikPa | AD24: MikPa | AE24: 0 | AF24: 0 | AG24: 4 | AH24: 4 | AI24: ==W24+ Y24+D24+H24 | AJ24: ==X24+Z24+E24+I24 | AK24: ==IF(AI24=0,AJ24,0) | AL24: ==IF(AND(AI24>0,AJ24>AI24),AJ24-AI24,0) | AM24: ==IF(AI24=AJ24,AJ24,0) | AN24: ==IF(AJ24=0,AI24,0) | AO24: ==IF(AND(AJ24>0,AJ24<AI24),AI24-AJ24,0) | AP24: US-Accounts Receivable | AQ24: 164857 | AR24: 0 | AS24: 0
A25: advprosecurity | B25: ExistingCustomerEOM | C25: ExistingCustomerEOM | D25: 0 | E25: 0 | F25: 0 | G25: 0 | H25: -30 | I25: -30 | K25: -264 | L25: -264 | M25: 3 | N25: 3 | O25: New | P25: New | Q25: 0 | R25: 0 | S25: 0 | T25: 0 | U25: 0 | V25: 0 | W25: 0 | X25: 0 | Y25: 294 | Z25: 294 | AA25: Prepay | AB25: Prepay | AC25: ShaLi | AD25: ShaLi | AE25: 0 | AF25: 0 | AG25: 6 | AH25: 6 | AI25: ==W25+ Y25+D25+H25 | AJ25: ==X25+Z25+E25+I25 | AK25: ==IF(AI25=0,AJ25,0) | AL25: ==IF(AND(AI25>0,AJ25>AI25),AJ25-AI25,0) | AM25: ==IF(AI25=AJ25,AJ25,0) | AN25: ==IF(AJ25=0,AI25,0) | AO25: ==IF(AND(AJ25>0,AJ25<AI25),AI25-AJ25,0) | AP25: US-Accounts Receivable | AQ25: 164832 | AR25: 0 | AS25: 0
A26: arianhomecarecorporation | B26: ExistingCustomerEOM | D26: 0 | E26: 0 | F26: 0 | G26: 0 | H26: 0 | I26: 0 | K26: 0 | L26: 0 | M26: 4 | N26: 0 | O26: New | Q26: 0 | R26: 0 | S26: 0 | T26: 0 | U26: 0 | V26: 0 | W26: 0 | X26: 0 | Y26: 184 | Z26: 0 | AA26: Monthly | AC26: PhuPh | AE26: 0 | AF26: 0 | AG26: 4 | AH26: 0 | AI26: ==W26+ Y26+D26+H26 | AJ26: ==X26+Z26+E26+I26 | AK26: ==IF(AI26=0,AJ26,0) | AL26: ==IF(AND(AI26>0,AJ26>AI26),AJ26-AI26,0) | AM26: ==IF(AI26=AJ26,AJ26,0) | AN26: ==IF(AJ26=0,AI26,0) | AO26: ==IF(AND(AJ26>0,AJ26<AI26),AI26-AJ26,0) | AP26: CAN-Accounts Receivable | AQ26: 166319 | AR26: 0 | AS26: 0
A27: agpharma | B27: ExistingCustomerEOM | C27: ExistingCustomerEOM | D27: 0 | E27: 0 | F27: -36.25 | G27: 0 | H27: 0 | I27: 0 | K27: 0 | L27: 0 | M27: 3 | N27: 3 | O27: unknown | P27: New | Q27: 0 | R27: 0 | S27: 725 | T27: 0 | U27: 0 | V27: 0 | W27: 0 | X27: 0 | Y27: 421 | Z27: 479 | AA27: Monthly | AB27: Monthly | AC27: PhuPh | AD27: PhuPh | AE27: 0 | AF27: 0 | AG27: 10 | AH27: 11 | AI27: ==W27+ Y27+D27+H27 | AJ27: ==X27+Z27+E27+I27 | AK27: ==IF(AI27=0,AJ27,0) | AL27: ==IF(AND(AI27>0,AJ27>AI27),AJ27-AI27,0) | AM27: ==IF(AI27=AJ27,AJ27,0) | AN27: ==IF(AJ27=0,AI27,0) | AO27: ==IF(AND(AJ27>0,AJ27<AI27),AI27-AJ27,0) | AP27: US-Accounts Receivable | AQ27: 166164 | AR27: 0 | AS27: 0
A28: bptest | B28: ExistingCustomerEOM | D28: 0 | E28: 0 | F28: 0 | G28: 0 | H28: -8 | I28: 0 | K28: -72 | L28: 0 | M28: 2 | N28: 0 | O28: New | Q28: 0 | R28: 0 | S28: 0 | T28: 0 | U28: 0 | V28: 0 | W28: 0 | X28: 0 | Y28: 80 | Z28: 0 | AA28: Prepay | AC28: RafSy | AE28: 0 | AF28: 0 | AG28: 2 | AH28: 0 | AI28: ==W28+ Y28+D28+H28 | AJ28: ==X28+Z28+E28+I28 | AK28: ==IF(AI28=0,AJ28,0) | AL28: ==IF(AND(AI28>0,AJ28>AI28),AJ28-AI28,0) | AM28: ==IF(AI28=AJ28,AJ28,0) | AN28: ==IF(AJ28=0,AI28,0) | AO28: ==IF(AND(AJ28>0,AJ28<AI28),AI28-AJ28,0) | AP28: US-Accounts Receivable | AQ28: 165958 | AR28: 0 | AS28: 0
A29: permitsbymirza2 | B29: ExistingCustomerEOM | D29: 0 | E29: 0 | F29: 0 | G29: 0 | H29: 0 | I29: 0 | K29: 0 | L29: 0 | M29: 3 | N29: 0 | O29: New | Q29: 0 | R29: 0 | S29: 0 | T29: 0 | U29: 0 | V29: 0 | W29: 0 | X29: 0 | Y29: 89 | Z29: 0 | AA29: Monthly | AC29: RafSy | AE29: 0 | AF29: 0 | AG29: 2 | AH29: 0 | AI29: ==W29+ Y29+D29+H29 | AJ29: ==X29+Z29+E29+I29 | AK29: ==IF(AI29=0,AJ29,0) | AL29: ==IF(AND(AI29>0,AJ29>AI29),AJ29-AI29,0) | AM29: ==IF(AI29=AJ29,AJ29,0) | AN29: ==IF(AJ29=0,AI29,0) | AO29: ==IF(AND(AJ29>0,AJ29<AI29),AI29-AJ29,0) | AP29: US-Accounts Receivable | AQ29: 167628 | AR29: 0 | AS29: 0
A30: trendysurfaces | B30: ExistingCustomerEOM | C30: ExistingCustomerEOM | D30: 0 | E30: 0 | F30: 0 | G30: 0 | H30: 0 | I30: 0 | K30: 0 | L30: 0 | M30: 1 | N30: 1 | O30: New | P30: New | Q30: 0 | R30: 0 | S30: 0 | T30: 0 | U30: 0 | V30: 0 | W30: 0 | X30: 0 | Y30: 84 | Z30: 56 | AA30: Monthly | AB30: Monthly | AC30: RafSy | AD30: RafSy | AE30: 0 | AF30: 0 | AG30: 3 | AH30: 2 | AI30: ==W30+ Y30+D30+H30 | AJ30: ==X30+Z30+E30+I30 | AK30: ==IF(AI30=0,AJ30,0) | AL30: ==IF(AND(AI30>0,AJ30>AI30),AJ30-AI30,0) | AM30: ==IF(AI30=AJ30,AJ30,0) | AN30: ==IF(AJ30=0,AI30,0) | AO30: ==IF(AND(AJ30>0,AJ30<AI30),AI30-AJ30,0) | AP30: US-Accounts Receivable | AQ30: 159898 | AR30: 0 | AS30: 0
A31: tipsyponypartybarllc | B31: ExistingCustomerEOM | C31: ExistingCustomerEOM | D31: 0 | E31: 0 | F31: 0 | G31: 0 | H31: -11 | I31: -11 | K31: -74 | L31: -74 | M31: 6 | N31: 6 | O31: New | P31: New | Q31: 0 | R31: 0 | S31: 0 | T31: 0 | U31: 0 | V31: 0 | W31: 0 | X31: 0 | Y31: 85 | Z31: 85 | AA31: Prepay | AB31: Prepay | AC31: SukSa | AD31: SukSa | AE31: 0 | AF31: 0 | AG31: 1 | AH31: 1 | AI31: ==W31+ Y31+D31+H31 | AJ31: ==X31+Z31+E31+I31 | AK31: ==IF(AI31=0,AJ31,0) | AL31: ==IF(AND(AI31>0,AJ31>AI31),AJ31-AI31,0) | AM31: ==IF(AI31=AJ31,AJ31,0) | AN31: ==IF(AJ31=0,AI31,0) | AO31: ==IF(AND(AJ31>0,AJ31<AI31),AI31-AJ31,0) | AP31: US-Accounts Receivable | AQ31: 161000 | AR31: 0 | AS31: 0
A32: dinosaw2 | B32: ExistingCustomerEOM | C32: ExistingCustomerEOM | D32: 0 | E32: 0 | F32: 0 | G32: 0 | H32: 0 | I32: 0 | K32: 0 | L32: 0 | M32: 4 | N32: 4 | O32: New | P32: New | Q32: 0 | R32: 0 | S32: 0 | T32: 0 | U32: 0 | V32: 0 | W32: 0 | X32: 0 | Y32: 61 | Z32: 61 | AA32: Monthly | AB32: Monthly | AC32: RafSy | AD32: RafSy | AE32: 0 | AF32: 0 | AG32: 1 | AH32: 1 | AI32: ==W32+ Y32+D32+H32 | AJ32: ==X32+Z32+E32+I32 | AK32: ==IF(AI32=0,AJ32,0) | AL32: ==IF(AND(AI32>0,AJ32>AI32),AJ32-AI32,0) | AM32: ==IF(AI32=AJ32,AJ32,0) | AN32: ==IF(AJ32=0,AI32,0) | AO32: ==IF(AND(AJ32>0,AJ32<AI32),AI32-AJ32,0) | AP32: US-Accounts Receivable | AQ32: 160992 | AR32: 0 | AS32: 0
A33: nextsteporlando4 | B33: ExistingCustomerEOM | C33: ExistingCustomerEOM | D33: 0 | E33: 0 | F33: 0 | G33: 0 | H33: 0 | I33: 0 | K33: 0 | L33: 0 | M33: 3 | N33: 3 | O33: New | P33: New | Q33: 0 | R33: 0 | S33: 0 | T33: 0 | U33: 0 | V33: 0 | W33: 0 | X33: 0 | Y33: 52 | Z33: 52 | AA33: Monthly | AB33: Monthly | AC33: SukSa | AD33: SukSa | AE33: 0 | AF33: 0 | AG33: 1 | AH33: 1 | AI33: ==W33+ Y33+D33+H33 | AJ33: ==X33+Z33+E33+I33 | AK33: ==IF(AI33=0,AJ33,0) | AL33: ==IF(AND(AI33>0,AJ33>AI33),AJ33-AI33,0) | AM33: ==IF(AI33=AJ33,AJ33,0) | AN33: ==IF(AJ33=0,AI33,0) | AO33: ==IF(AND(AJ33>0,AJ33<AI33),AI33-AJ33,0) | AP33: US-Accounts Receivable | AQ33: 162151 | AR33: 0 | AS33: 0
A34: turnservllc2 | B34: ExistingCustomerEOM | C34: ExistingCustomerEOM | D34: 0 | E34: 0 | F34: -725 | G34: 0 | H34: 0 | I34: 0 | K34: 0 | L34: 0 | M34: 6 | N34: 6 | O34: unknown | P34: New | Q34: 0 | R34: 0 | S34: 3625 | T34: 0 | U34: 0 | V34: 0 | W34: 0 | X34: 0 | Y34: 1628 | Z34: 1518 | AA34: Monthly | AB34: Monthly | AC34: MikPa | AD34: MikPa | AE34: 0 | AF34: 0 | AG34: 35 | AH34: 23 | AI34: ==W34+ Y34+D34+H34 | AJ34: ==X34+Z34+E34+I34 | AK34: ==IF(AI34=0,AJ34,0) | AL34: ==IF(AND(AI34>0,AJ34>AI34),AJ34-AI34,0) | AM34: ==IF(AI34=AJ34,AJ34,0) | AN34: ==IF(AJ34=0,AI34,0) | AO34: ==IF(AND(AJ34>0,AJ34<AI34),AI34-AJ34,0) | AP34: US-Accounts Receivable | AQ34: 163490 | AR34: 0 | AS34: 0
A35: blackhausflooring | B35: ExistingCustChurn | D35: 0 | E35: 0 | F35: 0 | G35: 0 | H35: -9 | I35: 0 | K35: -64 | L35: 0 | M35: 5 | N35: 0 | O35: unknown | Q35: 0 | R35: 0 | S35: 0 | T35: 0 | U35: 0 | V35: 0 | W35: 0 | X35: 0 | Y35: 73 | Z35: 0 | AA35: Prepay | AC35: JaiPa | AE35: 0 | AF35: 0 | AG35: 1 | AH35: 0 | AI35: ==W35+ Y35+D35+H35 | AJ35: ==X35+Z35+E35+I35 | AK35: ==IF(AI35=0,AJ35,0) | AL35: ==IF(AND(AI35>0,AJ35>AI35),AJ35-AI35,0) | AM35: ==IF(AI35=AJ35,AJ35,0) | AN35: ==IF(AJ35=0,AI35,0) | AO35: ==IF(AND(AJ35>0,AJ35<AI35),AI35-AJ35,0) | AP35: US-Accounts Receivable | AQ35: 163512 | AR35: 0 | AS35: 0
A36: cascadestainlesssolutionsllc | B36: ExistingCustomerEOM | D36: 0 | E36: 0 | F36: 0 | G36: 0 | H36: 0 | I36: 0 | K36: 0 | L36: 0 | M36: 5 | N36: 0 | O36: New | Q36: 0 | R36: 0 | S36: 0 | T36: 0 | U36: 0 | V36: 0 | W36: 0 | X36: 0 | Y36: 122 | Z36: 0 | AA36: Monthly | AC36: SukSa | AE36: 0 | AF36: 0 | AG36: 2 | AH36: 0 | AI36: ==W36+ Y36+D36+H36 | AJ36: ==X36+Z36+E36+I36 | AK36: ==IF(AI36=0,AJ36,0) | AL36: ==IF(AND(AI36>0,AJ36>AI36),AJ36-AI36,0) | AM36: ==IF(AI36=AJ36,AJ36,0) | AN36: ==IF(AJ36=0,AI36,0) | AO36: ==IF(AND(AJ36>0,AJ36<AI36),AI36-AJ36,0) | AP36: US-Accounts Receivable | AQ36: 155176 | AR36: 0 | AS36: 0
A37: colonyroofing | B37: ExistingCustomerEOM | C37: ExistingCustomerEOM | D37: 0 | E37: 0 | F37: 0 | G37: 0 | H37: 0 | I37: 0 | K37: 0 | L37: 0 | M37: 3 | N37: 3 | O37: New | P37: New | Q37: 0 | R37: 0 | S37: 0 | T37: 0 | U37: 0 | V37: 0 | W37: 0 | X37: 0 | Y37: 322 | Z37: 322 | AA37: Monthly | AB37: Monthly | AC37: MikPa | AD37: MikPa | AE37: 0 | AF37: 0 | AG37: 7 | AH37: 7 | AI37: ==W37+ Y37+D37+H37 | AJ37: ==X37+Z37+E37+I37 | AK37: ==IF(AI37=0,AJ37,0) | AL37: ==IF(AND(AI37>0,AJ37>AI37),AJ37-AI37,0) | AM37: ==IF(AI37=AJ37,AJ37,0) | AN37: ==IF(AJ37=0,AI37,0) | AO37: ==IF(AND(AJ37>0,AJ37<AI37),AI37-AJ37,0) | AP37: US-Accounts Receivable | AQ37: 156444 | AR37: 0 | AS37: 0
A38: pioneersourcingsolutionsllc | B38: ExistingCustomerEOM | C38: ExistingCustomerEOM | D38: 0 | E38: 0 | F38: 0 | G38: 0 | H38: -3 | I38: -3 | K38: -25 | L38: -25 | M38: 1 | N38: 1 | O38: New | P38: New | Q38: 0 | R38: 0 | S38: 0 | T38: 0 | U38: 0 | V38: 0 | W38: 0 | X38: 0 | Y38: 28 | Z38: 28 | AA38: Prepay | AB38: Prepay | AC38: RafSy | AD38: RafSy | AE38: 0 | AF38: 0 | AG38: 1 | AH38: 1 | AI38: ==W38+ Y38+D38+H38 | AJ38: ==X38+Z38+E38+I38 | AK38: ==IF(AI38=0,AJ38,0) | AL38: ==IF(AND(AI38>0,AJ38>AI38),AJ38-AI38,0) | AM38: ==IF(AI38=AJ38,AJ38,0) | AN38: ==IF(AJ38=0,AI38,0) | AO38: ==IF(AND(AJ38>0,AJ38<AI38),AI38-AJ38,0) | AP38: US-Accounts Receivable | AQ38: 158737 | AR38: 0 | AS38: 0
A39: jdshouseoftrophies | B39: ExistingCustomerEOM | C39: ExistingCustomerEOM | D39: 0 | E39: 0 | F39: 0 | G39: -155 | H39: 0 | I39: 0 | K39: 0 | L39: 0 | M39: 3 | N39: 3 | O39: New | P39: unknown | Q39: 0 | R39: 0 | S39: 0 | T39: 155 | U39: 0 | V39: 0 | W39: 0 | X39: 0 | Y39: 196 | Z39: 196 | AA39: Monthly | AB39: Monthly | AC39: PhuPh | AD39: PhuPh | AE39: 0 | AF39: 0 | AG39: 4 | AH39: 4 | AI39: ==W39+ Y39+D39+H39 | AJ39: ==X39+Z39+E39+I39 | AK39: ==IF(AI39=0,AJ39,0) | AL39: ==IF(AND(AI39>0,AJ39>AI39),AJ39-AI39,0) | AM39: ==IF(AI39=AJ39,AJ39,0) | AN39: ==IF(AJ39=0,AI39,0) | AO39: ==IF(AND(AJ39>0,AJ39<AI39),AI39-AJ39,0) | AP39: US-Accounts Receivable | AQ39: 158724 | AR39: 0 | AS39: 0
A40: finelinecreativeartscenter | B40: ExistingCustomerEOM | C40: ExistingCustomerEOM | D40: 0 | E40: 0 | F40: 0 | G40: 0 | H40: -5.6 | I40: -5.6 | K40: -50.4 | L40: -50.4 | M40: 1 | N40: 1 | O40: New | P40: New | Q40: 0 | R40: 0 | S40: 0 | T40: 0 | U40: 0 | V40: 0 | W40: 0 | X40: 0 | Y40: 56 | Z40: 56 | AA40: Prepay | AB40: Prepay | AC40: RafSy | AD40: RafSy | AE40: 0 | AF40: 0 | AG40: 2 | AH40: 2 | AI40: ==W40+ Y40+D40+H40 | AJ40: ==X40+Z40+E40+I40 | AK40: ==IF(AI40=0,AJ40,0) | AL40: ==IF(AND(AI40>0,AJ40>AI40),AJ40-AI40,0) | AM40: ==IF(AI40=AJ40,AJ40,0) | AN40: ==IF(AJ40=0,AI40,0) | AO40: ==IF(AND(AJ40>0,AJ40<AI40),AI40-AJ40,0) | AP40: US-Accounts Receivable | AQ40: 158733 | AR40: 0 | AS40: 0
...

Sheet NRR By Account
A1: Start of Month | B1: Start of Month | C1: Start of Month | D1: Cancellation | E1: Cancellation | F1: Cancellation | G1: Downgrades | H1: Downgrades | I1: Downgrades | J1: Expansion | K1: Expansion | L1: Expansion | M1: New ARR | N1: New ARR | O1: New ARR | P1: Other | Q1: Other | R1: Other | S1: OtherChurn | T1: OtherChurn | U1: OtherChurn | V1: Count | W1: Count | X1: Count
A2: US-Accounts Receivable | B2: CAN-Accounts Receivable | C2: UK-Accounts Receivable | D2: US-Accounts Receivable | E2: CAN-Accounts Receivable | F2: UK-Accounts Receivable | G2: US-Accounts Receivable | H2: CAN-Accounts Receivable | I2: UK-Accounts Receivable | J2: US-Accounts Receivable | K2: CAN-Accounts Receivable | L2: UK-Accounts Receivable | M2: US-Accounts Receivable | N2: CAN-Accounts Receivable | O2: UK-Accounts Receivable | P2: US-Accounts Receivable | Q2: CAN-Accounts Receivable | R2: UK-Accounts Receivable | S2: US-Accounts Receivable | T2: CAN-Accounts Receivable | U2: UK-Accounts Receivable | V2: US-Accounts Receivable | W2: CAN-Accounts Receivable | X2: UK-Accounts Receivable
A3: ==SUMIFS(Accounts!AI:AI,Accounts!AP:AP,A$2) | B3: ==SUMIFS(Accounts!AI:AI,Accounts!AP:AP,B$2) | C3: ==SUMIFS(Accounts!AI:AI,Accounts!AP:AP,C$2) | D3: ==SUMIFS(Accounts!AN:AN,Accounts!AP:AP,D$2)-S3 | E3: ==SUMIFS(Accounts!AN:AN,Accounts!AP:AP,E$2)-T3 | F3: ==SUMIFS(Accounts!AN:AN,Accounts!AP:AP,F$2)-U3 | G3: ==SUMIFS(Accounts!AO:AO,Accounts!AP:AP,G$2) | H3: ==SUMIFS(Accounts!AO:AO,Accounts!AP:AP,H$2) | I3: ==SUMIFS(Accounts!AO:AO,Accounts!AP:AP,I$2) | J3: ==SUMIFS(Accounts!AL:AL,Accounts!AP:AP,J$2) | K3: ==SUMIFS(Accounts!AL:AL,Accounts!AP:AP,K$2) | L3: ==SUMIFS(Accounts!AL:AL,Accounts!AP:AP,L$2) | M3: ==SUMIFS(Accounts!AK:AK,Accounts!AP:AP,M$2)-P3 | N3: ==SUMIFS(Accounts!AK:AK,Accounts!AP:AP,N$2)-Q3 | O3: ==SUMIFS(Accounts!AK:AK,Accounts!AP:AP,O$2)-R3 | P3: ==SUMIFS(Customers!AS:AS,Customers!AP:AP,P$2) | Q3: ==SUMIFS(Customers!AS:AS,Customers!AP:AP,Q$2) | R3: ==SUMIFS(Customers!AS:AS,Customers!AP:AP,R$2) | S3: ==SUMIFS(Customers!AR:AR,Customers!AP:AP,P$2) | T3: ==SUMIFS(Customers!AR:AR,Customers!AP:AP,Q$2) | U3: ==SUMIFS(Customers!AR:AR,Customers!AP:AP,R$2) | V3: ==COUNTIFS(Accounts!Z:Z, ">0",Accounts!AP:AP,V$2) | W3: ==COUNTIFS(Accounts!Z:Z, ">0",Accounts!AP:AP,W$2) | X3: ==COUNTIFS(Accounts!Z:Z, ">0",Accounts!AP:AP,X$2)

Sheet SaaS Totals
A1: Use FX? | B1: TRUE
B2: F/X to CAD | C2: Start | D2: Less PreExpiry Income | E2: Net Change | F2: NRR Amount | G2: NRR% | H2: New+PrepExiry | I2: End
A3: US | B3: 1.33 | C3: ='NRR By Customer'!$A$3*IF($B$1=TRUE,$B3,1) -> 0 | D3: =C3-('NRR By Customer'!$S$3*IF($B$1=TRUE,$B3,1)) -> 0 | E3: =(('NRR By Customer'!$J$3)-('NRR By Customer'!$D$3)-('NRR By Customer'!$G$3))*IF($B$1=TRUE,$B3,1) -> 0 | F3: =D3+E3 -> 0 | G3: =F3/D3 -> #DIV/0! | H3: =('NRR By Customer'!$M$3+'NRR By Customer'!$P$3)*IF($B$1=TRUE,$B3,1) -> 0 | I3: =F3+H3 -> 0
A4: CAN | B4: 1 | C4: ='NRR By Customer'!$B$3*IF($B$1=TRUE,$B4,1) -> 0 | D4: =C4-('NRR By Customer'!$T$3*IF($B$1=TRUE,$B4,1)) -> 0 | E4: =(('NRR By Customer'!$K$3)-('NRR By Customer'!$E$3)-('NRR By Customer'!$H$3))*IF($B$1=TRUE,$B4,1) -> 0 | F4: =D4+E4 -> 0 | G4: =F4/D4 -> #DIV/0! | H4: =('NRR By Customer'!$N$3+'NRR By Customer'!$Q$3)*IF($B$1=TRUE,$B4,1) -> 0 | I4: =F4+H4 -> 0
A5: UK | B5: 1.7 | C5: ='NRR By Customer'!$C$3*IF($B$1=TRUE,$B5,1) -> 0 | D5: =C5-('NRR By Customer'!$U$3*IF($B$1=TRUE,$B5,1)) -> 0 | E5: =(('NRR By Customer'!$L$3)-('NRR By Customer'!$F$3)-('NRR By Customer'!$I$3))*IF($B$1=TRUE,$B5,1) -> 0 | F5: =D5+E5 -> 0 | G5: =F5/D5 -> #DIV/0! | H5: =('NRR By Customer'!O$3+'NRR By Customer'!$R$3)*IF($B$1=TRUE,$B5,1) -> 0 | I5: =F5+H5 -> 0
A6: Total | C6: =SUM(C3:C5) -> 0 | D6: =SUM(D3:D5) -> 0 | E6: =SUM(E3:E5) -> 0 | F6: =SUM(F3:F5) -> 0 | G6: =F6/D6 -> #DIV/0! | H6: =SUM(H3:H5) -> 0 | I6: =SUM(I3:I5) -> 0
