Workbook

Sheet Customers
A1: CompanyAccount | B1: CustomerGroupingPeriod1 | C1: CustomerGroupingPeriod2 | D1: DiscountOtherSaaSPeriod1 | E1: DiscountOtherSaaSPeriod2 | F1: DiscountOtherPSPeriod1 | G1: DiscountOtherPSPeriod2 | H1: DiscountPrepayPortionPeriod1 | I1: DiscountPrepayPortionPeriod2 | J1: InvoiceGrouping | K1: LiabilityPortionPeriod1 | L1: LiabilityPortionPeriod2 | M1: PackPaidCountPeriod1 | N1: PackPaidCountPeriod2 | O1: PlatformTogglePeriod1 | P1: PlatformTogglePeriod2 | Q1: PSExpenseAmountPeriod1 | R1: PSExpenseAmountPeriod2 | S1: PSIncomeAmountPeriod1 | T1: PSIncomeAmountPeriod2 | U1: SaasExpensePeriod1 | V1: SaasExpensePeriod2 | W1: SaaSIncomeAmountClassicPeriod1 | X1: SaaSIncomeAmountClassicPeriod2 | Y1: SaaSIncomeAmountNewPeriod1 | Z1: SaaSIncomeAmountNewPeriod2 | AA1: SaaSPayTypePeriod1 | AB1: SaaSPayTypePeriod2 | AC1: SalesRepSaaSPeriod1 | AD1: SalesRepSaaSPeriod2 | AE1: UncategorizedPortionPeriod1 | AF1: UncategorizedPortionPeriod2 | AG1: UserPaidCountPeriod1 | AH1: UserPaidCountPeriod2 | AI1: SaaSNetPeriod1 | AJ1: SaaSNetPeriod2 | AK1: SaaSExpandNew | AL1: SaaSExpansionUp | AM1: SaaSNoChange | AN1: SaaSContractionCancel | AO1: SaaSContractionDown | AP1: Currency | AQ1: CustomerRecordID | AR1: PerPayExpriyPeriod1 | AS1: PerPayExpriyPeriod2
A2: freedupsolutions | B2: ExistingCustomerEOM | C2: ExistingCustomerEOM | D2: -186 | E2: -186 | F2: 0 | G2: 0 | H2: 0 | I2: 0 | K2: 0 | L2: 0 | M2: 3 | N2: 3 | O2: New | P2: New | Q2: 0 | R2: 0 | S2: 0 | T2: 0 | U2: 0 | V2: 0 | W2: 0 | X2: 0 | Y2: 186 | Z2: 186 | AA2: Monthly | AB2: Monthly | AC2: ShaLi | AD2: ShaLi | AE2: 0 | AF2: 0 | AG2: 2 | AH2: 2 | AI2: =W2+ Y2+D2+H2 -> 0 | AJ2: =X2+Z2+E2+I2 -> 0 | AK2: =IF(AI2=0,AJ2,0) -> 0 | AL2: =IF(AND(AI2>0,AJ2>AI2),AJ2-AI2,0) -> 0 | AM2: =IF(AI2=AJ2,AJ2,0) -> 0 | AN2: =IF(AJ2=0,AI2,0) -> 0 | AO2: =IF(AND(AJ2>0,AJ2<AI2),AI2-AJ2,0) -> 0 | AP2: US-Accounts Receivable | AQ2: 4271 | AR2: 0 | AS2: 0
A3: therylangroupllc | B3: ExistingCustomerEOM | C3: ExistingCustomerEOM | D3: -80 | E3: -80 | F3: 0 | G3: 0 | H3: 0 | I3: 0 | K3: 0 | L3: 0 | M3: 1 | N3: 1 | O3: Classic | P3: Classic | Q3: 0 | R3: 0 | S3: 0 | T3: 0 | U3: 0 | V3: 0 | W3: 80 | X3: 80 | Y3: 0 | Z3: 0 | AA3: Monthly | AB3: Monthly | AC3: PhuPh | AD3: PhuPh | AE3: 0 | AF3: 0 | AG3: 1 | AH3: 1 | AI3: =W3+ Y3+D3+H3 -> 0 | AJ3: =X3+Z3+E3+I3 -> 0 | AK3: =IF(AI3=0,AJ3,0) -> 0 | AL3: =IF(AND(AI3>0,AJ3>AI3),AJ3-AI3,0) -> 0 | AM3: =IF(AI3=AJ3,AJ3,0) -> 0 | AN3: =IF(AJ3=0,AI3,0) -> 0 | AO3: =IF(AND(AJ3>0,AJ3<AI3),AI3-AJ3,0) -> 0 | AP3: US-Accounts Receivable | AQ3: 11547 | AR3: 0 | AS3: 0
A4: atlanticgraphics | B4: ExistingCustomerEOM | C4: ExistingCustomerEOM | D4: 0 | E4: 0 | F4: 0 | G4: 0 | H4: 0 | I4: 0 | K4: 0 | L4: 0 | M4: 3 | N4: 3 | O4: New | P4: New | Q4: 0 | R4: 0 | S4: 0 | T4: 0 | U4: 0 | V4: 0 | W4: 0 | X4: 0 | Y4: 365 | Z4: 365 | AA4: Monthly | AB4: Monthly | AC4: PhuPh | AD4: PhuPh | AE4: 0 | AF4: 0 | AG4: 9 | AH4: 9 | AI4: =W4+ Y4+D4+H4 -> 365 | AJ4: =X4+Z4+E4+I4 -> 365 | AK4: =IF(AI4=0,AJ4,0) -> 0 | AL4: =IF(AND(AI4>0,AJ4>AI4),AJ4-AI4,0) -> 0 | AM4: =IF(AI4=AJ4,AJ4,0) -> 365 | AN4: =IF(AJ4=0,AI4,0) -> 0 | AO4: =IF(AND(AJ4>0,AJ4<AI4),AI4-AJ4,0) -> 0 | AP4: US-Accounts Receivable | AQ4: 63546 | AR4: 0 | AS4: 0
A5: rhinebeckaerodromemuseum | B5: ExistingCustomerEOM | C5: ExistingCustomerEOM | D5: 0 | E5: 0 | F5: 0 | G5: 0 | H5: 0 | I5: 0 | K5: 0 | L5: 0 | M5: 1 | N5: 1 | O5: New | P5: New | Q5: 0 | R5: 0 | S5: 0 | T5: 0 | U5: 0 | V5: 0 | W5: 0 | X5: 0 | Y5: 28 | Z5: 28 | AA5: Monthly | AB5: Monthly | AC5: SukSa | AD5: SukSa | AE5: 0 | AF5: 0 | AG5: 1 | AH5: 1 | AI5: =W5+ Y5+D5+H5 -> 28 | AJ5: =X5+Z5+E5+I5 -> 28 | AK5: =IF(AI5=0,AJ5,0) -> 0 | AL5: =IF(AND(AI5>0,AJ5>AI5),AJ5-AI5,0) -> 0 | AM5: =IF(AI5=AJ5,AJ5,0) -> 28 | AN5: =IF(AJ5=0,AI5,0) -> 0 | AO5: =IF(AND(AJ5>0,AJ5<AI5),AI5-AJ5,0) -> 0 | AP5: US-Accounts Receivable | AQ5: 79741 | AR5: 0 | AS5: 0
A6: petersammsequipmentltd | B6: ExistingCustomerEOM | C6: ExistingCustomerEOM | D6: 0 | E6: 0 | F6: 0 | G6: 0 | H6: -5 | I6: -5 | K6: -44 | L6: -44 | M6: 3 | N6: 3 | O6: New | P6: New | Q6: 0 | R6: 0 | S6: 0 | T6: 0 | U6: 0 | V6: 0 | W6: 0 | X6: 0 | Y6: 49 | Z6: 49 | AA6: Prepay | AB6: Prepay | AC6: RafSy | AD6: RafSy | AE6: 0 | AF6: 0 | AG6: 1 | AH6: 1 | AI6: =W6+ Y6+D6+H6 -> 44 | AJ6: =X6+Z6+E6+I6 -> 44 | AK6: =IF(AI6=0,AJ6,0) -> 0 | AL6: =IF(AND(AI6>0,AJ6>AI6),AJ6-AI6,0) -> 0 | AM6: =IF(AI6=AJ6,AJ6,0) -> 44 | AN6: =IF(AJ6=0,AI6,0) -> 0 | AO6: =IF(AND(AJ6>0,AJ6<AI6),AI6-AJ6,0) -> 0 | AP6: US-Accounts Receivable | AQ6: 93516 | AR6: 0 | AS6: 0
A7: nwseaport | B7: ExistingCustomerEOM | C7: ExistingCustomerEOM | D7: 0 | E7: 0 | F7: 0 | G7: 0 | H7: -3 | I7: -3 | K7: -25 | L7: -25 | M7: 1 | N7: 1 | O7: New | P7: New | Q7: 0 | R7: 0 | S7: 0 | T7: 0 | U7: 0 | V7: 0 | W7: 0 | X7: 0 | Y7: 28 | Z7: 28 | AA7: Prepay | AB7: Prepay | AC7: SukSa | AD7: SukSa | AE7: 0 | AF7: 0 | AG7: 1 | AH7: 1 | AI7: =W7+ Y7+D7+H7 -> 25 | AJ7: =X7+Z7+E7+I7 -> 25 | AK7: =IF(AI7=0,AJ7,0) -> 0 | AL7: =IF(AND(AI7>0,AJ7>AI7),AJ7-AI7,0) -> 0 | AM7: =IF(AI7=AJ7,AJ7,0) -> 25 | AN7: =IF(AJ7=0,AI7,0) -> 0 | AO7: =IF(AND(AJ7>0,AJ7<AI7),AI7-AJ7,0) -> 0 | AP7: US-Accounts Receivable | AQ7: 95174 | AR7: 0 | AS7: 0
A8: pbaccounting | B8: ExistingCustomerEOM | C8: ExistingCustomerEOM | D8: -37 | E8: -37 | F8: 0 | G8: 0 | H8: 0 | I8: 0 | K8: 0 | L8: 0 | M8: 2 | N8: 2 | O8: New | P8: New | Q8: 0 | R8: 0 | S8: 0 | T8: 0 | U8: 0 | V8: 0 | W8: 0 | X8: 0 | Y8: 37 | Z8: 37 | AA8: Monthly | AB8: Monthly | AC8: PhuPh | AD8: PhuPh | AE8: 0 | AF8: 0 | AG8: 1 | AH8: 1 | AI8: =W8+ Y8+D8+H8 -> 0 | AJ8: =X8+Z8+E8+I8 -> 0 | AK8: =IF(AI8=0,AJ8,0) -> 0 | AL8: =IF(AND(AI8>0,AJ8>AI8),AJ8-AI8,0) -> 0 | AM8: =IF(AI8=AJ8,AJ8,0) -> 0 | AN8: =IF(AJ8=0,AI8,0) -> 0 | AO8: =IF(AND(AJ8>0,AJ8<AI8),AI8-AJ8,0) -> 0 | AP8: US-Accounts Receivable | AQ8: 94821 | AR8: 0 | AS8: 0
A9: alerthomewatch | B9: ExistingCustomerEOM | C9: ExistingCustomerEOM | D9: 0 | E9: 0 | F9: 0 | G9: 0 | H9: 0 | I9: 0 | K9: 0 | L9: 0 | M9: 1 | N9: 1 | O9: New | P9: New | Q9: 0 | R9: 0 | S9: 0 | T9: 0 | U9: 0 | V9: 0 | W9: 0 | X9: 0 | Y9: 84 | Z9: 84 | AA9: Monthly | AB9: Monthly | AC9: PhuPh | AD9: PhuPh | AE9: 0 | AF9: 0 | AG9: 3 | AH9: 3 | AI9: =W9+ Y9+D9+H9 -> 84 | AJ9: =X9+Z9+E9+I9 -> 84 | AK9: =IF(AI9=0,AJ9,0) -> 0 | AL9: =IF(AND(AI9>0,AJ9>AI9),AJ9-AI9,0) -> 0 | AM9: =IF(AI9=AJ9,AJ9,0) -> 84 | AN9: =IF(AJ9=0,AI9,0) -> 0 | AO9: =IF(AND(AJ9>0,AJ9<AI9),AI9-AJ9,0) -> 0 | AP9: US-Accounts Receivable | AQ9: 96657 | AR9: 0 | AS9: 0
A10: themovingcompany | B10: ExistingCustomerEOM | C10: ExistingCustomerEOM | D10: 0 | E10: 0 | F10: 0 | G10: 0 | H10: -3 | I10: -3 | K10: -25 | L10: -25 | M10: 1 | N10: 1 | O10: New | P10: New | Q10: 0 | R10: 0 | S10: 0 | T10: 0 | U10: 0 | V10: 0 | W10: 0 | X10: 0 | Y10: 28 | Z10: 28 | AA10: Prepay | AB10: Prepay | AC10: JaiPa | AD10: JaiPa | AE10: 0 | AF10: 0 | AG10: 1 | AH10: 1 | AI10: =W10+ Y10+D10+H10 -> 25 | AJ10: =X10+Z10+E10+I10 -> 25 | AK10: =IF(AI10=0,AJ10,0) -> 0 | AL10: =IF(AND(AI10>0,AJ10>AI10),AJ10-AI10,0) -> 0 | AM10: =IF(AI10=AJ10,AJ10,0) -> 25 | AN10: =IF(AJ10=0,AI10,0) -> 0 | AO10: =IF(AND(AJ10>0,AJ10<AI10),AI10-AJ10,0) -> 0 | AP10: US-Accounts Receivable | AQ10: 97379 | AR10: 0 | AS10: 0
A11: innovativeenergy | B11: ExistingCustomerEOM | C11: ExistingCustomerEOM | D11: 0 | E11: 0 | F11: 0 | G11: 0 | H11: 0 | I11: 0 | K11: 0 | L11: 0 | M11: 3 | N11: 3 | O11: New | P11: New | Q11: 0 | R11: 0 | S11: 0 | T11: 0 | U11: 0 | V11: 0 | W11: 0 | X11: 0 | Y11: 343 | Z11: 343 | AA11: Monthly | AB11: Monthly | AC11: HaPat | AD11: HaPat | AE11: 0 | AF11: 0 | AG11: 7 | AH11: 7 | AI11: =W11+ Y11+D11+H11 -> 343 | AJ11: =X11+Z11+E11+I11 -> 343 | AK11: =IF(AI11=0,AJ11,0) -> 0 | AL11: =IF(AND(AI11>0,AJ11>AI11),AJ11-AI11,0) -> 0 | AM11: =IF(AI11=AJ11,AJ11,0) -> 343 | AN11: =IF(AJ11=0,AI11,0) -> 0 | AO11: =IF(AND(AJ11>0,AJ11<AI11),AI11-AJ11,0) -> 0 | AP11: US-Accounts Receivable | AQ11: 98394 | AR11: 0 | AS11: 0
A12: CarlsonConcierge | B12: ExistingCustomerEOM | C12: ExistingCustomerEOM | D12: -11.2 | E12: -11.2 | F12: 0 | G12: 0 | H12: 0 | I12: 0 | K12: 0 | L12: 0 | M12: 1 | N12: 1 | O12: New | P12: New | Q12: 0 | R12: 0 | S12: 0 | T12: 0 | U12: 0 | V12: 0 | W12: 0 | X12: 0 | Y12: 56 | Z12: 56 | AA12: Monthly | AB12: Monthly | AC12: PhuPh | AD12: PhuPh | AE12: 0 | AF12: 0 | AG12: 2 | AH12: 2 | AI12: =W12+ Y12+D12+H12 -> 44.8 | AJ12: =X12+Z12+E12+I12 -> 44.8 | AK12: =IF(AI12=0,AJ12,0) -> 0 | AL12: =IF(AND(AI12>0,AJ12>AI12),AJ12-AI12,0) -> 0 | AM12: =IF(AI12=AJ12,AJ12,0) -> 44.8 | AN12: =IF(AJ12=0,AI12,0) -> 0 | AO12: =IF(AND(AJ12>0,AJ12<AI12),AI12-AJ12,0) -> 0 | AP12: US-Accounts Receivable | AQ12: 86456 | AR12: 0 | AS12: 0
A13: bbbsilCo1 | B13: ExistingCustomerEOM | C13: ExistingCustomerEOM | D13: 0 | E13: 0 | F13: 0 | G13: 0 | H13: -9 | I13: -18 | K13: -75 | L13: -150 | M13: 1 | N13: 1 | O13: New | P13: New | Q13: 0 | R13: 0 | S13: 0 | T13: 0 | U13: 0 | V13: 0 | W13: 0 | X13: 0 | Y13: 84 | Z13: 168 | AA13: Prepay | AB13: Prepay | AC13: RafSy | AD13: RafSy | AE13: 0 | AF13: 0 | AG13: 3 | AH13: 3 | AI13: =W13+ Y13+D13+H13 -> 75 | AJ13: =X13+Z13+E13+I13 -> 150 | AK13: =IF(AI13=0,AJ13,0) -> 0 | AL13: =IF(AND(AI13>0,AJ13>AI13),AJ13-AI13,0) -> 75 | AM13: =IF(AI13=AJ13,AJ13,0) -> 0 | AN13: =IF(AJ13=0,AI13,0) -> 0 | AO13: =IF(AND(AJ13>0,AJ13<AI13),AI13-AJ13,0) -> 0 | AP13: US-Accounts Receivable | AQ13: 98976 | AR13: 0 | AS13: 0
... A32: NewEnglandLanguageSchoolInc | B32: ExistingCustomerEOM | C32: ExistingCustomerEOM | D32: -5.6 | E32: -5.6 | F32: 0 | G32: 0 | H32: 0 | I32: 0 | K32: 0 | L32: 0 | M32: 1 | N32: 1 | O32: New | P32: New | Q32: 0 | R32: 0 | S32: 0 | T32: 0 | U32: 0 | V32: 0 | W32: 0 | X32: 0 | Y32: 28 | Z32: 28 | AA32: Monthly | AB32: Monthly | AC32: PhuPh | AD32: PhuPh | AE32: 0 | AF32: 0 | AG32: 1 | AH32: 1 | AI32: =W32+ Y32+D32+H32 -> 22.4 | AJ32: =X32+Z32+E32+I32 -> 22.4 | AK32: =IF(AI32=0,AJ32,0) -> 0 | AL32: =IF(AND(AI32>0,AJ32>AI32),AJ32-AI32,0) -> 0 | AM32: =IF(AI32=AJ32,AJ32,0) -> 22.4 | AN32: =IF(AJ32=0,AI32,0) -> 0 | AO32: =IF(AND(AJ32>0,AJ32<AI32),AI32-AJ32,0) -> 0 | AP32: US-Accounts Receivable | AQ32: 98759 | AR32: 0 | AS32: 0
A33: NovusFireProtectionConsultingInc | B33: ExistingCustomerEOM | C33: ExistingCustomerEOM | D33: 0 | E33: 0 | F33: 0 | G33: 0 | H33: 0 | I33: 0 | K33: 0 | L33: 0 | M33: 0 | N33: 0 | O33: unknown | P33: unknown | Q33: 0 | R33: 0 | S33: 0 | T33: 0 | U33: 0 | V33: 0 | W33: 0 | X33: 0 | Y33: 0 | Z33: 0 | AE33: 0 | AF33: 0 | AG33: 0 | AH33: 0 | AI33: =W33+ Y33+D33+H33 -> 0 | AJ33: =X33+Z33+E33+I33 -> 0 | AK33: =IF(AI33=0,AJ33,0) -> 0 | AL33: =IF(AND(AI33>0,AJ33>AI33),AJ33-AI33,0) -> 0 | AM33: =IF(AI33=AJ33,AJ33,0) -> 0 | AN33: =IF(AJ33=0,AI33,0) -> 0 | AO33: =IF(AND(AJ33>0,AJ33<AI33),AI33-AJ33,0) -> 0 | AP33: CAN-Accounts Receivable | AQ33: 85984 | AR33: 0 | AS33: 0
A34: BenShaffer | B34: ExistingCustomerEOM | C34: ExistingCustomerEOM | D34: -43.5 | E34: -43.5 | F34: 0 | G34: 0 | H34: 0 | I34: 0 | K34: 0 | L34: 0 | M34: 0 | N34: 0 | O34: unknown | P34: New | Q34: -77.5 | R34: 0 | S34: 77.5 | T34: 0 | U34: 0 | V34: 0 | W34: 0 | X34: 0 | Y34: 1402 | Z34: 1402 | AA34: Monthly | AB34: Monthly | AC34: HaPat | AD34: HaPat | AE34: 0 | AF34: 0 | AG34: 0 | AH34: 0 | AI34: =W34+ Y34+D34+H34 -> 1358.5 | AJ34: =X34+Z34+E34+I34 -> 1358.5 | AK34: =IF(AI34=0,AJ34,0) -> 0 | AL34: =IF(AND(AI34>0,AJ34>AI34),AJ34-AI34,0) -> 0 | AM34: =IF(AI34=AJ34,AJ34,0) -> 1358.5 | AN34: =IF(AJ34=0,AI34,0) -> 0 | AO34: =IF(AND(AJ34>0,AJ34<AI34),AI34-AJ34,0) -> 0 | AP34: US-Accounts Receivable | AQ34: 119118 | AR34: 0 | AS34: 0
A35: tristaterigging | B35: ExistingCustomerEOM | C35: ExistingCustomerEOM | D35: 0 | E35: 0 | F35: 0 | G35: 0 | H35: 0 | I35: 0 | K35: 0 | L35: 0 | M35: 4 | N35: 4 | O35: New | P35: New | Q35: 0 | R35: 0 | S35: 0 | T35: 0 | U35: 0 | V35: 0 | W35: 0 | X35: 0 | Y35: 614 | Z35: 565 | AA35: Monthly | AB35: Monthly | AC35: HaPat | AD35: HaPat | AE35: 0 | AF35: 0 | AG35: 11 | AH35: 10 | AI35: =W35+ Y35+D35+H35 -> 614 | AJ35: =X35+Z35+E35+I35 -> 565 | AK35: =IF(AI35=0,AJ35,0) -> 0 | AL35: =IF(AND(AI35>0,AJ35>AI35),AJ35-AI35,0) -> 0 | AM35: =IF(AI35=AJ35,AJ35,0) -> 0 | AN35: =IF(AJ35=0,AI35,0) -> 0 | AO35: =IF(AND(AJ35>0,AJ35<AI35),AI35-AJ35,0) -> 49 | AP35: US-Accounts Receivable | AQ35: 161002 | AR35: 0 | AS35: 0
A36: mobilitycityofcoloradosprings | B36: ExistingCustomerEOM | C36: ExistingCustomerEOM | D36: -2801.4 | E36: -2795.6 | F36: 0 | G36: 0 | H36: 0 | I36: 0 | K36: 0 | L36: 0 | M36: 4 | N36: 4 | O36: New | P36: New | Q36: -77.5 | R36: -232.5 | S36: 77.5 | T36: 232.5 | U36: 0 | V36: 0 | W36: 80 | X36: 0 | Y36: 14022.23 | Z36: 14085.93 | AA36: Monthly | AB36: Monthly | AC36: HaPat | AD36: HaPat | AE36: 0 | AF36: 0 | AG36: 1 | AH36: 1 | AI36: =W36+ Y36+D36+H36 -> 11300.83 | AJ36: =X36+Z36+E36+I36 -> 11290.33 | AK36: =IF(AI36=0,AJ36,0) -> 0 | AL36: =IF(AND(AI36>0,AJ36>AI36),AJ36-AI36,0) -> 0 | AM36: =IF(AI36=AJ36,AJ36,0) -> 0 | AN36: =IF(AJ36=0,AI36,0) -> 0 | AO36: =IF(AND(AJ36>0,AJ36<AI36),AI36-AJ36,0) -> 10.5 | AP36: US-Accounts Receivable | AQ36: 133608 | AR36: 0 | AS36: 0
A37: deccanfoods4 | B37: ExistingCustomerEOM | C37: ExistingCustomerEOM | D37: 0 | E37: 0 | F37: -31 | G37: 0 | H37: 0 | I37: 0 | K37: 0 | L37: 0 | M37: 4 | N37: 4 | O37: unknown | P37: New | Q37: 0 | R37: 0 | S37: 310 | T37: 0 | U37: 0 | V37: 0 | W37: 0 | X37: 0 | Y37: 508 | Z37: 508 | AA37: Monthly | AB37: Monthly | AC37: PhuPh | AD37: PhuPh | AE37: 0 | AF37: 0 | AG37: 3 | AH37: 3 | AI37: =W37+ Y37+D37+H37 -> 508 | AJ37: =X37+Z37+E37+I37 -> 508 | AK37: =IF(AI37=0,AJ37,0) -> 0 | AL37: =IF(AND(AI37>0,AJ37>AI37),AJ37-AI37,0) -> 0 | AM37: =IF(AI37=AJ37,AJ37,0) -> 508 | AN37: =IF(AJ37=0,AI37,0) -> 0 | AO37: =IF(AND(AJ37>0,AJ37<AI37),AI37-AJ37,0) -> 0 | AP37: US-Accounts Receivable | AQ37: 176596 | AR37: 0 | AS37: 0
A38: allfloridawallsystems2 | B38: ExistingCustomerEOM | C38: ExistingCustomerEOM | D38: 0 | E38: 0 | F38: 0 | G38: 0 | H38: 0 | I38: 0 | K38: 0 | L38: 0 | M38: 4 | N38: 4 | O38: New | P38: New | Q38: 0 | R38: 0 | S38: 0 | T38: 0 | U38: 0 | V38: 0 | W38: 0 | X38: 0 | Y38: 544 | Z38: 544 | AA38: Monthly | AB38: Monthly | AC38: HaPat | AD38: HaPat | AE38: 0 | AF38: 0 | AG38: 10 | AH38: 10 | AI38: =W38+ Y38+D38+H38 -> 544 | AJ38: =X38+Z38+E38+I38 -> 544 | AK38: =IF(AI38=0,AJ38,0) -> 0 | AL38: =IF(AND(AI38>0,AJ38>AI38),AJ38-AI38,0) -> 0 | AM38: =IF(AI38=AJ38,AJ38,0) -> 544 | AN38: =IF(AJ38=0,AI38,0) -> 0 | AO38: =IF(AND(AJ38>0,AJ38<AI38),AI38-AJ38,0) -> 0 | AP38: US-Accounts Receivable | AQ38: 186453 | AR38: 0 | AS38: 0
A39: templatepaulettedreher | B39: ExistingCustomerEOM | C39: ExistingCustomerEOM | D39: -273 | E39: -273 | F39: 0 | G39: 0 | H39: 0 | I39: 0 | K39: 0 | L39: 0 | M39: 6 | N39: 6 | O39: New | P39: New | Q39: 0 | R39: 0 | S39: 0 | T39: 0 | U39: 0 | V39: 0 | W39: 0 | X39: 0 | Y39: 273 | Z39: 273 | AA39: Monthly | AB39: Monthly | AC39: PhuPh | AD39: PhuPh | AE39: 0 | AF39: 0 | AG39: 4 | AH39: 4 | AI39: =W39+ Y39+D39+H39 -> 0 | AJ39: =X39+Z39+E39+I39 -> 0 | AK39: =IF(AI39=0,AJ39,0) -> 0 | AL39: =IF(AND(AI39>0,AJ39>AI39),AJ39-AI39,0) -> 0 | AM39: =IF(AI39=AJ39,AJ39,0) -> 0 | AN39: =IF(AJ39=0,AI39,0) -> 0 | AO39: =IF(AND(AJ39>0,AJ39<AI39),AI39-AJ39,0) -> 0 | AP39: US-Accounts Receivable | AQ39: 12018 | AR39: 0 | AS39: 0
A40: mehrcpa | B40: ExistingCustomerEOM | C40: ExistingCustomerEOM | D40: -25 | E40: -25 | F40: 0 | G40: 0 | H40: 0 | I40: 0 | K40: 0 | L40: 0 | M40: 1 | N40: 1 | O40: New | P40: New | Q40: 0 | R40: 0 | S40: 0 | T40: 0 | U40: 0 | V40: 0 | W40: 0 | X40: 0 | Y40: 25 | Z40: 25 | AA40: Monthly | AB40: Monthly | AC40: ShaLi | AD40: SukSa | AE40: 0 | AF40: 0 | AG40: 1 | AH40: 1 | AI40: =W40+ Y40+D40+H40 -> 0 | AJ40: =X40+Z40+E40+I40 -> 0 | AK40: =IF(AI40=0,AJ40,0) -> 0 | AL40: =IF(AND(AI40>0,AJ40>AI40),AJ40-AI40,0) -> 0 | AM40: =IF(AI40=AJ40,AJ40,0) -> 0 | AN40: =IF(AJ40=0,AI40,0) -> 0 | AO40: =IF(AND(AJ40>0,AJ40<AI40),AI40-AJ40,0) -> 0 | AP40: US-Accounts Receivable | AQ40: 14118 | AR40: 0 | AS40: 0
A41: reelwasterecycling | B41: ExistingCustomerEOM | C41: ExistingCustomerEOM | D41: 0 | E41: 0 | F41: -31 | G41: 0 | H41: 0 | I41: 0 | K41: 0 | L41: 0 | M41: 1 | N41: 1 | O41: Classic | P41: Classic | Q41: 0 | R41: 0 | S41: 310 | T41: 0 | U41: 0 | V41: 0 | W41: 310 | X41: 310 | Y41: 325 | Z41: 325 | AA41: Monthly | AB41: Monthly | AC41: ShaLi | AD41: ShaLi | AE41: 0 | AF41: 0 | AG41: 1 | AH41: 1 | AI41: =W41+ Y41+D41+H41 -> 635 | AJ41: =X41+Z41+E41+I41 -> 635 | AK41: =IF(AI41=0,AJ41,0) -> 0 | AL41: =IF(AND(AI41>0,AJ41>AI41),AJ41-AI41,0) -> 0 | AM41: =IF(AI41=AJ41,AJ41,0) -> 635 | AN41: =IF(AJ41=0,AI41,0) -> 0 | AO41: =IF(AND(AJ41>0,AJ41<AI41),AI41-AJ41,0) -> 0 | AP41: US-Accounts Receivable | AQ41: 14565 | AR41: 0 | AS41: 0
A42: valleypublishing | B42: ExistingCustomerEOM | C42: ExistingCustomerEOM | D42: 0 | E42: 0 | F42: 0 | G42: 0 | H42: 0 | I42: 0 | K42: 0 | L42: 0 | M42: 1 | N42: 1 | O42: Classic | P42: Classic | Q42: 0 | R42: 0 | S42: 0 | T42: 0 | U42: 0 | V42: 0 | W42: 25 | X42: 25 | Y42: 0 | Z42: 0 | AA42: Monthly | AB42: Monthly | AC42: JaiPa | AD42: JaiPa | AE42: 0 | AF42: 0 | AG42: 1 | AH42: 1 | AI42: =W42+ Y42+D42+H42 -> 25 | AJ42: =X42+Z42+E42+I42 -> 25 | AK42: =IF(AI42=0,AJ42,0) -> 0 | AL42: =IF(AND(AI42>0,AJ42>AI42),AJ42-AI42,0) -> 0 | AM42: =IF(AI42=AJ42,AJ42,0) -> 25 | AN42: =IF(AJ42=0,AI42,0) -> 0 | AO42: =IF(AND(AJ42>0,AJ42<AI42),AI42-AJ42,0) -> 0 | AP42: US-Accounts Receivable | AQ42: 15712 | AR42: 0 | AS42: 0
A43: louschcreations | B43: ExistingCustomerEOM | C43: ExistingCustomerEOM | D43: 0 | E43: 0 | F43: 0 | G43: 0 | H43: -8 | I43: -8 | K43: -72 | L43: -72 | M43: 1 | N43: 1 | O43: Classic | P43: Classic | Q43: 0 | R43: 0 | S43: 0 | T43: 0 | U43: 0 | V43: 0 | W43: 80 | X43: 80 | Y43: 0 | Z43: 0 | AA43: Prepay | AB43: Prepay | AC43: SukSa | AD43: SukSa | AE43: 0 | AF43: 0 | AG43: 2 | AH43: 2 | AI43: =W43+ Y43+D43+H43 -> 72 | AJ43: =X43+Z43+E43+I43 -> 72 | AK43: =IF(AI43=0,AJ43,0) -> 0 | AL43: =IF(AND(AI43>0,AJ43>AI43),AJ43-AI43,0) -> 0 | AM43: =IF(AI43=AJ43,AJ43,0) -> 72 | AN43: =IF(AJ43=0,AI43,0) -> 0 | AO43: =IF(AND(AJ43>0,AJ43<AI43),AI43-AJ43,0) -> 0 | AP43: US-Accounts Receivable | AQ43: 25891 | AR43: 0 | AS43: 0
A44: deltataudelta | B44: ExistingCustomerEOM | C44: ExistingCustomerEOM | D44: 0 | E44: 0 | F44: 0 | G44: 0 | H44: 0 | I44: 0 | K44: 0 | L44: 0 | M44: 3 | N44: 3 | O44: New | P44: New | Q44: 0 | R44: 0 | S44: 0 | T44: 0 | U44: 0 | V44: 0 | W44: 0 | X44: 0 | Y44: 172 | Z44: 172 | AA44: Monthly | AB44: Monthly | AC44: HaPat | AD44: HaPat | AE44: 0 | AF44: 0 | AG44: 4 | AH44: 4 | AI44: =W44+ Y44+D44+H44 -> 172 | AJ44: =X44+Z44+E44+I44 -> 172 | AK44: =IF(AI44=0,AJ44,0) -> 0 | AL44: =IF(AND(AI44>0,AJ44>AI44),AJ44-AI44,0) -> 0 | AM44: =IF(AI44=AJ44,AJ44,0) -> 172 | AN44: =IF(AJ44=0,AI44,0) -> 0 | AO44: =IF(AND(AJ44>0,AJ44<AI44),AI44-AJ44,0) -> 0 | AP44: US-Accounts Receivable | AQ44: 32842 | AR44: 0 | AS44: 0
A45: happe | B45: ExistingCustomerEOM | C45: ExistingCustomerEOM | D45: -60 | E45: -60 | F45: 0 | G45: 0 | H45: 0 | I45: 0 | K45: 0 | L45: 0 | M45: 1 | N45: 1 | O45: New | P45: New | Q45: 0 | R45: 0 | S45: 0 | T45: 0 | U45: 0 | V45: 0 | W45: 0 | X45: 0 | Y45: 60 | Z45: 60 | AA45: Monthly | AB45: Monthly | AC45: PhuPh | AD45: PhuPh | AE45: 0 | AF45: 0 | AG45: 1 | AH45: 1 | AI45: =W45+ Y45+D45+H45 -> 0 | AJ45: =X45+Z45+E45+I45 -> 0 | AK45: =IF(AI45=0,AJ45,0) -> 0 | AL45: =IF(AND(AI45>0,AJ45>AI45),AJ45-AI45,0) -> 0 | AM45: =IF(AI45=AJ45,AJ45,0) -> 0 | AN45: =IF(AJ45=0,AI45,0) -> 0 | AO45: =IF(AND(AJ45>0,AJ45<AI45),AI45-AJ45,0) -> 0 | AP45: US-Accounts Receivable | AQ45: 12066 | AR45: 0 | AS45: 0
... A73: beyonddetailedsolutions | B73: ExistingCustomerEOM | C73: ExistingCustomerEOM | D73: 0 | E73: 0 | F73: 0 | G73: 0 | H73: -3 | I73: -3 | K73: -25 | L73: -25 | M73: 1 | N73: 1 | O73: New | P73: New | Q73: 0 | R73: 0 | S73: 0 | T73: 0 | U73: 0 | V73: 0 | W73: 0 | X73: 0 | Y73: 28 | Z73: 28 | AA73: Prepay | AB73: Prepay | AC73: PhuPh | AD73: PhuPh | AE73: 0 | AF73: 0 | AG73: 1 | AH73: 1 | AI73: =W73+ Y73+D73+H73 -> 25 | AJ73: =X73+Z73+E73+I73 -> 25 | AK73: =IF(AI73=0,AJ73,0) -> 0 | AL73: =IF(AND(AI73>0,AJ73>AI73),AJ73-AI73,0) -> 0 | AM73: =IF(AI73=AJ73,AJ73,0) -> 25 | AN73: =IF(AJ73=0,AI73,0) -> 0 | AO73: =IF(AND(AJ73>0,AJ73<AI73),AI73-AJ73,0) -> 0 | AP73: US-Accounts Receivable | AQ73: 150052 | AR73: 0 | AS73: 0
A74: guardianangel | B74: ExistingCustomerEOM | C74: ExistingCustomerEOM | D74: 0 | E74: 0 | F74: 0 | G74: 0 | H74: 0 | I74: 0 | K74: 0 | L74: 0 | M74: 0 | N74: 0 | O74: unknown | P74: unknown | Q74: 0 | R74: 0 | S74: 0 | T74: 0 | U74: 0 | V74: 0 | W74: 0 | X74: 0 | Y74: 0 | Z74: 0 | AE74: 0 | AF74: 0 | AG74: 0 | AH74: 0 | AI74: =W74+ Y74+D74+H74 -> 0 | AJ74: =X74+Z74+E74+I74 -> 0 | AK74: =IF(AI74=0,AJ74,0) -> 0 | AL74: =IF(AND(AI74>0,AJ74>AI74),AJ74-AI74,0) -> 0 | AM74: =IF(AI74=AJ74,AJ74,0) -> 0 | AN74: =IF(AJ74=0,AI74,0) -> 0 | AO74: =IF(AND(AJ74>0,AJ74<AI74),AI74-AJ74,0) -> 0 | AP74: US-Accounts Receivable | AQ74: 150132 | AR74: 0 | AS74: 0
A75: lafittesseafood | B75: ExistingCustomerEOM | C75: ExistingCustomerEOM | D75: 0 | E75: 0 | F75: 0 | G75: 0 | H75: -15 | I75: -15 | K75: 1034 | L75: -94 | M75: 5 | N75: 5 | O75: New | P75: New | Q75: 0 | R75: 0 | S75: 0 | T75: 0 | U75: 0 | V75: 0 | W75: 0 | X75: 0 | Y75: 109 | Z75: 109 | AA75: Prepay | AB75: Prepay | AC75: ShaLi | AD75: SukSa | AE75: 0 | AF75: 0 | AG75: 3 | AH75: 3 | AI75: =W75+ Y75+D75+H75 -> 94 | AJ75: =X75+Z75+E75+I75 -> 94 | AK75: =IF(AI75=0,AJ75,0) -> 0 | AL75: =IF(AND(AI75>0,AJ75>AI75),AJ75-AI75,0) -> 0 | AM75: =IF(AI75=AJ75,AJ75,0) -> 94 | AN75: =IF(AJ75=0,AI75,0) -> 0 | AO75: =IF(AND(AJ75>0,AJ75<AI75),AI75-AJ75,0) -> 0 | AP75: US-Accounts Receivable | AQ75: 148736 | AR75: 0 | AS75: 0
A76: ebasesolutions2 | B76: ExistingCustomerEOM | C76: ExistingCustomerEOM | D76: 0 | E76: 0 | F76: 0 | G76: 0 | H76: 0 | I76: 0 | K76: 0 | L76: 0 | M76: 3 | N76: 3 | O76: New | P76: New | Q76: 0 | R76: 0 | S76: 0 | T76: 0 | U76: 0 | V76: 0 | W76: 0 | X76: 0 | Y76: 270 | Z76: 270 | AA76: Monthly | AB76: Monthly | AC76: MikPa | AD76: MikPa | AE76: 0 | AF76: 0 | AG76: 6 | AH76: 6 | AI76: =W76+ Y76+D76+H76 -> 270 | AJ76: =X76+Z76+E76+I76 -> 270 | AK76: =IF(AI76=0,AJ76,0) -> 0 | AL76: =IF(AND(AI76>0,AJ76>AI76),AJ76-AI76,0) -> 0 | AM76: =IF(AI76=AJ76,AJ76,0) -> 270 | AN76: =IF(AJ76=0,AI76,0) -> 0 | AO76: =IF(AND(AJ76>0,AJ76<AI76),AI76-AJ76,0) -> 0 | AP76: CAN-Accounts Receivable | AQ76: 151557 | AR76: 0 | AS76: 0
A77: bandkmurphyplumbingheatingandcoolingllc | B77: ExistingCustomerEOM | C77: ExistingCustomerEOM | D77: 0 | E77: 0 | F77: 0 | G77: 0 | H77: -14 | I77: -14 | K77: -124 | L77: -124 | M77: 3 | N77: 3 | O77: unknown | P77: unknown | Q77: 0 | R77: 0 | S77: 465 | T77: 77.5 | U77: 0 | V77: 0 | W77: 0 | X77: 0 | Y77: 138 | Z77: 138 | AA77: Prepay | AB77: Prepay | AC77: JaiPa | AD77: JaiPa | AE77: 0 | AF77: 0 | AG77: 3 | AH77: 3 | AI77: =W77+ Y77+D77+H77 -> 124 | AJ77: =X77+Z77+E77+I77 -> 124 | AK77: =IF(AI77=0,AJ77,0) -> 0 | AL77: =IF(AND(AI77>0,AJ77>AI77),AJ77-AI77,0) -> 0 | AM77: =IF(AI77=AJ77,AJ77,0) -> 124 | AN77: =IF(AJ77=0,AI77,0) -> 0 | AO77: =IF(AND(AJ77>0,AJ77<AI77),AI77-AJ77,0) -> 0 | AP77: US-Accounts Receivable | AQ77: 152999 | AR77: 0 | AS77: 0
A78: bramattcomputingltd | B78: ExistingCustomerEOM | C78: ExistingCustomerEOM | D78: 0 | E78: 0 | F78: 0 | G78: 0 | H78: -31.7 | I78: -31.7 | K78: -285.3 | L78: -285.3 | M78: 5 | N78: 5 | O78: New | P78: New | Q78: 0 | R78: 0 | S78: 0 | T78: 0 | U78: 0 | V78: 0 | W78: 0 | X78: 0 | Y78: 317 | Z78: 317 | AA78: Prepay | AB78: Prepay | AC78: HaPat | AD78: HaPat | AE78: 0 | AF78: 0 | AG78: 5 | AH78: 5 | AI78: =W78+ Y78+D78+H78 -> 285.3 | AJ78: =X78+Z78+E78+I78 -> 285.3 | AK78: =IF(AI78=0,AJ78,0) -> 0 | AL78: =IF(AND(AI78>0,AJ78>AI78),AJ78-AI78,0) -> 0 | AM78: =IF(AI78=AJ78,AJ78,0) -> 285.3 | AN78: =IF(AJ78=0,AI78,0) -> 0 | AO78: =IF(AND(AJ78>0,AJ78<AI78),AI78-AJ78,0) -> 0 | AP78: US-Accounts Receivable | AQ78: 152961 | AR78: 0 | AS78: 0
A79: beaconseed | B79: ExistingCustomerEOM | C79: ExistingCustomerEOM | D79: 0 | E79: 0 | F79: 0 | G79: 0 | H79: 0 | I79: 0 | K79: 0 | L79: 0 | M79: 3 | N79: 3 | O79: New | P79: New | Q79: 0 | R79: 0 | S79: 0 | T79: 0 | U79: 0 | V79: 0 | W79: 0 | X79: 0 | Y79: 147 | Z79: 147 | AA79: Monthly | AB79: Monthly | AC79: SukSa | AD79: SukSa | AE79: 0 | AF79: 0 | AG79: 3 | AH79: 3 | AI79: =W79+ Y79+D79+H79 -> 147 | AJ79: =X79+Z79+E79+I79 -> 147 | AK79: =IF(AI79=0,AJ79,0) -> 0 | AL79: =IF(AND(AI79>0,AJ79>AI79),AJ79-AI79,0) -> 0 | AM79: =IF(AI79=AJ79,AJ79,0) -> 147 | AN79: =IF(AJ79=0,AI79,0) -> 0 | AO79: =IF(AND(AJ79>0,AJ79<AI79),AI79-AJ79,0) -> 0 | AP79: US-Accounts Receivable | AQ79: 152970 | AR79: 0 | AS79: 0
A80: wtidistributioninc | B80: ExistingCustomerEOM | C80: ExistingCustomerEOM | D80: 0 | E80: 0 | F80: 0 | G80: 0 | H80: -4 | I80: -4 | K80: -36 | L80: -36 | M80: 2 | N80: 2 | O80: New | P80: New | Q80: 0 | R80: 0 | S80: 0 | T80: 0 | U80: 0 | V80: 0 | W80: 0 | X80: 0 | Y80: 40 | Z80: 40 | AA80: Prepay | AB80: Prepay | AC80: RafSy | AD80: RafSy | AE80: 0 | AF80: 0 | AG80: 1 | AH80: 1 | AI80: =W80+ Y80+D80+H80 -> 36 | AJ80: =X80+Z80+E80+I80 -> 36 | AK80: =IF(AI80=0,AJ80,0) -> 0 | AL80: =IF(AND(AI80>0,AJ80>AI80),AJ80-AI80,0) -> 0 | AM80: =IF(AI80=AJ80,AJ80,0) -> 36 | AN80: =IF(AJ80=0,AI80,0) -> 0 | AO80: =IF(AND(AJ80>0,AJ80<AI80),AI80-AJ80,0) -> 0 | AP80: US-Accounts Receivable | AQ80: 154920 | AR80: 0 | AS80: 0
A81: colonyroofing | B81: ExistingCustomerEOM | C81: ExistingCustomerEOM | D81: 0 | E81: 0 | F81: 0 | G81: 0 | H81: 0 | I81: 0 | K81: 0 | L81: 0 | M81: 3 | N81: 3 | O81: New | P81: New | Q81: 0 | R81: 0 | S81: 0 | T81: 0 | U81: 0 | V81: 0 | W81: 0 | X81: 0 | Y81: 322 | Z81: 322 | AA81: Monthly | AB81: Monthly | AC81: MikPa | AD81: MikPa | AE81: 0 | AF81: 0 | AG81: 7 | AH81: 7 | AI81: =W81+ Y81+D81+H81 -> 322 | AJ81: =X81+Z81+E81+I81 -> 322 | AK81: =IF(AI81=0,AJ81,0) -> 0 | AL81: =IF(AND(AI81>0,AJ81>AI81),AJ81-AI81,0) -> 0 | AM81: =IF(AI81=AJ81,AJ81,0) -> 322 | AN81: =IF(AJ81=0,AI81,0) -> 0 | AO81: =IF(AND(AJ81>0,AJ81<AI81),AI81-AJ81,0) -> 0 | AP81: US-Accounts Receivable | AQ81: 156444 | AR81: 0 | AS81: 0
A82: pioneersourcingsolutionsllc | B82: ExistingCustomerEOM | C82: ExistingCustomerEOM | D82: 0 | E82: 0 | F82: 0 | G82: 0 | H82: -3 | I82: -3 | K82: 275 | L82: -25 | M82: 1 | N82: 1 | O82: New | P82: New | Q82: 0 | R82: 0 | S82: 0 | T82: 0 | U82: 0 | V82: 0 | W82: 0 | X82: 0 | Y82: 28 | Z82: 28 | AA82: Prepay | AB82: Prepay | AC82: RafSy | AD82: RafSy | AE82: 0 | AF82: 0 | AG82: 1 | AH82: 1 | AI82: =W82+ Y82+D82+H82 -> 25 | AJ82: =X82+Z82+E82+I82 -> 25 | AK82: =IF(AI82=0,AJ82,0) -> 0 | AL82: =IF(AND(AI82>0,AJ82>AI82),AJ82-AI82,0) -> 0 | AM82: =IF(AI82=AJ82,AJ82,0) -> 25 | AN82: =IF(AJ82=0,AI82,0) -> 0 | AO82: =IF(AND(AJ82>0,AJ82<AI82),AI82-AJ82,0) -> 0 | AP82: US-Accounts Receivable | AQ82: 158737 | AR82: 0 | AS82: 0
A83: jdshouseoftrophies | B83: ExistingCustomerEOM | C83: ExistingCustomerEOM | D83: 0 | E83: 0 | F83: 0 | G83: 0 | H83: 0 | I83: 0 | K83: 0 | L83: 0 | M83: 3 | N83: 3 | O83: New | P83: New | Q83: 0 | R83: 0 | S83: 0 | T83: 0 | U83: 0 | V83: 0 | W83: 0 | X83: 0 | Y83: 196 | Z83: 196 | AA83: Monthly | AB83: Monthly | AC83: PhuPh | AD83: PhuPh | AE83: 0 | AF83: 0 | AG83: 4 | AH83: 4 | AI83: =W83+ Y83+D83+H83 -> 196 | AJ83: =X83+Z83+E83+I83 -> 196 | AK83: =IF(AI83=0,AJ83,0) -> 0 | AL83: =IF(AND(AI83>0,AJ83>AI83),AJ83-AI83,0) -> 0 | AM83: =IF(AI83=AJ83,AJ83,0) -> 196 | AN83: =IF(AJ83=0,AI83,0) -> 0 | AO83: =IF(AND(AJ83>0,AJ83<AI83),AI83-AJ83,0) -> 0 | AP83: US-Accounts Receivable | AQ83: 158724 | AR83: 0 | AS83: 0
A84: finelinecreativeartscenter | B84: ExistingCustomerEOM | C84: ExistingCustomerEOM | D84: 0 | E84: 0 | F84: 0 | G84: 0 | H84: -5.6 | I84: -5.6 | K84: 554.4 | L84: -50.4 | M84: 1 | N84: 1 | O84: New | P84: New | Q84: 0 | R84: 0 | S84: 0 | T84: 0 | U84: 0 | V84: 0 | W84: 0 | X84: 0 | Y84: 56 | Z84: 56 | AA84: Prepay | AB84: Prepay | AC84: RafSy | AD84: RafSy | AE84: 0 | AF84: 0 | AG84: 2 | AH84: 2 | AI84: =W84+ Y84+D84+H84 -> 50.4 | AJ84: =X84+Z84+E84+I84 -> 50.4 | AK84: =IF(AI84=0,AJ84,0) -> 0 | AL84: =IF(AND(AI84>0,AJ84>AI84),AJ84-AI84,0) -> 0 | AM84: =IF(AI84=AJ84,AJ84,0) -> 50.4 | AN84: =IF(AJ84=0,AI84,0) -> 0 | AO84: =IF(AND(AJ84>0,AJ84<AI84),AI84-AJ84,0) -> 0 | AP84: US-Accounts Receivable | AQ84: 158733 | AR84: 0 | AS84: 0
A85: casanapleshomewatch | B85: ExistingCustomerEOM | C85: ExistingCustomerEOM | D85: 0 | E85: 0 | F85: 0 | G85: 0 | H85: 0 | I85: 0 | K85: 0 | L85: 0 | M85: 1 | N85: 1 | O85: New | P85: New | Q85: 0 | R85: 0 | S85: 0 | T85: 0 | U85: 0 | V85: 0 | W85: 0 | X85: 0 | Y85: 28 | Z85: 28 | AA85: Monthly | AB85: Monthly | AC85: PhuPh | AD85: PhuPh | AE85: 0 | AF85: 0 | AG85: 1 | AH85: 1 | AI85: =W85+ Y85+D85+H85 -> 28 | AJ85: =X85+Z85+E85+I85 -> 28 | AK85: =IF(AI85=0,AJ85,0) -> 0 | AL85: =IF(AND(AI85>0,AJ85>AI85),AJ85-AI85,0) -> 0 | AM85: =IF(AI85=AJ85,AJ85,0) -> 28 | AN85: =IF(AJ85=0,AI85,0) -> 0 | AO85: =IF(AND(AJ85>0,AJ85<AI85),AI85-AJ85,0) -> 0 | AP85: US-Accounts Receivable | AQ85: 159752 | AR85: 0 | AS85: 0
...

Sheet NRR By Customer
A1: Start of Month | B1: Start of Month | C1: Start of Month | D1: Cancellation | E1: Cancellation | F1: Cancellation | G1: Downgrades | H1: Downgrades | I1: Downgrades | J1: Expansion | K1: Expansion | L1: Expansion | M1: New ARR | N1: New ARR | O1: New ARR | P1: Other | Q1: Other | R1: Other | S1: OtherChurn | T1: OtherChurn | U1: OtherChurn | V1: Count | W1: Count | X1: Count
A2: US-Accounts Receivable | B2: CAN-Accounts Receivable | C2: UK-Accounts Receivable | D2: US-Accounts Receivable | E2: CAN-Accounts Receivable | F2: UK-Accounts Receivable | G2: US-Accounts Receivable | H2: CAN-Accounts Receivable | I2: UK-Accounts Receivable | J2: US-Accounts Receivable | K2: CAN-Accounts Receivable | L2: UK-Accounts Receivable | M2: US-Accounts Receivable | N2: CAN-Accounts Receivable | O2: UK-Accounts Receivable | P2: US-Accounts Receivable | Q2: CAN-Accounts Receivable | R2: UK-Accounts Receivable | S2: US-Accounts Receivable | T2: CAN-Accounts Receivable | U2: UK-Accounts Receivable | V2: US-Accounts Receivable | W2: CAN-Accounts Receivable | X2: UK-Accounts Receivable
A3: =SUMIFS(Customers!AI:AI,Customers!AP:AP,A$2) -> 718226.91 | B3: =SUMIFS(Customers!AI:AI,Customers!AP:AP,B$2) -> 80784.68 | C3: =SUMIFS(Customers!AI:AI,Customers!AP:AP,C$2) -> 0 | D3: =SUMIFS(Customers!AN:AN,Customers!AP:AP,D$2)-S3 -> 10015.3 | E3: =SUMIFS(Customers!AN:AN,Customers!AP:AP,E$2)-T3 -> 709 | F3: =SUMIFS(Customers!AN:AN,Customers!AP:AP,F$2)-U3 -> 0 | G3: =SUMIFS(Customers!AO:AO,Customers!AP:AP,G$2) -> 13540.54 | H3: =SUMIFS(Customers!AO:AO,Customers!AP:AP,H$2) -> 1492.25 | I3: =SUMIFS(Customers!AO:AO,Customers!AP:AP,I$2) -> 0 | J3: =SUMIFS(Customers!AL:AL,Customers!AP:AP,J$2) -> 12539.4 | K3: =SUMIFS(Customers!AL:AL,Customers!AP:AP,K$2) -> 2181.73 | L3: =SUMIFS(Customers!AL:AL,Customers!AP:AP,L$2) -> 0 | M3: =SUMIFS(Customers!AK:AK,Customers!AP:AP,M$2)-P3 -> 12223.05 | N3: =SUMIFS(Customers!AK:AK,Customers!AP:AP,N$2)-Q3 -> 947 | O3: =SUMIFS(Customers!AK:AK,Customers!AP:AP,O$2)-R3 -> 0 | P3: =SUMIFS(Customers!AS:AS,Customers!AP:AP,P$2) -> 10316.75 | Q3: =SUMIFS(Customers!AS:AS,Customers!AP:AP,Q$2) -> 0 | R3: =SUMIFS(Customers!AS:AS,Customers!AP:AP,R$2) -> 0 | S3: =SUMIFS(Customers!AR:AR,Customers!AP:AP,P$2) -> 10354 | T3: =SUMIFS(Customers!AR:AR,Customers!AP:AP,Q$2) -> 0 | U3: =SUMIFS(Customers!AR:AR,Customers!AP:AP,R$2) -> 0 | V3: =COUNTIFS(Customers!Z:Z, ">0",Customers!AP:AP,V$2) -> 3009 | W3: =COUNTIFS(Customers!Z:Z, ">0",Customers!AP:AP,W$2) -> 393 | X3: =COUNTIFS(Customers!Z:Z, ">0",Customers!AP:AP,X$2) -> 0
A5: =SUM(A3:C3) -> 799011.59 | D5: =SUM(D3:F3) -> 10724.3 | G5: =SUM(G3:I3) -> 15032.79 | J5: =SUM(J3:L3) -> 14721.13 | M5: =SUM(M3:O3) -> 13170.05 | P5: =SUM(P3:R3) -> 10316.75 | S5: =SUM(S3:U3) -> 10354 | V5: =SUM(V3:X3) -> 3402 | Y5: =A5+J5+M5+P5-D5-G5-S5 -> 801108.43

Sheet Accounts
A1: CompanyAccount | B1: CustomerGroupingPeriod1 | C1: CustomerGroupingPeriod2 | D1: DiscountOtherSaaSPeriod1 | E1: DiscountOtherSaaSPeriod2 | F1: DiscountOtherPSPeriod1 | G1: DiscountOtherPSPeriod2 | H1: DiscountPrepayPortionPeriod1 | I1: DiscountPrepayPortionPeriod2 | J1: InvoiceGrouping | K1: LiabilityPortionPeriod1 | L1: LiabilityPortionPeriod2 | M1: PackPaidCountPeriod1 | N1: PackPaidCountPeriod2 | O1: PlatformTogglePeriod1 | P1: PlatformTogglePeriod2 | Q1: PSExpenseAmountPeriod1 | R1: PSExpenseAmountPeriod2 | S1: PSIncomeAmountPeriod1 | T1: PSIncomeAmountPeriod2 | U1: SaasExpensePeriod1 | V1: SaasExpensePeriod2 | W1: SaaSIncomeAmountClassicPeriod1 | X1: SaaSIncomeAmountClassicPeriod2 | Y1: SaaSIncomeAmountNewPeriod1 | Z1: SaaSIncomeAmountNewPeriod2 | AA1: SaaSPayTypePeriod1 | AB1: SaaSPayTypePeriod2 | AC1: SalesRepSaaSPeriod1 | AD1: SalesRepSaaSPeriod2 | AE1: UncategorizedPortionPeriod1 | AF1: UncategorizedPortionPeriod2 | AG1: UserPaidCountPeriod1 | AH1: UserPaidCountPeriod2 | AI1: SaaSNetPeriod1 | AJ1: SaaSNetPeriod2 | AK1: SaaSExpandNew | AL1: SaaSExpansionUp | AM1: SaaSNoChange | AN1: SaaSContractionCancel | AO1: SaaSContractionDown | AP1: Currency | AQ1: CustomerRecordID | AR1: PrepPayExpiryPeriod1 | AS1: PrepPayExpiryPeriod2
A2: freedupsolutions | B2: ExistingCustomerEOM | C2: ExistingCustomerEOM | D2: -45 | E2: -45 | F2: 0 | G2: 0 | H2: 0 | I2: 0 | K2: 0 | L2: 0 | M2: 3 | N2: 3 | O2: New | P2: New | Q2: 0 | R2: 0 | S2: 0 | T2: 0 | U2: 0 | V2: 0 | W2: 0 | X2: 0 | Y2: 45 | Z2: 45 | AA2: Monthly | AB2: Monthly | AC2: ShaLi | AD2: ShaLi | AE2: 0 | AF2: 0 | AG2: 1 | AH2: 1 | AI2: =W2+ Y2+D2+H2 -> 0 | AJ2: =X2+Z2+E2+I2 -> 0 | AK2: =IF(AI2=0,AJ2,0) -> 0 | AL2: =IF(AND(AI2>0,AJ2>AI2),AJ2-AI2,0) -> 0 | AM2: =IF(AI2=AJ2,AJ2,0) -> 0 | AN2: =IF(AJ2=0,AI2,0) -> 0 | AO2: =IF(AND(AJ2>0,AJ2<AI2),AI2-AJ2,0) -> 0 | AP2: US-Accounts Receivable | AQ2: 4271 | AR2: 0 | AS2: 0
A3: therylangroupllc | B3: ExistingCustomerEOM | C3: ExistingCustomerEOM | D3: -40 | E3: -40 | F3: 0 | G3: 0 | H3: 0 | I3: 0 | K3: 0 | L3: 0 | M3: 1 | N3: 1 | O3: Classic | P3: Classic | Q3: 0 | R3: 0 | S3: 0 | T3: 0 | U3: 0 | V3: 0 | W3: 40 | X3: 40 | Y3: 0 | Z3: 0 | AA3: Monthly | AB3: Monthly | AC3: PhuPh | AD3: PhuPh | AE3: 0 | AF3: 0 | AG3: 1 | AH3: 1 | AI3: =W3+ Y3+D3+H3 -> 0 | AJ3: =X3+Z3+E3+I3 -> 0 | AK3: =IF(AI3=0,AJ3,0) -> 0 | AL3: =IF(AND(AI3>0,AJ3>AI3),AJ3-AI3,0) -> 0 | AM3: =IF(AI3=AJ3,AJ3,0) -> 0 | AN3: =IF(AJ3=0,AI3,0) -> 0 | AO3: =IF(AND(AJ3>0,AJ3<AI3),AI3-AJ3,0) -> 0 | AP3: US-Accounts Receivable | AQ3: 11547 | AR3: 0 | AS3: 0
A4: TemplateHermanBaptist | B4: ExistingCustomerEOM | C4: ExistingCustomerEOM | D4: -40 | E4: -40 | F4: 0 | G4: 0 | H4: 0 | I4: 0 | K4: 0 | L4: 0 | M4: 1 | N4: 1 | O4: Classic | P4: Classic | Q4: 0 | R4: 0 | S4: 0 | T4: 0 | U4: 0 | V4: 0 | W4: 40 | X4: 40 | Y4: 0 | Z4: 0 | AA4: Monthly | AB4: Monthly | AC4: PhuPh | AD4: PhuPh | AE4: 0 | AF4: 0 | AG4: 1 | AH4: 1 | AI4: =W4+ Y4+D4+H4 -> 0 | AJ4: =X4+Z4+E4+I4 -> 0 | AK4: =IF(AI4=0,AJ4,0) -> 0 | AL4: =IF(AND(AI4>0,AJ4>AI4),AJ4-AI4,0) -> 0 | AM4: =IF(AI4=AJ4,AJ4,0) -> 0 | AN4: =IF(AJ4=0,AI4,0) -> 0 | AO4: =IF(AND(AJ4>0,AJ4<AI4),AI4-AJ4,0) -> 0 | AP4: US-Accounts Receivable | AQ4: 11547 | AR4: 0 | AS4: 0
A5: atlanticgraphics | B5: ExistingCustomerEOM | C5: ExistingCustomerEOM | D5: 0 | E5: 0 | F5: 0 | G5: 0 | H5: 0 | I5: 0 | K5: 0 | L5: 0 | M5: 3 | N5: 3 | O5: New | P5: New | Q5: 0 | R5: 0 | S5: 0 | T5: 0 | U5: 0 | V5: 0 | W5: 0 | X5: 0 | Y5: 365 | Z5: 365 | AA5: Monthly | AB5: Monthly | AC5: PhuPh | AD5: PhuPh | AE5: 0 | AF5: 0 | AG5: 9 | AH5: 9 | AI5: =W5+ Y5+D5+H5 -> 365 | AJ5: =X5+Z5+E5+I5 -> 365 | AK5: =IF(AI5=0,AJ5,0) -> 0 | AL5: =IF(AND(AI5>0,AJ5>AI5),AJ5-AI5,0) -> 0 | AM5: =IF(AI5=AJ5,AJ5,0) -> 365 | AN5: =IF(AJ5=0,AI5,0) -> 0 | AO5: =IF(AND(AJ5>0,AJ5<AI5),AI5-AJ5,0) -> 0 | AP5: US-Accounts Receivable | AQ5: 63546 | AR5: 0 | AS5: 0
A6: rhinebeckaerodromemuseum | B6: ExistingCustomerEOM | C6: ExistingCustomerEOM | D6: 0 | E6: 0 | F6: 0 | G6: 0 | H6: 0 | I6: 0 | K6: 0 | L6: 0 | M6: 1 | N6: 1 | O6: New | P6: New | Q6: 0 | R6: 0 | S6: 0 | T6: 0 | U6: 0 | V6: 0 | W6: 0 | X6: 0 | Y6: 28 | Z6: 28 | AA6: Monthly | AB6: Monthly | AC6: SukSa | AD6: SukSa | AE6: 0 | AF6: 0 | AG6: 1 | AH6: 1 | AI6: =W6+ Y6+D6+H6 -> 28 | AJ6: =X6+Z6+E6+I6 -> 28 | AK6: =IF(AI6=0,AJ6,0) -> 0 | AL6: =IF(AND(AI6>0,AJ6>AI6),AJ6-AI6,0) -> 0 | AM6: =IF(AI6=AJ6,AJ6,0) -> 28 | AN6: =IF(AJ6=0,AI6,0) -> 0 | AO6: =IF(AND(AJ6>0,AJ6<AI6),AI6-AJ6,0) -> 0 | AP6: US-Accounts Receivable | AQ6: 79741 | AR6: 0 | AS6: 0
A7: petersammsequipmentltd | B7: ExistingCustomerEOM | C7: ExistingCustomerEOM | D7: 0 | E7: 0 | F7: 0 | G7: 0 | H7: -5 | I7: -5 | K7: -44 | L7: -44 | M7: 3 | N7: 3 | O7: New | P7: New | Q7: 0 | R7: 0 | S7: 0 | T7: 0 | U7: 0 | V7: 0 | W7: 0 | X7: 0 | Y7: 49 | Z7: 49 | AA7: Prepay | AB7: Prepay | AC7: RafSy | AD7: RafSy | AE7: 0 | AF7: 0 | AG7: 1 | AH7: 1 | AI7: =W7+ Y7+D7+H7 -> 44 | AJ7: =X7+Z7+E7+I7 -> 44 | AK7: =IF(AI7=0,AJ7,0) -> 0 | AL7: =IF(AND(AI7>0,AJ7>AI7),AJ7-AI7,0) -> 0 | AM7: =IF(AI7=AJ7,AJ7,0) -> 44 | AN7: =IF(AJ7=0,AI7,0) -> 0 | AO7: =IF(AND(AJ7>0,AJ7<AI7),AI7-AJ7,0) -> 0 | AP7: US-Accounts Receivable | AQ7: 93516 | AR7: 0 | AS7: 0
A8: nwseaport | B8: ExistingCustomerEOM | C8: ExistingCustomerEOM | D8: 0 | E8: 0 | F8: 0 | G8: 0 | H8: -3 | I8: -3 | K8: -25 | L8: -25 | M8: 1 | N8: 1 | O8: New | P8: New | Q8: 0 | R8: 0 | S8: 0 | T8: 0 | U8: 0 | V8: 0 | W8: 0 | X8: 0 | Y8: 28 | Z8: 28 | AA8: Prepay | AB8: Prepay | AC8: SukSa | AD8: SukSa | AE8: 0 | AF8: 0 | AG8: 1 | AH8: 1 | AI8: =W8+ Y8+D8+H8 -> 25 | AJ8: =X8+Z8+E8+I8 -> 25 | AK8: =IF(AI8=0,AJ8,0) -> 0 | AL8: =IF(AND(AI8>0,AJ8>AI8),AJ8-AI8,0) -> 0 | AM8: =IF(AI8=AJ8,AJ8,0) -> 25 | AN8: =IF(AJ8=0,AI8,0) -> 0 | AO8: =IF(AND(AJ8>0,AJ8<AI8),AI8-AJ8,0) -> 0 | AP8: US-Accounts Receivable | AQ8: 95174 | AR8: 0 | AS8: 0
A9: pbaccounting | B9: ExistingCustomerEOM | C9: ExistingCustomerEOM | D9: -37 | E9: -37 | F9: 0 | G9: 0 | H9: 0 | I9: 0 | K9: 0 | L9: 0 | M9: 2 | N9: 2 | O9: New | P9: New | Q9: 0 | R9: 0 | S9: 0 | T9: 0 | U9: 0 | V9: 0 | W9: 0 | X9: 0 | Y9: 37 | Z9: 37 | AA9: Monthly | AB9: Monthly | AC9: PhuPh | AD9: PhuPh | AE9: 0 | AF9: 0 | AG9: 1 | AH9: 1 | AI9: =W9+ Y9+D9+H9 -> 0 | AJ9: =X9+Z9+E9+I9 -> 0 | AK9: =IF(AI9=0,AJ9,0) -> 0 | AL9: =IF(AND(AI9>0,AJ9>AI9),AJ9-AI9,0) -> 0 | AM9: =IF(AI9=AJ9,AJ9,0) -> 0 | AN9: =IF(AJ9=0,AI9,0) -> 0 | AO9: =IF(AND(AJ9>0,AJ9<AI9),AI9-AJ9,0) -> 0 | AP9: US-Accounts Receivable | AQ9: 94821 | AR9: 0 | AS9: 0
A10: alerthomewatch | B10: ExistingCustomerEOM | C10: ExistingCustomerEOM | D10: 0 | E10: 0 | F10: 0 | G10: 0 | H10: 0 | I10: 0 | K10: 0 | L10: 0 | M10: 1 | N10: 1 | O10: New | P10: New | Q10: 0 | R10: 0 | S10: 0 | T10: 0 | U10: 0 | V10: 0 | W10: 0 | X10: 0 | Y10: 84 | Z10: 84 | AA10: Monthly | AB10: Monthly | AC10: PhuPh | AD10: PhuPh | AE10: 0 | AF10: 0 | AG10: 3 | AH10: 3 | AI10: =W10+ Y10+D10+H10 -> 84 | AJ10: =X10+Z10+E10+I10 -> 84 | AK10: =IF(AI10=0,AJ10,0) -> 0 | AL10: =IF(AND(AI10>0,AJ10>AI10),AJ10-AI10,0) -> 0 | AM10: =IF(AI10=AJ10,AJ10,0) -> 84 | AN10: =IF(AJ10=0,AI10,0) -> 0 | AO10: =IF(AND(AJ10>0,AJ10<AI10),AI10-AJ10,0) -> 0 | AP10: US-Accounts Receivable | AQ10: 96657 | AR10: 0 | AS10: 0
A11: themovingcompany | B11: ExistingCustomerEOM | C11: ExistingCustomerEOM | D11: 0 | E11: 0 | F11: 0 | G11: 0 | H11: -3 | I11: -3 | K11: -25 | L11: -25 | M11: 1 | N11: 1 | O11: New | P11: New | Q11: 0 | R11: 0 | S11: 0 | T11: 0 | U11: 0 | V11: 0 | W11: 0 | X11: 0 | Y11: 28 | Z11: 28 | AA11: Prepay | AB11: Prepay | AC11: JaiPa | AD11: JaiPa | AE11: 0 | AF11: 0 | AG11: 1 | AH11: 1 | AI11: =W11+ Y11+D11+H11 -> 25 | AJ11: =X11+Z11+E11+I11 -> 25 | AK11: =IF(AI11=0,AJ11,0) -> 0 | AL11: =IF(AND(AI11>0,AJ11>AI11),AJ11-AI11,0) -> 0 | AM11: =IF(AI11=AJ11,AJ11,0) -> 25 | AN11: =IF(AJ11=0,AI11,0) -> 0 | AO11: =IF(AND(AJ11>0,AJ11<AI11),AI11-AJ11,0) -> 0 | AP11: US-Accounts Receivable | AQ11: 97379 | AR11: 0 | AS11: 0
A12: innovativeenergy | B12: ExistingCustomerEOM | C12: ExistingCustomerEOM | D12: 0 | E12: 0 | F12: 0 | G12: 0 | H12: 0 | I12: 0 | K12: 0 | L12: 0 | M12: 3 | N12: 3 | O12: New | P12: New | Q12: 0 | R12: 0 | S12: 0 | T12: 0 | U12: 0 | V12: 0 | W12: 0 | X12: 0 | Y12: 343 | Z12: 343 | AA12: Monthly | AB12: Monthly | AC12: HaPat | AD12: HaPat | AE12: 0 | AF12: 0 | AG12: 7 | AH12: 7 | AI12: =W12+ Y12+D12+H12 -> 343 | AJ12: =X12+Z12+E12+I12 -> 343 | AK12: =IF(AI12=0,AJ12,0) -> 0 | AL12: =IF(AND(AI12>0,AJ12>AI12),AJ12-AI12,0) -> 0 | AM12: =IF(AI12=AJ12,AJ12,0) -> 343 | AN12: =IF(AJ12=0,AI12,0) -> 0 | AO12: =IF(AND(AJ12>0,AJ12<AI12),AI12-AJ12,0) -> 0 | AP12: US-Accounts Receivable | AQ12: 98394 | AR12: 0 | AS12: 0
A13: CarlsonConcierge | B13: ExistingCustomerEOM | C13: ExistingCustomerEOM | D13: -11.2 | E13: -11.2 | F13: 0 | G13: 0 | H13: 0 | I13: 0 | K13: 0 | L13: 0 | M13: 1 | N13: 1 | O13: New | P13: New | Q13: 0 | R13: 0 | S13: 0 | T13: 0 | U13: 0 | V13: 0 | W13: 0 | X13: 0 | Y13: 56 | Z13: 56 | AA13: Monthly | AB13: Monthly | AC13: PhuPh | AD13: PhuPh | AE13: 0 | AF13: 0 | AG13: 2 | AH13: 2 | AI13: =W13+ Y13+D13+H13 -> 44.8 | AJ13: =X13+Z13+E13+I13 -> 44.8 | AK13: =IF(AI13=0,AJ13,0) -> 0 | AL13: =IF(AND(AI13>0,AJ13>AI13),AJ13-AI13,0) -> 0 | AM13: =IF(AI13=AJ13,AJ13,0) -> 44.8 | AN13: =IF(AJ13=0,AI13,0) -> 0 | AO13: =IF(AND(AJ13>0,AJ13<AI13),AI13-AJ13,0) -> 0 | AP13: US-Accounts Receivable | AQ13: 86456 | AR13: 0 | AS13: 0
... A33: NewEnglandLanguageSchoolInc | B33: ExistingCustomerEOM | C33: ExistingCustomerEOM | D33: -5.6 | E33: -5.6 | F33: 0 | G33: 0 | H33: 0 | I33: 0 | K33: 0 | L33: 0 | M33: 1 | N33: 1 | O33: New | P33: New | Q33: 0 | R33: 0 | S33: 0 | T33: 0 | U33: 0 | V33: 0 | W33: 0 | X33: 0 | Y33: 28 | Z33: 28 | AA33: Monthly | AB33: Monthly | AC33: PhuPh | AD33: PhuPh | AE33: 0 | AF33: 0 | AG33: 1 | AH33: 1 | AI33: =W33+ Y33+D33+H33 -> 22.4 | AJ33: =X33+Z33+E33+I33 -> 22.4 | AK33: =IF(AI33=0,AJ33,0) -> 0 | AL33: =IF(AND(AI33>0,AJ33>AI33),AJ33-AI33,0) -> 0 | AM33: =IF(AI33=AJ33,AJ33,0) -> 22.4 | AN33: =IF(AJ33=0,AI33,0) -> 0 | AO33: =IF(AND(AJ33>0,AJ33<AI33),AI33-AJ33,0) -> 0 | AP33: US-Accounts Receivable | AQ33: 98759 | AR33: 0 | AS33: 0
A34: NovusFireProtectionConsultingInc | B34: ExistingCustomerEOM | C34: ExistingCustomerEOM | D34: 0 | E34: 0 | F34: 0 | G34: 0 | H34: 0 | I34: 0 | K34: 0 | L34: 0 | M34: 0 | N34: 0 | O34: unknown | P34: unknown | Q34: 0 | R34: 0 | S34: 0 | T34: 0 | U34: 0 | V34: 0 | W34: 0 | X34: 0 | Y34: 0 | Z34: 0 | AE34: 0 | AF34: 0 | AG34: 0 | AH34: 0 | AI34: =W34+ Y34+D34+H34 -> 0 | AJ34: =X34+Z34+E34+I34 -> 0 | AK34: =IF(AI34=0,AJ34,0) -> 0 | AL34: =IF(AND(AI34>0,AJ34>AI34),AJ34-AI34,0) -> 0 | AM34: =IF(AI34=AJ34,AJ34,0) -> 0 | AN34: =IF(AJ34=0,AI34,0) -> 0 | AO34: =IF(AND(AJ34>0,AJ34<AI34),AI34-AJ34,0) -> 0 | AP34: CAN-Accounts Receivable | AQ34: 85984 | AR34: 0 | AS34: 0
A35: BenShaffer | B35: ExistingCustomerEOM | C35: ExistingCustomerEOM | D35: -43.5 | E35: -43.5 | F35: 0 | G35: 0 | H35: 0 | I35: 0 | K35: 0 | L35: 0 | M35: 0 | N35: 0 | O35: unknown | P35: New | Q35: -77.5 | R35: 0 | S35: 77.5 | T35: 0 | U35: 0 | V35: 0 | W35: 0 | X35: 0 | Y35: 1402 | Z35: 1402 | AA35: Monthly | AB35: Monthly | AC35: HaPat | AD35: HaPat | AE35: 0 | AF35: 0 | AG35: 0 | AH35: 0 | AI35: =W35+ Y35+D35+H35 -> 1358.5 | AJ35: =X35+Z35+E35+I35 -> 1358.5 | AK35: =IF(AI35=0,AJ35,0) -> 0 | AL35: =IF(AND(AI35>0,AJ35>AI35),AJ35-AI35,0) -> 0 | AM35: =IF(AI35=AJ35,AJ35,0) -> 1358.5 | AN35: =IF(AJ35=0,AI35,0) -> 0 | AO35: =IF(AND(AJ35>0,AJ35<AI35),AI35-AJ35,0) -> 0 | AP35: US-Accounts Receivable | AQ35: 119118 | AR35: 0 | AS35: 0
A36: tristaterigging | B36: ExistingCustomerEOM | C36: ExistingCustomerEOM | D36: 0 | E36: 0 | F36: 0 | G36: 0 | H36: 0 | I36: 0 | K36: 0 | L36: 0 | M36: 4 | N36: 4 | O36: New | P36: New | Q36: 0 | R36: 0 | S36: 0 | T36: 0 | U36: 0 | V36: 0 | W36: 0 | X36: 0 | Y36: 614 | Z36: 565 | AA36: Monthly | AB36: Monthly | AC36: HaPat | AD36: HaPat | AE36: 0 | AF36: 0 | AG36: 11 | AH36: 10 | AI36: =W36+ Y36+D36+H36 -> 614 | AJ36: =X36+Z36+E36+I36 -> 565 | AK36: =IF(AI36=0,AJ36,0) -> 0 | AL36: =IF(AND(AI36>0,AJ36>AI36),AJ36-AI36,0) -> 0 | AM36: =IF(AI36=AJ36,AJ36,0) -> 0 | AN36: =IF(AJ36=0,AI36,0) -> 0 | AO36: =IF(AND(AJ36>0,AJ36<AI36),AI36-AJ36,0) -> 49 | AP36: US-Accounts Receivable | AQ36: 161002 | AR36: 0 | AS36: 0
A37: mobilitycityofcoloradosprings | B37: ExistingCustomerEOM | C37: ExistingCustomerEOM | D37: -49 | E37: -49 | F37: 0 | G37: 0 | H37: 0 | I37: 0 | K37: 0 | L37: 0 | M37: 3 | N37: 3 | O37: New | P37: New | Q37: 0 | R37: 0 | S37: 0 | T37: 0 | U37: 0 | V37: 0 | W37: 0 | X37: 0 | Y37: 245 | Z37: 245 | AA37: Monthly | AB37: Monthly | AC37: HaPat | AD37: HaPat | AE37: 0 | AF37: 0 | AG37: 5 | AH37: 5 | AI37: =W37+ Y37+D37+H37 -> 196 | AJ37: =X37+Z37+E37+I37 -> 196 | AK37: =IF(AI37=0,AJ37,0) -> 0 | AL37: =IF(AND(AI37>0,AJ37>AI37),AJ37-AI37,0) -> 0 | AM37: =IF(AI37=AJ37,AJ37,0) -> 196 | AN37: =IF(AJ37=0,AI37,0) -> 0 | AO37: =IF(AND(AJ37>0,AJ37<AI37),AI37-AJ37,0) -> 0 | AP37: US-Accounts Receivable | AQ37: 133608 | AR37: 0 | AS37: 0
A38: mobilitycityofcostalalabama | B38: ExistingCustomerEOM | C38: ExistingCustomerEOM | D38: -44.8 | E38: -49 | F38: 0 | G38: 0 | H38: 0 | I38: 0 | K38: 0 | L38: 0 | M38: 3 | N38: 3 | O38: New | P38: New | Q38: 0 | R38: 0 | S38: 0 | T38: 0 | U38: 0 | V38: 0 | W38: 0 | X38: 0 | Y38: 224 | Z38: 245 | AA38: Monthly | AB38: Monthly | AC38: HaPat | AD38: HaPat | AE38: 0 | AF38: 0 | AG38: 5 | AH38: 5 | AI38: =W38+ Y38+D38+H38 -> 179.2 | AJ38: =X38+Z38+E38+I38 -> 196 | AK38: =IF(AI38=0,AJ38,0) -> 0 | AL38: =IF(AND(AI38>0,AJ38>AI38),AJ38-AI38,0) -> 16.8 | AM38: =IF(AI38=AJ38,AJ38,0) -> 0 | AN38: =IF(AJ38=0,AI38,0) -> 0 | AO38: =IF(AND(AJ38>0,AJ38<AI38),AI38-AJ38,0) -> 0 | AP38: US-Accounts Receivable | AQ38: 133608 | AR38: 0 | AS38: 0
A39: deccanfoods4 | B39: ExistingCustomerEOM | C39: ExistingCustomerEOM | D39: 0 | E39: 0 | F39: -31 | G39: 0 | H39: 0 | I39: 0 | K39: 0 | L39: 0 | M39: 4 | N39: 4 | O39: unknown | P39: New | Q39: 0 | R39: 0 | S39: 310 | T39: 0 | U39: 0 | V39: 0 | W39: 0 | X39: 0 | Y39: 508 | Z39: 508 | AA39: Monthly | AB39: Monthly | AC39: PhuPh | AD39: PhuPh | AE39: 0 | AF39: 0 | AG39: 3 | AH39: 3 | AI39: =W39+ Y39+D39+H39 -> 508 | AJ39: =X39+Z39+E39+I39 -> 508 | AK39: =IF(AI39=0,AJ39,0) -> 0 | AL39: =IF(AND(AI39>0,AJ39>AI39),AJ39-AI39,0) -> 0 | AM39: =IF(AI39=AJ39,AJ39,0) -> 508 | AN39: =IF(AJ39=0,AI39,0) -> 0 | AO39: =IF(AND(AJ39>0,AJ39<AI39),AI39-AJ39,0) -> 0 | AP39: US-Accounts Receivable | AQ39: 176596 | AR39: 0 | AS39: 0
A40: allfloridawallsystems2 | B40: ExistingCustomerEOM | C40: ExistingCustomerEOM | D40: 0 | E40: 0 | F40: 0 | G40: 0 | H40: 0 | I40: 0 | K40: 0 | L40: 0 | M40: 4 | N40: 4 | O40: New | P40: New | Q40: 0 | R40: 0 | S40: 0 | T40: 0 | U40: 0 | V40: 0 | W40: 0 | X40: 0 | Y40: 544 | Z40: 544 | AA40: Monthly | AB40: Monthly | AC40: HaPat | AD40: HaPat | AE40: 0 | AF40: 0 | AG40: 10 | AH40: 10 | AI40: =W40+ Y40+D40+H40 -> 544 | AJ40: =X40+Z40+E40+I40 -> 544 | AK40: =IF(AI40=0,AJ40,0) -> 0 | AL40: =IF(AND(AI40>0,AJ40>AI40),AJ40-AI40,0) -> 0 | AM40: =IF(AI40=AJ40,AJ40,0) -> 544 | AN40: =IF(AJ40=0,AI40,0) -> 0 | AO40: =IF(AND(AJ40>0,AJ40<AI40),AI40-AJ40,0) -> 0 | AP40: US-Accounts Receivable | AQ40: 186453 | AR40: 0 | AS40: 0
A41: templatepaulettedreher | B41: ExistingCustomerEOM | C41: ExistingCustomerEOM | D41: -59 | E41: -59 | F41: 0 | G41: 0 | H41: 0 | I41: 0 | K41: 0 | L41: 0 | M41: 4 | N41: 4 | O41: New | P41: New | Q41: 0 | R41: 0 | S41: 0 | T41: 0 | U41: 0 | V41: 0 | W41: 0 | X41: 0 | Y41: 59 | Z41: 59 | AA41: Monthly | AB41: Monthly | AC41: PhuPh | AD41: PhuPh | AE41: 0 | AF41: 0 | AG41: 1 | AH41: 1 | AI41: =W41+ Y41+D41+H41 -> 0 | AJ41: =X41+Z41+E41+I41 -> 0 | AK41: =IF(AI41=0,AJ41,0) -> 0 | AL41: =IF(AND(AI41>0,AJ41>AI41),AJ41-AI41,0) -> 0 | AM41: =IF(AI41=AJ41,AJ41,0) -> 0 | AN41: =IF(AJ41=0,AI41,0) -> 0 | AO41: =IF(AND(AJ41>0,AJ41<AI41),AI41-AJ41,0) -> 0 | AP41: US-Accounts Receivable | AQ41: 12018 | AR41: 0 | AS41: 0
A42: mehrcpa | B42: ExistingCustomerEOM | C42: ExistingCustomerEOM | D42: -25 | E42: -25 | F42: 0 | G42: 0 | H42: 0 | I42: 0 | K42: 0 | L42: 0 | M42: 1 | N42: 1 | O42: New | P42: New | Q42: 0 | R42: 0 | S42: 0 | T42: 0 | U42: 0 | V42: 0 | W42: 0 | X42: 0 | Y42: 25 | Z42: 25 | AA42: Monthly | AB42: Monthly | AC42: ShaLi | AD42: SukSa | AE42: 0 | AF42: 0 | AG42: 1 | AH42: 1 | AI42: =W42+ Y42+D42+H42 -> 0 | AJ42: =X42+Z42+E42+I42 -> 0 | AK42: =IF(AI42=0,AJ42,0) -> 0 | AL42: =IF(AND(AI42>0,AJ42>AI42),AJ42-AI42,0) -> 0 | AM42: =IF(AI42=AJ42,AJ42,0) -> 0 | AN42: =IF(AJ42=0,AI42,0) -> 0 | AO42: =IF(AND(AJ42>0,AJ42<AI42),AI42-AJ42,0) -> 0 | AP42: US-Accounts Receivable | AQ42: 14118 | AR42: 0 | AS42: 0
A43: reelwasterecycling | B43: ExistingCustomerEOM | C43: ExistingCustomerEOM | D43: 0 | E43: 0 | F43: -31 | G43: 0 | H43: 0 | I43: 0 | K43: 0 | L43: 0 | M43: 1 | N43: 1 | O43: unknown | P43: Classic | Q43: 0 | R43: 0 | S43: 310 | T43: 0 | U43: 0 | V43: 0 | W43: 245 | X43: 245 | Y43: 325 | Z43: 325 | AA43: Monthly | AB43: Monthly | AC43: ShaLi | AD43: ShaLi | AE43: 0 | AF43: 0 | AG43: 8 | AH43: 8 | AI43: =W43+ Y43+D43+H43 -> 570 | AJ43: =X43+Z43+E43+I43 -> 570 | AK43: =IF(AI43=0,AJ43,0) -> 0 | AL43: =IF(AND(AI43>0,AJ43>AI43),AJ43-AI43,0) -> 0 | AM43: =IF(AI43=AJ43,AJ43,0) -> 570 | AN43: =IF(AJ43=0,AI43,0) -> 0 | AO43: =IF(AND(AJ43>0,AJ43<AI43),AI43-AJ43,0) -> 0 | AP43: US-Accounts Receivable | AQ43: 14565 | AR43: 0 | AS43: 0
A44: valleypublishing | B44: ExistingCustomerEOM | C44: ExistingCustomerEOM | D44: 0 | E44: 0 | F44: 0 | G44: 0 | H44: 0 | I44: 0 | K44: 0 | L44: 0 | M44: 1 | N44: 1 | O44: Classic | P44: Classic | Q44: 0 | R44: 0 | S44: 0 | T44: 0 | U44: 0 | V44: 0 | W44: 25 | X44: 25 | Y44: 0 | Z44: 0 | AA44: Monthly | AB44: Monthly | AC44: JaiPa | AD44: JaiPa | AE44: 0 | AF44: 0 | AG44: 1 | AH44: 1 | AI44: =W44+ Y44+D44+H44 -> 25 | AJ44: =X44+Z44+E44+I44 -> 25 | AK44: =IF(AI44=0,AJ44,0) -> 0 | AL44: =IF(AND(AI44>0,AJ44>AI44),AJ44-AI44,0) -> 0 | AM44: =IF(AI44=AJ44,AJ44,0) -> 25 | AN44: =IF(AJ44=0,AI44,0) -> 0 | AO44: =IF(AND(AJ44>0,AJ44<AI44),AI44-AJ44,0) -> 0 | AP44: US-Accounts Receivable | AQ44: 15712 | AR44: 0 | AS44: 0
A45: louschcreations | B45: ExistingCustomerEOM | C45: ExistingCustomerEOM | D45: 0 | E45: 0 | F45: 0 | G45: 0 | H45: -8 | I45: -8 | K45: -72 | L45: -72 | M45: 1 | N45: 1 | O45: Classic | P45: Classic | Q45: 0 | R45: 0 | S45: 0 | T45: 0 | U45: 0 | V45: 0 | W45: 80 | X45: 80 | Y45: 0 | Z45: 0 | AA45: Prepay | AB45: Prepay | AC45: SukSa | AD45: SukSa | AE45: 0 | AF45: 0 | AG45: 2 | AH45: 2 | AI45: =W45+ Y45+D45+H45 -> 72 | AJ45: =X45+Z45+E45+I45 -> 72 | AK45: =IF(AI45=0,AJ45,0) -> 0 | AL45: =IF(AND(AI45>0,AJ45>AI45),AJ45-AI45,0) -> 0 | AM45: =IF(AI45=AJ45,AJ45,0) -> 72 | AN45: =IF(AJ45=0,AI45,0) -> 0 | AO45: =IF(AND(AJ45>0,AJ45<AI45),AI45-AJ45,0) -> 0 | AP45: US-Accounts Receivable | AQ45: 25891 | AR45: 0 | AS45: 0
A46: deltataudelta | B46: ExistingCustomerEOM | C46: ExistingCustomerEOM | D46: 0 | E46: 0 | F46: 0 | G46: 0 | H46: 0 | I46: 0 | K46: 0 | L46: 0 | M46: 3 | N46: 3 | O46: New | P46: New | Q46: 0 | R46: 0 | S46: 0 | T46: 0 | U46: 0 | V46: 0 | W46: 0 | X46: 0 | Y46: 172 | Z46: 172 | AA46: Monthly | AB46: Monthly | AC46: HaPat | AD46: HaPat | AE46: 0 | AF46: 0 | AG46: 4 | AH46: 4 | AI46: =W46+ Y46+D46+H46 -> 172 | AJ46: =X46+Z46+E46+I46 -> 172 | AK46: =IF(AI46=0,AJ46,0) -> 0 | AL46: =IF(AND(AI46>0,AJ46>AI46),AJ46-AI46,0) -> 0 | AM46: =IF(AI46=AJ46,AJ46,0) -> 172 | AN46: =IF(AJ46=0,AI46,0) -> 0 | AO46: =IF(AND(AJ46>0,AJ46<AI46),AI46-AJ46,0) -> 0 | AP46: US-Accounts Receivable | AQ46: 32842 | AR46: 0 | AS46: 0
... A77: beyonddetailedsolutions | B77: ExistingCustomerEOM | C77: ExistingCustomerEOM | D77: 0 | E77: 0 | F77: 0 | G77: 0 | H77: -3 | I77: -3 | K77: -25 | L77: -25 | M77: 1 | N77: 1 | O77: New | P77: New | Q77: 0 | R77: 0 | S77: 0 | T77: 0 | U77: 0 | V77: 0 | W77: 0 | X77: 0 | Y77: 28 | Z77: 28 | AA77: Prepay | AB77: Prepay | AC77: PhuPh | AD77: PhuPh | AE77: 0 | AF77: 0 | AG77: 1 | AH77: 1 | AI77: =W77+ Y77+D77+H77 -> 25 | AJ77: =X77+Z77+E77+I77 -> 25 | AK77: =IF(AI77=0,AJ77,0) -> 0 | AL77: =IF(AND(AI77>0,AJ77>AI77),AJ77-AI77,0) -> 0 | AM77: =IF(AI77=AJ77,AJ77,0) -> 25 | AN77: =IF(AJ77=0,AI77,0) -> 0 | AO77: =IF(AND(AJ77>0,AJ77<AI77),AI77-AJ77,0) -> 0 | AP77: US-Accounts Receivable | AQ77: 150052 | AR77: 0 | AS77: 0
A78: guardianangel | B78: ExistingCustomerEOM | C78: ExistingCustomerEOM | D78: 0 | E78: 0 | F78: 0 | G78: 0 | H78: 0 | I78: 0 | K78: 0 | L78: 0 | M78: 0 | N78: 0 | O78: unknown | P78: unknown | Q78: 0 | R78: 0 | S78: 0 | T78: 0 | U78: 0 | V78: 0 | W78: 0 | X78: 0 | Y78: 0 | Z78: 0 | AE78: 0 | AF78: 0 | AG78: 0 | AH78: 0 | AI78: =W78+ Y78+D78+H78 -> 0 | AJ78: =X78+Z78+E78+I78 -> 0 | AK78: =IF(AI78=0,AJ78,0) -> 0 | AL78: =IF(AND(AI78>0,AJ78>AI78),AJ78-AI78,0) -> 0 | AM78: =IF(AI78=AJ78,AJ78,0) -> 0 | AN78: =IF(AJ78=0,AI78,0) -> 0 | AO78: =IF(AND(AJ78>0,AJ78<AI78),AI78-AJ78,0) -> 0 | AP78: US-Accounts Receivable | AQ78: 150132 | AR78: 0 | AS78: 0
A79: lafittesseafood | B79: ExistingCustomerEOM | C79: ExistingCustomerEOM | D79: 0 | E79: 0 | F79: 0 | G79: 0 | H79: -15 | I79: -15 | K79: 1034 | L79: -94 | M79: 5 | N79: 5 | O79: New | P79: New | Q79: 0 | R79: 0 | S79: 0 | T79: 0 | U79: 0 | V79: 0 | W79: 0 | X79: 0 | Y79: 109 | Z79: 109 | AA79: Prepay | AB79: Prepay | AC79: ShaLi | AD79: SukSa | AE79: 0 | AF79: 0 | AG79: 3 | AH79: 3 | AI79: =W79+ Y79+D79+H79 -> 94 | AJ79: =X79+Z79+E79+I79 -> 94 | AK79: =IF(AI79=0,AJ79,0) -> 0 | AL79: =IF(AND(AI79>0,AJ79>AI79),AJ79-AI79,0) -> 0 | AM79: =IF(AI79=AJ79,AJ79,0) -> 94 | AN79: =IF(AJ79=0,AI79,0) -> 0 | AO79: =IF(AND(AJ79>0,AJ79<AI79),AI79-AJ79,0) -> 0 | AP79: US-Accounts Receivable | AQ79: 148736 | AR79: 0 | AS79: 0
A80: ebasesolutions2 | B80: ExistingCustomerEOM | C80: ExistingCustomerEOM | D80: 0 | E80: 0 | F80: 0 | G80: 0 | H80: 0 | I80: 0 | K80: 0 | L80: 0 | M80: 3 | N80: 3 | O80: New | P80: New | Q80: 0 | R80: 0 | S80: 0 | T80: 0 | U80: 0 | V80: 0 | W80: 0 | X80: 0 | Y80: 270 | Z80: 270 | AA80: Monthly | AB80: Monthly | AC80: MikPa | AD80: MikPa | AE80: 0 | AF80: 0 | AG80: 6 | AH80: 6 | AI80: =W80+ Y80+D80+H80 -> 270 | AJ80: =X80+Z80+E80+I80 -> 270 | AK80: =IF(AI80=0,AJ80,0) -> 0 | AL80: =IF(AND(AI80>0,AJ80>AI80),AJ80-AI80,0) -> 0 | AM80: =IF(AI80=AJ80,AJ80,0) -> 270 | AN80: =IF(AJ80=0,AI80,0) -> 0 | AO80: =IF(AND(AJ80>0,AJ80<AI80),AI80-AJ80,0) -> 0 | AP80: CAN-Accounts Receivable | AQ80: 151557 | AR80: 0 | AS80: 0
A81: bandkmurphyplumbingheatingandcoolingllc | B81: ExistingCustomerEOM | C81: ExistingCustomerEOM | D81: 0 | E81: 0 | F81: 0 | G81: 0 | H81: -14 | I81: -14 | K81: -124 | L81: -124 | M81: 3 | N81: 3 | O81: unknown | P81: unknown | Q81: 0 | R81: 0 | S81: 465 | T81: 77.5 | U81: 0 | V81: 0 | W81: 0 | X81: 0 | Y81: 138 | Z81: 138 | AA81: Prepay | AB81: Prepay | AC81: JaiPa | AD81: JaiPa | AE81: 0 | AF81: 0 | AG81: 3 | AH81: 3 | AI81: =W81+ Y81+D81+H81 -> 124 | AJ81: =X81+Z81+E81+I81 -> 124 | AK81: =IF(AI81=0,AJ81,0) -> 0 | AL81: =IF(AND(AI81>0,AJ81>AI81),AJ81-AI81,0) -> 0 | AM81: =IF(AI81=AJ81,AJ81,0) -> 124 | AN81: =IF(AJ81=0,AI81,0) -> 0 | AO81: =IF(AND(AJ81>0,AJ81<AI81),AI81-AJ81,0) -> 0 | AP81: US-Accounts Receivable | AQ81: 152999 | AR81: 0 | AS81: 0
A82: bramattcomputingltd | B82: ExistingCustomerEOM | C82: ExistingCustomerEOM | D82: 0 | E82: 0 | F82: 0 | G82: 0 | H82: -31.7 | I82: -31.7 | K82: -285.3 | L82: -285.3 | M82: 5 | N82: 5 | O82: New | P82: New | Q82: 0 | R82: 0 | S82: 0 | T82: 0 | U82: 0 | V82: 0 | W82: 0 | X82: 0 | Y82: 317 | Z82: 317 | AA82: Prepay | AB82: Prepay | AC82: HaPat | AD82: HaPat | AE82: 0 | AF82: 0 | AG82: 5 | AH82: 5 | AI82: =W82+ Y82+D82+H82 -> 285.3 | AJ82: =X82+Z82+E82+I82 -> 285.3 | AK82: =IF(AI82=0,AJ82,0) -> 0 | AL82: =IF(AND(AI82>0,AJ82>AI82),AJ82-AI82,0) -> 0 | AM82: =IF(AI82=AJ82,AJ82,0) -> 285.3 | AN82: =IF(AJ82=0,AI82,0) -> 0 | AO82: =IF(AND(AJ82>0,AJ82<AI82),AI82-AJ82,0) -> 0 | AP82: US-Accounts Receivable | AQ82: 152961 | AR82: 0 | AS82: 0
A83: beaconseed | B83: ExistingCustomerEOM | C83: ExistingCustomerEOM | D83: 0 | E83: 0 | F83: 0 | G83: 0 | H83: 0 | I83: 0 | K83: 0 | L83: 0 | M83: 3 | N83: 3 | O83: New | P83: New | Q83: 0 | R83: 0 | S83: 0 | T83: 0 | U83: 0 | V83: 0 | W83: 0 | X83: 0 | Y83: 147 | Z83: 147 | AA83: Monthly | AB83: Monthly | AC83: SukSa | AD83: SukSa | AE83: 0 | AF83: 0 | AG83: 3 | AH83: 3 | AI83: =W83+ Y83+D83+H83 -> 147 | AJ83: =X83+Z83+E83+I83 -> 147 | AK83: =IF(AI83=0,AJ83,0) -> 0 | AL83: =IF(AND(AI83>0,AJ83>AI83),AJ83-AI83,0) -> 0 | AM83: =IF(AI83=AJ83,AJ83,0) -> 147 | AN83: =IF(AJ83=0,AI83,0) -> 0 | AO83: =IF(AND(AJ83>0,AJ83<AI83),AI83-AJ83,0) -> 0 | AP83: US-Accounts Receivable | AQ83: 152970 | AR83: 0 | AS83: 0
A84: wtidistributioninc | B84: ExistingCustomerEOM | C84: ExistingCustomerEOM | D84: 0 | E84: 0 | F84: 0 | G84: 0 | H84: -4 | I84: -4 | K84: -36 | L84: -36 | M84: 2 | N84: 2 | O84: New | P84: New | Q84: 0 | R84: 0 | S84: 0 | T84: 0 | U84: 0 | V84: 0 | W84: 0 | X84: 0 | Y84: 40 | Z84: 40 | AA84: Prepay | AB84: Prepay | AC84: RafSy | AD84: RafSy | AE84: 0 | AF84: 0 | AG84: 1 | AH84: 1 | AI84: =W84+ Y84+D84+H84 -> 36 | AJ84: =X84+Z84+E84+I84 -> 36 | AK84: =IF(AI84=0,AJ84,0) -> 0 | AL84: =IF(AND(AI84>0,AJ84>AI84),AJ84-AI84,0) -> 0 | AM84: =IF(AI84=AJ84,AJ84,0) -> 36 | AN84: =IF(AJ84=0,AI84,0) -> 0 | AO84: =IF(AND(AJ84>0,AJ84<AI84),AI84-AJ84,0) -> 0 | AP84: US-Accounts Receivable | AQ84: 154920 | AR84: 0 | AS84: 0
A85: colonyroofing | B85: ExistingCustomerEOM | C85: ExistingCustomerEOM | D85: 0 | E85: 0 | F85: 0 | G85: 0 | H85: 0 | I85: 0 | K85: 0 | L85: 0 | M85: 3 | N85: 3 | O85: New | P85: New | Q85: 0 | R85: 0 | S85: 0 | T85: 0 | U85: 0 | V85: 0 | W85: 0 | X85: 0 | Y85: 322 | Z85: 322 | AA85: Monthly | AB85: Monthly | AC85: MikPa | AD85: MikPa | AE85: 0 | AF85: 0 | AG85: 7 | AH85: 7 | AI85: =W85+ Y85+D85+H85 -> 322 | AJ85: =X85+Z85+E85+I85 -> 322 | AK85: =IF(AI85=0,AJ85,0) -> 0 | AL85: =IF(AND(AI85>0,AJ85>AI85),AJ85-AI85,0) -> 0 | AM85: =IF(AI85=AJ85,AJ85,0) -> 322 | AN85: =IF(AJ85=0,AI85,0) -> 0 | AO85: =IF(AND(AJ85>0,AJ85<AI85),AI85-AJ85,0) -> 0 | AP85: US-Accounts Receivable | AQ85: 156444 | AR85: 0 | AS85: 0
A86: pioneersourcingsolutionsllc | B86: ExistingCustomerEOM | C86: ExistingCustomerEOM | D86: 0 | E86: 0 | F86: 0 | G86: 0 | H86: -3 | I86: -3 | K86: 275 | L86: -25 | M86: 1 | N86: 1 | O86: New | P86: New | Q86: 0 | R86: 0 | S86: 0 | T86: 0 | U86: 0 | V86: 0 | W86: 0 | X86: 0 | Y86: 28 | Z86: 28 | AA86: Prepay | AB86: Prepay | AC86: RafSy | AD86: RafSy | AE86: 0 | AF86: 0 | AG86: 1 | AH86: 1 | AI86: =W86+ Y86+D86+H86 -> 25 | AJ86: =X86+Z86+E86+I86 -> 25 | AK86: =IF(AI86=0,AJ86,0) -> 0 | AL86: =IF(AND(AI86>0,AJ86>AI86),AJ86-AI86,0) -> 0 | AM86: =IF(AI86=AJ86,AJ86,0) -> 25 | AN86: =IF(AJ86=0,AI86,0) -> 0 | AO86: =IF(AND(AJ86>0,AJ86<AI86),AI86-AJ86,0) -> 0 | AP86: US-Accounts Receivable | AQ86: 158737 | AR86: 0 | AS86: 0
A87: jdshouseoftrophies | B87: ExistingCustomerEOM | C87: ExistingCustomerEOM | D87: 0 | E87: 0 | F87: 0 | G87: 0 | H87: 0 | I87: 0 | K87: 0 | L87: 0 | M87: 3 | N87: 3 | O87: New | P87: New | Q87: 0 | R87: 0 | S87: 0 | T87: 0 | U87: 0 | V87: 0 | W87: 0 | X87: 0 | Y87: 196 | Z87: 196 | AA87: Monthly | AB87: Monthly | AC87: PhuPh | AD87: PhuPh | AE87: 0 | AF87: 0 | AG87: 4 | AH87: 4 | AI87: =W87+ Y87+D87+H87 -> 196 | AJ87: =X87+Z87+E87+I87 -> 196 | AK87: =IF(AI87=0,AJ87,0) -> 0 | AL87: =IF(AND(AI87>0,AJ87>AI87),AJ87-AI87,0) -> 0 | AM87: =IF(AI87=AJ87,AJ87,0) -> 196 | AN87: =IF(AJ87=0,AI87,0) -> 0 | AO87: =IF(AND(AJ87>0,AJ87<AI87),AI87-AJ87,0) -> 0 | AP87: US-Accounts Receivable | AQ87: 158724 | AR87: 0 | AS87: 0
A88: finelinecreativeartscenter | B88: ExistingCustomerEOM | C88: ExistingCustomerEOM | D88: 0 | E88: 0 | F88: 0 | G88: 0 | H88: -5.6 | I88: -5.6 | K88: 554.4 | L88: -50.4 | M88: 1 | N88: 1 | O88: New | P88: New | Q88: 0 | R88: 0 | S88: 0 | T88: 0 | U88: 0 | V88: 0 | W88: 0 | X88: 0 | Y88: 56 | Z88: 56 | AA88: Prepay | AB88: Prepay | AC88: RafSy | AD88: RafSy | AE88: 0 | AF88: 0 | AG88: 2 | AH88: 2 | AI88: =W88+ Y88+D88+H88 -> 50.4 | AJ88: =X88+Z88+E88+I88 -> 50.4 | AK88: =IF(AI88=0,AJ88,0) -> 0 | AL88: =IF(AND(AI88>0,AJ88>AI88),AJ88-AI88,0) -> 0 | AM88: =IF(AI88=AJ88,AJ88,0) -> 50.4 | AN88: =IF(AJ88=0,AI88,0) -> 0 | AO88: =IF(AND(AJ88>0,AJ88<AI88),AI88-AJ88,0) -> 0 | AP88: US-Accounts Receivable | AQ88: 158733 | AR88: 0 | AS88: 0
